Workbook

Sheet Solicitações
J1: Preenchimento do Coordenador
A2: Projeto | B2: Linha | C2: Aprovado | D2: Ação | E2: Trâmite | F2: Data Pedido | G2: Dígito | H2: Rodada em que foi solicitado o atendimento | I2: Preenchimento da TGCO | J2: Observação do Coordenador | K2: Impactos do não atendimento | L2: Projeto | M2: Atividade | N2: Tarefa | O2: Valor total | P2: Executora | Q2: ND | R2: PACOTE | S2: Para Contrato | T2: Para Motores | U2: Mês previsto
A3: A-29 | B3: 10000 | C3: {=INDEX('MTA 28-09'!B:B,MATCH(B3,'MTA 28-09'!A:A,0))} -> SIM | D3: {=INDEX('MTA 28-09'!D:D,MATCH(B3,'MTA 28-09'!A:A,0))} -> 2048 | E3: {=INDEX('MTA 28-09'!F:F,MATCH(B3,'MTA 28-09'!A:A,0))} -> ATENDIDO | F3: {=INDEX('MTA 28-09'!I:I,MATCH(B3,'MTA 28-09'!A:A,0))} -> 46052 | G3: {=INDEX('MTA 28-09'!J:J,MATCH(B3,'MTA 28-09'!A:A,0))} -> C26059 | H3: 1 | L3: {=INDEX('MTA 28-09'!S:S,MATCH(B3,'MTA 28-09'!A:A,0))} -> A-29 | M3: {=INDEX('MTA 28-09'!T:T,MATCH(B3,'MTA 28-09'!A:A,0))} -> CTT 102/CELOG-PAMALS/2023 – EMBRAER - PSLI | N3: {=INDEX('MTA 28-09'!U:U,MATCH(B3,'MTA 28-09'!A:A,0))} -> Parcela Fixa 01/12 | O3: {=INDEX('MTA 28-09'!AC:AC,MATCH(B3,'MTA 28-09'!A:A,0))} -> 664243.94 | P3: {=INDEX('MTA 28-09'!N:N,MATCH(B3,'MTA 28-09'!A:A,0))} -> CELOG | Q3: {=INDEX('MTA 28-09'!Z:Z,MATCH(B3,'MTA 28-09'!A:A,0))} -> 339039 | R3: {=INDEX('MTA 28-09'!L:L,MATCH(B3,'MTA 28-09'!A:A,0))} -> A | S3: {=INDEX('MTA 28-09'!X:X,MATCH(B3,'MTA 28-09'!A:A,0))} -> PARCELA FIXA | T3: {=INDEX('MTA 28-09'!W:W,MATCH(B3,'MTA 28-09'!A:A,0))} -> Não | U3: {=INDEX('MTA 28-09'!AE:AE,MATCH(B3,'MTA 28-09'!A:A,0))} -> 46107
A4: A-29 | B4: 10001 | C4: {=INDEX('MTA 28-09'!B:B,MATCH(B4,'MTA 28-09'!A:A,0))} -> SIM | D4: {=INDEX('MTA 28-09'!D:D,MATCH(B4,'MTA 28-09'!A:A,0))} -> 2048 | E4: {=INDEX('MTA 28-09'!F:F,MATCH(B4,'MTA 28-09'!A:A,0))} -> ATENDIDO | F4: {=INDEX('MTA 28-09'!I:I,MATCH(B4,'MTA 28-09'!A:A,0))} -> 46052 | G4: {=INDEX('MTA 28-09'!J:J,MATCH(B4,'MTA 28-09'!A:A,0))} -> C26065 | H4: 1 | L4: {=INDEX('MTA 28-09'!S:S,MATCH(B4,'MTA 28-09'!A:A,0))} -> A-29 | M4: {=INDEX('MTA 28-09'!T:T,MATCH(B4,'MTA 28-09'!A:A,0))} -> CTT 102/CELOG-PAMALS/2023 – EMBRAER - PSLI | N4: {=INDEX('MTA 28-09'!U:U,MATCH(B4,'MTA 28-09'!A:A,0))} -> Parcela Fixa 01/12 | O4: {=INDEX('MTA 28-09'!AC:AC,MATCH(B4,'MTA 28-09'!A:A,0))} -> 1645756.1 | P4: {=INDEX('MTA 28-09'!N:N,MATCH(B4,'MTA 28-09'!A:A,0))} -> CELOG | Q4: {=INDEX('MTA 28-09'!Z:Z,MATCH(B4,'MTA 28-09'!A:A,0))} -> 339039 | R4: {=INDEX('MTA 28-09'!L:L,MATCH(B4,'MTA 28-09'!A:A,0))} -> A | S4: {=INDEX('MTA 28-09'!X:X,MATCH(B4,'MTA 28-09'!A:A,0))} -> PARCELA FIXA | T4: {=INDEX('MTA 28-09'!W:W,MATCH(B4,'MTA 28-09'!A:A,0))} -> Não | U4: {=INDEX('MTA 28-09'!AE:AE,MATCH(B4,'MTA 28-09'!A:A,0))} -> 46107
A5: C-97 | B5: 10020 | C5: {=INDEX('MTA 28-09'!B:B,MATCH(B5,'MTA 28-09'!A:A,0))} -> SIM | D5: {=INDEX('MTA 28-09'!D:D,MATCH(B5,'MTA 28-09'!A:A,0))} -> 2048 | E5: {=INDEX('MTA 28-09'!F:F,MATCH(B5,'MTA 28-09'!A:A,0))} -> ATENDIDO | F5: {=INDEX('MTA 28-09'!I:I,MATCH(B5,'MTA 28-09'!A:A,0))} -> 46041 | G5: {=INDEX('MTA 28-09'!J:J,MATCH(B5,'MTA 28-09'!A:A,0))} -> C26050 | H5: 1 | L5: {=INDEX('MTA 28-09'!S:S,MATCH(B5,'MTA 28-09'!A:A,0))} -> C-97 | M5: {=INDEX('MTA 28-09'!T:T,MATCH(B5,'MTA 28-09'!A:A,0))} -> CTT 096/CAE-PAMALS/2021 - CLS C-97 | N5: {=INDEX('MTA 28-09'!U:U,MATCH(B5,'MTA 28-09'!A:A,0))} -> Parcela Fixa 01/12 | O5: {=INDEX('MTA 28-09'!AC:AC,MATCH(B5,'MTA 28-09'!A:A,0))} -> 332718.75 | P5: {=INDEX('MTA 28-09'!N:N,MATCH(B5,'MTA 28-09'!A:A,0))} -> CELOG | Q5: {=INDEX('MTA 28-09'!Z:Z,MATCH(B5,'MTA 28-09'!A:A,0))} -> 339039 | R5: {=INDEX('MTA 28-09'!L:L,MATCH(B5,'MTA 28-09'!A:A,0))} -> A | S5: {=INDEX('MTA 28-09'!X:X,MATCH(B5,'MTA 28-09'!A:A,0))} -> PARCELA FIXA | T5: {=INDEX('MTA 28-09'!W:W,MATCH(B5,'MTA 28-09'!A:A,0))} -> Não | U5: {=INDEX('MTA 28-09'!AE:AE,MATCH(B5,'MTA 28-09'!A:A,0))} -> 46107
A6: C-97 | B6: 10040 | C6: {=INDEX('MTA 28-09'!B:B,MATCH(B6,'MTA 28-09'!A:A,0))} -> SIM | D6: {=INDEX('MTA 28-09'!D:D,MATCH(B6,'MTA 28-09'!A:A,0))} -> 2048 | E6: {=INDEX('MTA 28-09'!F:F,MATCH(B6,'MTA 28-09'!A:A,0))} -> ATENDIDO | F6: {=INDEX('MTA 28-09'!I:I,MATCH(B6,'MTA 28-09'!A:A,0))} -> 46041 | G6: {=INDEX('MTA 28-09'!J:J,MATCH(B6,'MTA 28-09'!A:A,0))} -> C26052 | H6: 1 | L6: {=INDEX('MTA 28-09'!S:S,MATCH(B6,'MTA 28-09'!A:A,0))} -> C-97 | M6: {=INDEX('MTA 28-09'!T:T,MATCH(B6,'MTA 28-09'!A:A,0))} -> CTT 096/CAE-PAMALS/2021 - CLS C-97 | N6: {=INDEX('MTA 28-09'!U:U,MATCH(B6,'MTA 28-09'!A:A,0))} -> Hora de Voo 2025 (520HV voadas a mais) | O6: {=INDEX('MTA 28-09'!AC:AC,MATCH(B6,'MTA 28-09'!A:A,0))} -> 581400 | P6: {=INDEX('MTA 28-09'!N:N,MATCH(B6,'MTA 28-09'!A:A,0))} -> CELOG | Q6: {=INDEX('MTA 28-09'!Z:Z,MATCH(B6,'MTA 28-09'!A:A,0))} -> 339039 | R6: {=INDEX('MTA 28-09'!L:L,MATCH(B6,'MTA 28-09'!A:A,0))} -> A | S6: {=INDEX('MTA 28-09'!X:X,MATCH(B6,'MTA 28-09'!A:A,0))} -> HORA DE VOO | T6: {=INDEX('MTA 28-09'!W:W,MATCH(B6,'MTA 28-09'!A:A,0))} -> Não | U6: {=INDEX('MTA 28-09'!AE:AE,MATCH(B6,'MTA 28-09'!A:A,0))} -> 46107
A7: C-97 | B7: 10060 | C7: {=INDEX('MTA 28-09'!B:B,MATCH(B7,'MTA 28-09'!A:A,0))} -> SIM | D7: {=INDEX('MTA 28-09'!D:D,MATCH(B7,'MTA 28-09'!A:A,0))} -> 2048 | E7: {=INDEX('MTA 28-09'!F:F,MATCH(B7,'MTA 28-09'!A:A,0))} -> ATENDIDO | F7: {=INDEX('MTA 28-09'!I:I,MATCH(B7,'MTA 28-09'!A:A,0))} -> 46055 | G7: {=INDEX('MTA 28-09'!J:J,MATCH(B7,'MTA 28-09'!A:A,0))} -> C26070 | H7: 1 | L7: {=INDEX('MTA 28-09'!S:S,MATCH(B7,'MTA 28-09'!A:A,0))} -> C-97 | M7: {=INDEX('MTA 28-09'!T:T,MATCH(B7,'MTA 28-09'!A:A,0))} -> CTT 096/CAE-PAMALS/2021 - CLS C-97 | N7: {=INDEX('MTA 28-09'!U:U,MATCH(B7,'MTA 28-09'!A:A,0))} -> Hora de Voo 01/09 (500HV) | O7: {=INDEX('MTA 28-09'!AC:AC,MATCH(B7,'MTA 28-09'!A:A,0))} -> 2182993 | P7: {=INDEX('MTA 28-09'!N:N,MATCH(B7,'MTA 28-09'!A:A,0))} -> CELOG | Q7: {=INDEX('MTA 28-09'!Z:Z,MATCH(B7,'MTA 28-09'!A:A,0))} -> 339039 | R7: {=INDEX('MTA 28-09'!L:L,MATCH(B7,'MTA 28-09'!A:A,0))} -> A | S7: {=INDEX('MTA 28-09'!X:X,MATCH(B7,'MTA 28-09'!A:A,0))} -> HORA DE VOO | T7: {=INDEX('MTA 28-09'!W:W,MATCH(B7,'MTA 28-09'!A:A,0))} -> Não | U7: {=INDEX('MTA 28-09'!AE:AE,MATCH(B7,'MTA 28-09'!A:A,0))} -> 46107
A8: C-97 | B8: 10061 | C8: {=INDEX('MTA 28-09'!B:B,MATCH(B8,'MTA 28-09'!A:A,0))} -> SIM | D8: {=INDEX('MTA 28-09'!D:D,MATCH(B8,'MTA 28-09'!A:A,0))} -> 2048 | E8: {=INDEX('MTA 28-09'!F:F,MATCH(B8,'MTA 28-09'!A:A,0))} -> ATENDIDO | F8: {=INDEX('MTA 28-09'!I:I,MATCH(B8,'MTA 28-09'!A:A,0))} -> 46057 | G8: {=INDEX('MTA 28-09'!J:J,MATCH(B8,'MTA 28-09'!A:A,0))} -> C26079 | H8: 1 | L8: {=INDEX('MTA 28-09'!S:S,MATCH(B8,'MTA 28-09'!A:A,0))} -> C-97 | M8: {=INDEX('MTA 28-09'!T:T,MATCH(B8,'MTA 28-09'!A:A,0))} -> CTT 096/CAE-PAMALS/2021 - CLS C-97 | N8: {=INDEX('MTA 28-09'!U:U,MATCH(B8,'MTA 28-09'!A:A,0))} -> Hora de Voo 01/09 (500HV) | O8: {=INDEX('MTA 28-09'!AC:AC,MATCH(B8,'MTA 28-09'!A:A,0))} -> 221702.86 | P8: {=INDEX('MTA 28-09'!N:N,MATCH(B8,'MTA 28-09'!A:A,0))} -> CELOG | Q8: {=INDEX('MTA 28-09'!Z:Z,MATCH(B8,'MTA 28-09'!A:A,0))} -> 339039 | R8: {=INDEX('MTA 28-09'!L:L,MATCH(B8,'MTA 28-09'!A:A,0))} -> A | S8: {=INDEX('MTA 28-09'!X:X,MATCH(B8,'MTA 28-09'!A:A,0))} -> HORA DE VOO | T8: {=INDEX('MTA 28-09'!W:W,MATCH(B8,'MTA 28-09'!A:A,0))} -> Não | U8: {=INDEX('MTA 28-09'!AE:AE,MATCH(B8,'MTA 28-09'!A:A,0))} -> 46107
A9: C-97 | B9: 10062 | C9: {=INDEX('MTA 28-09'!B:B,MATCH(B9,'MTA 28-09'!A:A,0))} -> SIM | D9: {=INDEX('MTA 28-09'!D:D,MATCH(B9,'MTA 28-09'!A:A,0))} -> 2048 | E9: {=INDEX('MTA 28-09'!F:F,MATCH(B9,'MTA 28-09'!A:A,0))} -> ATENDIDO | F9: {=INDEX('MTA 28-09'!I:I,MATCH(B9,'MTA 28-09'!A:A,0))} -> 46055 | G9: {=INDEX('MTA 28-09'!J:J,MATCH(B9,'MTA 28-09'!A:A,0))} -> C26070 | H9: 1 | L9: {=INDEX('MTA 28-09'!S:S,MATCH(B9,'MTA 28-09'!A:A,0))} -> C-97 | M9: {=INDEX('MTA 28-09'!T:T,MATCH(B9,'MTA 28-09'!A:A,0))} -> CTT 096/CAE-PAMALS/2021 - CLS C-97 | N9: {=INDEX('MTA 28-09'!U:U,MATCH(B9,'MTA 28-09'!A:A,0))} -> Hora de Voo 01/09 (500HV) | O9: {=INDEX('MTA 28-09'!AC:AC,MATCH(B9,'MTA 28-09'!A:A,0))} -> 167804.17 | P9: {=INDEX('MTA 28-09'!N:N,MATCH(B9,'MTA 28-09'!A:A,0))} -> CELOG | Q9: {=INDEX('MTA 28-09'!Z:Z,MATCH(B9,'MTA 28-09'!A:A,0))} -> 339039 | R9: {=INDEX('MTA 28-09'!L:L,MATCH(B9,'MTA 28-09'!A:A,0))} -> A | S9: {=INDEX('MTA 28-09'!X:X,MATCH(B9,'MTA 28-09'!A:A,0))} -> HORA DE VOO | T9: {=INDEX('MTA 28-09'!W:W,MATCH(B9,'MTA 28-09'!A:A,0))} -> Não | U9: {=INDEX('MTA 28-09'!AE:AE,MATCH(B9,'MTA 28-09'!A:A,0))} -> 46107
A10: T-25 | B10: 10080 | C10: {=INDEX('MTA 28-09'!B:B,MATCH(B10,'MTA 28-09'!A:A,0))} -> SIM | D10: {=INDEX('MTA 28-09'!D:D,MATCH(B10,'MTA 28-09'!A:A,0))} -> 2048 | E10: {=INDEX('MTA 28-09'!F:F,MATCH(B10,'MTA 28-09'!A:A,0))} | F10: {=INDEX('MTA 28-09'!I:I,MATCH(B10,'MTA 28-09'!A:A,0))} | G10: {=INDEX('MTA 28-09'!J:J,MATCH(B10,'MTA 28-09'!A:A,0))} | H10: 46276 | I10: Atender | J10: LIVRE | L10: {=INDEX('MTA 28-09'!S:S,MATCH(B10,'MTA 28-09'!A:A,0))} -> T-25 | M10: {=INDEX('MTA 28-09'!T:T,MATCH(B10,'MTA 28-09'!A:A,0))} -> Requisição CABW | N10: {=INDEX('MTA 28-09'!U:U,MATCH(B10,'MTA 28-09'!A:A,0))} -> Requisição Consumíveis | O10: {=INDEX('MTA 28-09'!AC:AC,MATCH(B10,'MTA 28-09'!A:A,0))} -> 374409.15 | P10: {=INDEX('MTA 28-09'!N:N,MATCH(B10,'MTA 28-09'!A:A,0))} -> CABW | Q10: {=INDEX('MTA 28-09'!Z:Z,MATCH(B10,'MTA 28-09'!A:A,0))} -> 339030 | R10: {=INDEX('MTA 28-09'!L:L,MATCH(B10,'MTA 28-09'!A:A,0))} -> A | S10: {=INDEX('MTA 28-09'!X:X,MATCH(B10,'MTA 28-09'!A:A,0))} -> REQUISIÇÃO | T10: {=INDEX('MTA 28-09'!W:W,MATCH(B10,'MTA 28-09'!A:A,0))} -> Não | U10: {=INDEX('MTA 28-09'!AE:AE,MATCH(B10,'MTA 28-09'!A:A,0))} -> 46291
A11: T-25 | B11: 10081 | C11: {=INDEX('MTA 28-09'!B:B,MATCH(B11,'MTA 28-09'!A:A,0))} -> SIM | D11: {=INDEX('MTA 28-09'!D:D,MATCH(B11,'MTA 28-09'!A:A,0))} -> 2048 | E11: {=INDEX('MTA 28-09'!F:F,MATCH(B11,'MTA 28-09'!A:A,0))} -> ATENDIDO | F11: {=INDEX('MTA 28-09'!I:I,MATCH(B11,'MTA 28-09'!A:A,0))} -> 46098 | G11: {=INDEX('MTA 28-09'!J:J,MATCH(B11,'MTA 28-09'!A:A,0))} -> C26063 | H11: email do dia 11/03 | L11: {=INDEX('MTA 28-09'!S:S,MATCH(B11,'MTA 28-09'!A:A,0))} -> T-25 | M11: {=INDEX('MTA 28-09'!T:T,MATCH(B11,'MTA 28-09'!A:A,0))} -> Requisição CABW | N11: {=INDEX('MTA 28-09'!U:U,MATCH(B11,'MTA 28-09'!A:A,0))} -> Atualização de GPS | O11: {=INDEX('MTA 28-09'!AC:AC,MATCH(B11,'MTA 28-09'!A:A,0))} -> 260590.85 | P11: {=INDEX('MTA 28-09'!N:N,MATCH(B11,'MTA 28-09'!A:A,0))} -> CABW | Q11: {=INDEX('MTA 28-09'!Z:Z,MATCH(B11,'MTA 28-09'!A:A,0))} -> 339039 | R11: {=INDEX('MTA 28-09'!L:L,MATCH(B11,'MTA 28-09'!A:A,0))} -> A | S11: {=INDEX('MTA 28-09'!X:X,MATCH(B11,'MTA 28-09'!A:A,0))} -> REQUISIÇÃO | T11: {=INDEX('MTA 28-09'!W:W,MATCH(B11,'MTA 28-09'!A:A,0))} -> Não | U11: {=INDEX('MTA 28-09'!AE:AE,MATCH(B11,'MTA 28-09'!A:A,0))} -> 46107
A12: T-25 | B12: 10100 | C12: {=INDEX('MTA 28-09'!B:B,MATCH(B12,'MTA 28-09'!A:A,0))} -> SIM | D12: {=INDEX('MTA 28-09'!D:D,MATCH(B12,'MTA 28-09'!A:A,0))} -> 2048 | E12: {=INDEX('MTA 28-09'!F:F,MATCH(B12,'MTA 28-09'!A:A,0))} | F12: {=INDEX('MTA 28-09'!I:I,MATCH(B12,'MTA 28-09'!A:A,0))} | G12: {=INDEX('MTA 28-09'!J:J,MATCH(B12,'MTA 28-09'!A:A,0))} | H12: 46276 | I12: Atender | J12: MOTOR | L12: {=INDEX('MTA 28-09'!S:S,MATCH(B12,'MTA 28-09'!A:A,0))} -> T-25 | M12: {=INDEX('MTA 28-09'!T:T,MATCH(B12,'MTA 28-09'!A:A,0))} -> Requisição CABW | N12: {=INDEX('MTA 28-09'!U:U,MATCH(B12,'MTA 28-09'!A:A,0))} -> Requisição Consumíveis | O12: {=INDEX('MTA 28-09'!AC:AC,MATCH(B12,'MTA 28-09'!A:A,0))} -> 10000 | P12: {=INDEX('MTA 28-09'!N:N,MATCH(B12,'MTA 28-09'!A:A,0))} -> CABW | Q12: {=INDEX('MTA 28-09'!Z:Z,MATCH(B12,'MTA 28-09'!A:A,0))} -> 339030 | R12: {=INDEX('MTA 28-09'!L:L,MATCH(B12,'MTA 28-09'!A:A,0))} -> A | S12: {=INDEX('MTA 28-09'!X:X,MATCH(B12,'MTA 28-09'!A:A,0))} -> REQUISIÇÃO | T12: {=INDEX('MTA 28-09'!W:W,MATCH(B12,'MTA 28-09'!A:A,0))} -> Não | U12: {=INDEX('MTA 28-09'!AE:AE,MATCH(B12,'MTA 28-09'!A:A,0))} -> 46352
A13: T-27 | B13: 10120 | C13: {=INDEX('MTA 28-09'!B:B,MATCH(B13,'MTA 28-09'!A:A,0))} -> SIM | D13: {=INDEX('MTA 28-09'!D:D,MATCH(B13,'MTA 28-09'!A:A,0))} -> 2048 | E13: {=INDEX('MTA 28-09'!F:F,MATCH(B13,'MTA 28-09'!A:A,0))} | F13: {=INDEX('MTA 28-09'!I:I,MATCH(B13,'MTA 28-09'!A:A,0))} | G13: {=INDEX('MTA 28-09'!J:J,MATCH(B13,'MTA 28-09'!A:A,0))} | H13: 46276 | I13: REMANEJAR ATENDER $ 2.000,00 E MUDAR PARA ATUALIZAR GPS PJT A-29. Remanejar R$ 130.000,00 para o ctt 048 Willian | J13: LIVRE | L13: {=INDEX('MTA 28-09'!S:S,MATCH(B13,'MTA 28-09'!A:A,0))} -> T-27 | M13: {=INDEX('MTA 28-09'!T:T,MATCH(B13,'MTA 28-09'!A:A,0))} -> Requisição CABW | N13: {=INDEX('MTA 28-09'!U:U,MATCH(B13,'MTA 28-09'!A:A,0))} -> Atualização de GPS | O13: {=INDEX('MTA 28-09'!AC:AC,MATCH(B13,'MTA 28-09'!A:A,0))} -> 391353.59 | P13: {=INDEX('MTA 28-09'!N:N,MATCH(B13,'MTA 28-09'!A:A,0))} -> CABW | Q13: {=INDEX('MTA 28-09'!Z:Z,MATCH(B13,'MTA 28-09'!A:A,0))} -> 339039 | R13: {=INDEX('MTA 28-09'!L:L,MATCH(B13,'MTA 28-09'!A:A,0))} -> A | S13: {=INDEX('MTA 28-09'!X:X,MATCH(B13,'MTA 28-09'!A:A,0))} -> REQUISIÇÃO | T13: {=INDEX('MTA 28-09'!W:W,MATCH(B13,'MTA 28-09'!A:A,0))} -> Não | U13: {=INDEX('MTA 28-09'!AE:AE,MATCH(B13,'MTA 28-09'!A:A,0))} -> 46291
A14: T-27 | B14: 10121 | C14: {=INDEX('MTA 28-09'!B:B,MATCH(B14,'MTA 28-09'!A:A,0))} -> SIM | D14: {=INDEX('MTA 28-09'!D:D,MATCH(B14,'MTA 28-09'!A:A,0))} -> 2048 | E14: {=INDEX('MTA 28-09'!F:F,MATCH(B14,'MTA 28-09'!A:A,0))} -> ATENDIDO | F14: {=INDEX('MTA 28-09'!I:I,MATCH(B14,'MTA 28-09'!A:A,0))} -> 46098 | G14: {=INDEX('MTA 28-09'!J:J,MATCH(B14,'MTA 28-09'!A:A,0))} -> C26060 | H14: email do dia 11/03 | L14: {=INDEX('MTA 28-09'!S:S,MATCH(B14,'MTA 28-09'!A:A,0))} -> T-27 | M14: {=INDEX('MTA 28-09'!T:T,MATCH(B14,'MTA 28-09'!A:A,0))} -> Requisição CABW | N14: {=INDEX('MTA 28-09'!U:U,MATCH(B14,'MTA 28-09'!A:A,0))} -> Atualização de GPS | O14: {=INDEX('MTA 28-09'!AC:AC,MATCH(B14,'MTA 28-09'!A:A,0))} -> 245262 | P14: {=INDEX('MTA 28-09'!N:N,MATCH(B14,'MTA 28-09'!A:A,0))} -> CABW | Q14: {=INDEX('MTA 28-09'!Z:Z,MATCH(B14,'MTA 28-09'!A:A,0))} -> 339039 | R14: {=INDEX('MTA 28-09'!L:L,MATCH(B14,'MTA 28-09'!A:A,0))} -> A | S14: {=INDEX('MTA 28-09'!X:X,MATCH(B14,'MTA 28-09'!A:A,0))} -> REQUISIÇÃO | T14: {=INDEX('MTA 28-09'!W:W,MATCH(B14,'MTA 28-09'!A:A,0))} -> Não | U14: {=INDEX('MTA 28-09'!AE:AE,MATCH(B14,'MTA 28-09'!A:A,0))} -> 46107
A15: T-27 | B15: 10122 | C15: {=INDEX('MTA 28-09'!B:B,MATCH(B15,'MTA 28-09'!A:A,0))} -> SIM | D15: {=INDEX('MTA 28-09'!D:D,MATCH(B15,'MTA 28-09'!A:A,0))} -> 2048 | E15: {=INDEX('MTA 28-09'!F:F,MATCH(B15,'MTA 28-09'!A:A,0))} -> ATENDIDO | F15: {=INDEX('MTA 28-09'!I:I,MATCH(B15,'MTA 28-09'!A:A,0))} -> 46098 | G15: {=INDEX('MTA 28-09'!J:J,MATCH(B15,'MTA 28-09'!A:A,0))} -> C26153 | H15: email do dia 11/03 | L15: {=INDEX('MTA 28-09'!S:S,MATCH(B15,'MTA 28-09'!A:A,0))} -> T-27 | M15: {=INDEX('MTA 28-09'!T:T,MATCH(B15,'MTA 28-09'!A:A,0))} -> Contrato inexigibilidade EMBRAER | N15: {=INDEX('MTA 28-09'!U:U,MATCH(B15,'MTA 28-09'!A:A,0))} -> Publicação | O15: {=INDEX('MTA 28-09'!AC:AC,MATCH(B15,'MTA 28-09'!A:A,0))} -> 91984.41 | P15: {=INDEX('MTA 28-09'!N:N,MATCH(B15,'MTA 28-09'!A:A,0))} -> CELOG | Q15: {=INDEX('MTA 28-09'!Z:Z,MATCH(B15,'MTA 28-09'!A:A,0))} -> 339039 | R15: {=INDEX('MTA 28-09'!L:L,MATCH(B15,'MTA 28-09'!A:A,0))} -> A | S15: {=INDEX('MTA 28-09'!X:X,MATCH(B15,'MTA 28-09'!A:A,0))} -> REQUISIÇÃO | T15: {=INDEX('MTA 28-09'!W:W,MATCH(B15,'MTA 28-09'!A:A,0))} -> Não | U15: {=INDEX('MTA 28-09'!AE:AE,MATCH(B15,'MTA 28-09'!A:A,0))} -> 46107
A16: T-27 | B16: 10140 | C16: {=INDEX('MTA 28-09'!B:B,MATCH(B16,'MTA 28-09'!A:A,0))} -> SIM | D16: {=INDEX('MTA 28-09'!D:D,MATCH(B16,'MTA 28-09'!A:A,0))} -> 2048 | E16: {=INDEX('MTA 28-09'!F:F,MATCH(B16,'MTA 28-09'!A:A,0))} -> ATENDIDO | F16: {=INDEX('MTA 28-09'!I:I,MATCH(B16,'MTA 28-09'!A:A,0))} -> 46192 | G16: {=INDEX('MTA 28-09'!J:J,MATCH(B16,'MTA 28-09'!A:A,0))} -> C26038 | L16: {=INDEX('MTA 28-09'!S:S,MATCH(B16,'MTA 28-09'!A:A,0))} -> T-27 | M16: {=INDEX('MTA 28-09'!T:T,MATCH(B16,'MTA 28-09'!A:A,0))} -> REQUISIÇÃO SERVIÇO | N16: {=INDEX('MTA 28-09'!U:U,MATCH(B16,'MTA 28-09'!A:A,0))} -> RG Controlador de Torque 3 EA (1/2) | O16: {=INDEX('MTA 28-09'!AC:AC,MATCH(B16,'MTA 28-09'!A:A,0))} -> 60000 | P16: {=INDEX('MTA 28-09'!N:N,MATCH(B16,'MTA 28-09'!A:A,0))} -> CABW | Q16: {=INDEX('MTA 28-09'!Z:Z,MATCH(B16,'MTA 28-09'!A:A,0))} -> 339039 | R16: {=INDEX('MTA 28-09'!L:L,MATCH(B16,'MTA 28-09'!A:A,0))} -> A | S16: {=INDEX('MTA 28-09'!X:X,MATCH(B16,'MTA 28-09'!A:A,0))} -> REQUISIÇÃO | T16: {=INDEX('MTA 28-09'!W:W,MATCH(B16,'MTA 28-09'!A:A,0))} -> SIM | U16: {=INDEX('MTA 28-09'!AE:AE,MATCH(B16,'MTA 28-09'!A:A,0))} -> 46229
A17: A-29 | B17: 10160 | C17: {=INDEX('MTA 28-09'!B:B,MATCH(B17,'MTA 28-09'!A:A,0))} -> SIM | D17: {=INDEX('MTA 28-09'!D:D,MATCH(B17,'MTA 28-09'!A:A,0))} -> 2048 | E17: {=INDEX('MTA 28-09'!F:F,MATCH(B17,'MTA 28-09'!A:A,0))} -> ATENDIDO | F17: {=INDEX('MTA 28-09'!I:I,MATCH(B17,'MTA 28-09'!A:A,0))} -> 46098 | G17: {=INDEX('MTA 28-09'!J:J,MATCH(B17,'MTA 28-09'!A:A,0))} -> C26173 | H17: email do dia 11/03 | L17: {=INDEX('MTA 28-09'!S:S,MATCH(B17,'MTA 28-09'!A:A,0))} -> A-29 | M17: {=INDEX('MTA 28-09'!T:T,MATCH(B17,'MTA 28-09'!A:A,0))} -> Contrato inexigibilidade EMBRAER - CNT 012/CELOG-PAMALS/2026 | N17: {=INDEX('MTA 28-09'!U:U,MATCH(B17,'MTA 28-09'!A:A,0))} -> Publicação | O17: {=INDEX('MTA 28-09'!AC:AC,MATCH(B17,'MTA 28-09'!A:A,0))} -> 1624451.9 | P17: {=INDEX('MTA 28-09'!N:N,MATCH(B17,'MTA 28-09'!A:A,0))} -> CELOG | Q17: {=INDEX('MTA 28-09'!Z:Z,MATCH(B17,'MTA 28-09'!A:A,0))} -> 339039 | R17: {=INDEX('MTA 28-09'!L:L,MATCH(B17,'MTA 28-09'!A:A,0))} -> A | S17: {=INDEX('MTA 28-09'!X:X,MATCH(B17,'MTA 28-09'!A:A,0))} -> REQUISIÇÃO | T17: {=INDEX('MTA 28-09'!W:W,MATCH(B17,'MTA 28-09'!A:A,0))} -> Não | U17: {=INDEX('MTA 28-09'!AE:AE,MATCH(B17,'MTA 28-09'!A:A,0))} -> 46107
A18: A-29 | B18: 10180 | C18: {=INDEX('MTA 28-09'!B:B,MATCH(B18,'MTA 28-09'!A:A,0))} -> SIM | D18: {=INDEX('MTA 28-09'!D:D,MATCH(B18,'MTA 28-09'!A:A,0))} -> 2048 | E18: {=INDEX('MTA 28-09'!F:F,MATCH(B18,'MTA 28-09'!A:A,0))} -> ATENDIDO | F18: {=INDEX('MTA 28-09'!I:I,MATCH(B18,'MTA 28-09'!A:A,0))} -> 46041 | G18: {=INDEX('MTA 28-09'!J:J,MATCH(B18,'MTA 28-09'!A:A,0))} -> C26051 | H18: 1 | L18: {=INDEX('MTA 28-09'!S:S,MATCH(B18,'MTA 28-09'!A:A,0))} -> A-29 | M18: {=INDEX('MTA 28-09'!T:T,MATCH(B18,'MTA 28-09'!A:A,0))} -> CNT 060/CELOG-PAMASP/2023 - PW - HSI/REPARO | N18: {=INDEX('MTA 28-09'!U:U,MATCH(B18,'MTA 28-09'!A:A,0))} -> HSI PT6A-68C 1/4 | O18: {=INDEX('MTA 28-09'!AC:AC,MATCH(B18,'MTA 28-09'!A:A,0))} -> 2500000 | P18: {=INDEX('MTA 28-09'!N:N,MATCH(B18,'MTA 28-09'!A:A,0))} -> CELOG | Q18: {=INDEX('MTA 28-09'!Z:Z,MATCH(B18,'MTA 28-09'!A:A,0))} -> 339039 | R18: {=INDEX('MTA 28-09'!L:L,MATCH(B18,'MTA 28-09'!A:A,0))} -> A | S18: {=INDEX('MTA 28-09'!X:X,MATCH(B18,'MTA 28-09'!A:A,0))} -> SOB DEMANDA | T18: {=INDEX('MTA 28-09'!W:W,MATCH(B18,'MTA 28-09'!A:A,0))} -> SIM | U18: {=INDEX('MTA 28-09'!AE:AE,MATCH(B18,'MTA 28-09'!A:A,0))} -> 46079
A19: A-29 | B19: 10200 | C19: {=INDEX('MTA 28-09'!B:B,MATCH(B19,'MTA 28-09'!A:A,0))} -> SIM | D19: {=INDEX('MTA 28-09'!D:D,MATCH(B19,'MTA 28-09'!A:A,0))} -> 2048 | E19: {=INDEX('MTA 28-09'!F:F,MATCH(B19,'MTA 28-09'!A:A,0))} -> ATENDIDO | F19: {=INDEX('MTA 28-09'!I:I,MATCH(B19,'MTA 28-09'!A:A,0))} -> 46057 | G19: {=INDEX('MTA 28-09'!J:J,MATCH(B19,'MTA 28-09'!A:A,0))} -> C26078 | H19: 1 | L19: {=INDEX('MTA 28-09'!S:S,MATCH(B19,'MTA 28-09'!A:A,0))} -> A-29 | M19: {=INDEX('MTA 28-09'!T:T,MATCH(B19,'MTA 28-09'!A:A,0))} -> CTT 004/CELOG-PAMASP/2025 - PW - AQ. PEÇAS | N19: {=INDEX('MTA 28-09'!U:U,MATCH(B19,'MTA 28-09'!A:A,0))} -> Material para PT6A-68C 1/3 | O19: {=INDEX('MTA 28-09'!AC:AC,MATCH(B19,'MTA 28-09'!A:A,0))} -> 1830599 | P19: {=INDEX('MTA 28-09'!N:N,MATCH(B19,'MTA 28-09'!A:A,0))} -> CELOG | Q19: {=INDEX('MTA 28-09'!Z:Z,MATCH(B19,'MTA 28-09'!A:A,0))} -> 339030 | R19: {=INDEX('MTA 28-09'!L:L,MATCH(B19,'MTA 28-09'!A:A,0))} -> A | S19: {=INDEX('MTA 28-09'!X:X,MATCH(B19,'MTA 28-09'!A:A,0))} -> SOB DEMANDA | T19: {=INDEX('MTA 28-09'!W:W,MATCH(B19,'MTA 28-09'!A:A,0))} -> SIM | U19: {=INDEX('MTA 28-09'!AE:AE,MATCH(B19,'MTA 28-09'!A:A,0))} -> 46079
A20: A-29 | B20: 10201 | C20: {=INDEX('MTA 28-09'!B:B,MATCH(B20,'MTA 28-09'!A:A,0))} -> SIM | D20: {=INDEX('MTA 28-09'!D:D,MATCH(B20,'MTA 28-09'!A:A,0))} -> 2048 | E20: {=INDEX('MTA 28-09'!F:F,MATCH(B20,'MTA 28-09'!A:A,0))} -> ATENDIDO | F20: {=INDEX('MTA 28-09'!I:I,MATCH(B20,'MTA 28-09'!A:A,0))} -> 46052 | G20: {=INDEX('MTA 28-09'!J:J,MATCH(B20,'MTA 28-09'!A:A,0))} -> C26066 | H20: 1 | L20: {=INDEX('MTA 28-09'!S:S,MATCH(B20,'MTA 28-09'!A:A,0))} -> A-29 | M20: {=INDEX('MTA 28-09'!T:T,MATCH(B20,'MTA 28-09'!A:A,0))} -> CTT 004/CELOG-PAMASP/2025 - PW - AQ. PEÇAS | N20: {=INDEX('MTA 28-09'!U:U,MATCH(B20,'MTA 28-09'!A:A,0))} -> Material para PT6A-68C 1/3 | O20: {=INDEX('MTA 28-09'!AC:AC,MATCH(B20,'MTA 28-09'!A:A,0))} -> 1169401 | P20: {=INDEX('MTA 28-09'!N:N,MATCH(B20,'MTA 28-09'!A:A,0))} -> CELOG | Q20: {=INDEX('MTA 28-09'!Z:Z,MATCH(B20,'MTA 28-09'!A:A,0))} -> 339030 | R20: {=INDEX('MTA 28-09'!L:L,MATCH(B20,'MTA 28-09'!A:A,0))} -> A | S20: {=INDEX('MTA 28-09'!X:X,MATCH(B20,'MTA 28-09'!A:A,0))} -> SOB DEMANDA | T20: {=INDEX('MTA 28-09'!W:W,MATCH(B20,'MTA 28-09'!A:A,0))} -> SIM | U20: {=INDEX('MTA 28-09'!AE:AE,MATCH(B20,'MTA 28-09'!A:A,0))} -> 46079
A21: C-95M | B21: 10220 | C21: {=INDEX('MTA 28-09'!B:B,MATCH(B21,'MTA 28-09'!A:A,0))} -> SIM | D21: {=INDEX('MTA 28-09'!D:D,MATCH(B21,'MTA 28-09'!A:A,0))} -> 2048 | E21: {=INDEX('MTA 28-09'!F:F,MATCH(B21,'MTA 28-09'!A:A,0))} | F21: {=INDEX('MTA 28-09'!I:I,MATCH(B21,'MTA 28-09'!A:A,0))} | G21: {=INDEX('MTA 28-09'!J:J,MATCH(B21,'MTA 28-09'!A:A,0))} | H21: 46276 | I21: Atender | J21: LIVRE | L21: {=INDEX('MTA 28-09'!S:S,MATCH(B21,'MTA 28-09'!A:A,0))} -> C-95M | M21: {=INDEX('MTA 28-09'!T:T,MATCH(B21,'MTA 28-09'!A:A,0))} -> Requisição CABW | N21: {=INDEX('MTA 28-09'!U:U,MATCH(B21,'MTA 28-09'!A:A,0))} -> Requisição de Consumíveis | O21: {=INDEX('MTA 28-09'!AC:AC,MATCH(B21,'MTA 28-09'!A:A,0))} -> 149138.2 | P21: {=INDEX('MTA 28-09'!N:N,MATCH(B21,'MTA 28-09'!A:A,0))} -> CABW | Q21: {=INDEX('MTA 28-09'!Z:Z,MATCH(B21,'MTA 28-09'!A:A,0))} -> 339030 | R21: {=INDEX('MTA 28-09'!L:L,MATCH(B21,'MTA 28-09'!A:A,0))} -> A | S21: {=INDEX('MTA 28-09'!X:X,MATCH(B21,'MTA 28-09'!A:A,0))} -> REQUISIÇÃO | T21: {=INDEX('MTA 28-09'!W:W,MATCH(B21,'MTA 28-09'!A:A,0))} -> Não | U21: {=INDEX('MTA 28-09'!AE:AE,MATCH(B21,'MTA 28-09'!A:A,0))} -> 46291
A22: C-95M | B22: 10221 | C22: {=INDEX('MTA 28-09'!B:B,MATCH(B22,'MTA 28-09'!A:A,0))} -> SIM | D22: {=INDEX('MTA 28-09'!D:D,MATCH(B22,'MTA 28-09'!A:A,0))} -> 20XV | E22: {=INDEX('MTA 28-09'!F:F,MATCH(B22,'MTA 28-09'!A:A,0))} -> ATENDIDO | F22: {=INDEX('MTA 28-09'!I:I,MATCH(B22,'MTA 28-09'!A:A,0))} -> 46098 | G22: {=INDEX('MTA 28-09'!J:J,MATCH(B22,'MTA 28-09'!A:A,0))} -> C26062 | H22: email do dia 11/03 | L22: {=INDEX('MTA 28-09'!S:S,MATCH(B22,'MTA 28-09'!A:A,0))} -> C-95M | M22: {=INDEX('MTA 28-09'!T:T,MATCH(B22,'MTA 28-09'!A:A,0))} -> Requisição CABW | N22: {=INDEX('MTA 28-09'!U:U,MATCH(B22,'MTA 28-09'!A:A,0))} -> Atualização de GPS | O22: {=INDEX('MTA 28-09'!AC:AC,MATCH(B22,'MTA 28-09'!A:A,0))} -> 150861.8 | P22: {=INDEX('MTA 28-09'!N:N,MATCH(B22,'MTA 28-09'!A:A,0))} -> CABW | Q22: {=INDEX('MTA 28-09'!Z:Z,MATCH(B22,'MTA 28-09'!A:A,0))} -> 339039 | R22: {=INDEX('MTA 28-09'!L:L,MATCH(B22,'MTA 28-09'!A:A,0))} -> A | S22: {=INDEX('MTA 28-09'!X:X,MATCH(B22,'MTA 28-09'!A:A,0))} -> REQUISIÇÃO | T22: {=INDEX('MTA 28-09'!W:W,MATCH(B22,'MTA 28-09'!A:A,0))} -> Não | U22: {=INDEX('MTA 28-09'!AE:AE,MATCH(B22,'MTA 28-09'!A:A,0))} -> 46107
A23: C-95M | B23: 10240 | C23: {=INDEX('MTA 28-09'!B:B,MATCH(B23,'MTA 28-09'!A:A,0))} -> SIM | D23: {=INDEX('MTA 28-09'!D:D,MATCH(B23,'MTA 28-09'!A:A,0))} -> 2048 | E23: {=INDEX('MTA 28-09'!F:F,MATCH(B23,'MTA 28-09'!A:A,0))} | F23: {=INDEX('MTA 28-09'!I:I,MATCH(B23,'MTA 28-09'!A:A,0))} | G23: {=INDEX('MTA 28-09'!J:J,MATCH(B23,'MTA 28-09'!A:A,0))} | H23: 46276 | I23: Atender | J23: restante livre | L23: {=INDEX('MTA 28-09'!S:S,MATCH(B23,'MTA 28-09'!A:A,0))} -> C-95M | M23: {=INDEX('MTA 28-09'!T:T,MATCH(B23,'MTA 28-09'!A:A,0))} -> Requisição CABW | N23: {=INDEX('MTA 28-09'!U:U,MATCH(B23,'MTA 28-09'!A:A,0))} -> Requisição Consumíveis | O23: {=INDEX('MTA 28-09'!AC:AC,MATCH(B23,'MTA 28-09'!A:A,0))} -> 451164.69 | P23: {=INDEX('MTA 28-09'!N:N,MATCH(B23,'MTA 28-09'!A:A,0))} -> CABW | Q23: {=INDEX('MTA 28-09'!Z:Z,MATCH(B23,'MTA 28-09'!A:A,0))} -> 339030 | R23: {=INDEX('MTA 28-09'!L:L,MATCH(B23,'MTA 28-09'!A:A,0))} -> A | S23: {=INDEX('MTA 28-09'!X:X,MATCH(B23,'MTA 28-09'!A:A,0))} -> REQUISIÇÃO | T23: {=INDEX('MTA 28-09'!W:W,MATCH(B23,'MTA 28-09'!A:A,0))} -> Não | U23: {=INDEX('MTA 28-09'!AE:AE,MATCH(B23,'MTA 28-09'!A:A,0))} -> 46260
A24: C-95M | B24: 10241 | C24: {=INDEX('MTA 28-09'!B:B,MATCH(B24,'MTA 28-09'!A:A,0))} -> SIM | D24: {=INDEX('MTA 28-09'!D:D,MATCH(B24,'MTA 28-09'!A:A,0))} -> 20XV | E24: {=INDEX('MTA 28-09'!F:F,MATCH(B24,'MTA 28-09'!A:A,0))} -> ATENDIDO | F24: {=INDEX('MTA 28-09'!I:I,MATCH(B24,'MTA 28-09'!A:A,0))} -> 46098 | G24: {=INDEX('MTA 28-09'!J:J,MATCH(B24,'MTA 28-09'!A:A,0))} -> C26151 | H24: email do dia 11/03 | L24: {=INDEX('MTA 28-09'!S:S,MATCH(B24,'MTA 28-09'!A:A,0))} -> C-95M | M24: {=INDEX('MTA 28-09'!T:T,MATCH(B24,'MTA 28-09'!A:A,0))} -> Contrato inexigibilidade EMBRAER | N24: {=INDEX('MTA 28-09'!U:U,MATCH(B24,'MTA 28-09'!A:A,0))} -> Publicação | O24: {=INDEX('MTA 28-09'!AC:AC,MATCH(B24,'MTA 28-09'!A:A,0))} -> 15615.31 | P24: {=INDEX('MTA 28-09'!N:N,MATCH(B24,'MTA 28-09'!A:A,0))} -> CELOG | Q24: {=INDEX('MTA 28-09'!Z:Z,MATCH(B24,'MTA 28-09'!A:A,0))} -> 339039 | R24: {=INDEX('MTA 28-09'!L:L,MATCH(B24,'MTA 28-09'!A:A,0))} -> A | S24: {=INDEX('MTA 28-09'!X:X,MATCH(B24,'MTA 28-09'!A:A,0))} -> REQUISIÇÃO | T24: {=INDEX('MTA 28-09'!W:W,MATCH(B24,'MTA 28-09'!A:A,0))} -> Não | U24: {=INDEX('MTA 28-09'!AE:AE,MATCH(B24,'MTA 28-09'!A:A,0))} -> 46107
A25: C-95M | B25: 10242 | C25: {=INDEX('MTA 28-09'!B:B,MATCH(B25,'MTA 28-09'!A:A,0))} -> SIM | D25: {=INDEX('MTA 28-09'!D:D,MATCH(B25,'MTA 28-09'!A:A,0))} -> 2048 | E25: {=INDEX('MTA 28-09'!F:F,MATCH(B25,'MTA 28-09'!A:A,0))} -> ATENDIDO | F25: {=INDEX('MTA 28-09'!I:I,MATCH(B25,'MTA 28-09'!A:A,0))} -> 46209 | G25: {=INDEX('MTA 28-09'!J:J,MATCH(B25,'MTA 28-09'!A:A,0))} -> C26146 | H25: email do dia 19/06 | L25: {=INDEX('MTA 28-09'!S:S,MATCH(B25,'MTA 28-09'!A:A,0))} -> C-95M | M25: {=INDEX('MTA 28-09'!T:T,MATCH(B25,'MTA 28-09'!A:A,0))} -> Requisição CABW | N25: {=INDEX('MTA 28-09'!U:U,MATCH(B25,'MTA 28-09'!A:A,0))} -> Publicação | O25: {=INDEX('MTA 28-09'!AC:AC,MATCH(B25,'MTA 28-09'!A:A,0))} -> 53149.73 | P25: {=INDEX('MTA 28-09'!N:N,MATCH(B25,'MTA 28-09'!A:A,0))} -> CABW | Q25: {=INDEX('MTA 28-09'!Z:Z,MATCH(B25,'MTA 28-09'!A:A,0))} -> 339039 | R25: {=INDEX('MTA 28-09'!L:L,MATCH(B25,'MTA 28-09'!A:A,0))} -> A | S25: {=INDEX('MTA 28-09'!X:X,MATCH(B25,'MTA 28-09'!A:A,0))} -> REQUISIÇÃO | T25: {=INDEX('MTA 28-09'!W:W,MATCH(B25,'MTA 28-09'!A:A,0))} -> Não | U25: {=INDEX('MTA 28-09'!AE:AE,MATCH(B25,'MTA 28-09'!A:A,0))} -> 46260
A26: C-97 | B26: 10260 | C26: {=INDEX('MTA 28-09'!B:B,MATCH(B26,'MTA 28-09'!A:A,0))} -> NÃO | D26: {=INDEX('MTA 28-09'!D:D,MATCH(B26,'MTA 28-09'!A:A,0))} | E26: {=INDEX('MTA 28-09'!F:F,MATCH(B26,'MTA 28-09'!A:A,0))} -> BLOQUEIO | F26: {=INDEX('MTA 28-09'!I:I,MATCH(B26,'MTA 28-09'!A:A,0))} | G26: {=INDEX('MTA 28-09'!J:J,MATCH(B26,'MTA 28-09'!A:A,0))} | J26: LIVRE | L26: {=INDEX('MTA 28-09'!S:S,MATCH(B26,'MTA 28-09'!A:A,0))} -> C-97 | M26: {=INDEX('MTA 28-09'!T:T,MATCH(B26,'MTA 28-09'!A:A,0))} -> Requisição CABW | N26: {=INDEX('MTA 28-09'!U:U,MATCH(B26,'MTA 28-09'!A:A,0))} -> Publicação | O26: {=INDEX('MTA 28-09'!AC:AC,MATCH(B26,'MTA 28-09'!A:A,0))} -> 501640.62 | P26: {=INDEX('MTA 28-09'!N:N,MATCH(B26,'MTA 28-09'!A:A,0))} -> CABW | Q26: {=INDEX('MTA 28-09'!Z:Z,MATCH(B26,'MTA 28-09'!A:A,0))} -> 339039 | R26: {=INDEX('MTA 28-09'!L:L,MATCH(B26,'MTA 28-09'!A:A,0))} -> B | S26: {=INDEX('MTA 28-09'!X:X,MATCH(B26,'MTA 28-09'!A:A,0))} -> REQUISIÇÃO | T26: {=INDEX('MTA 28-09'!W:W,MATCH(B26,'MTA 28-09'!A:A,0))} -> Não | U26: {=INDEX('MTA 28-09'!AE:AE,MATCH(B26,'MTA 28-09'!A:A,0))} -> 46291
A27: C-97 | B27: 10261 | C27: {=INDEX('MTA 28-09'!B:B,MATCH(B27,'MTA 28-09'!A:A,0))} -> SIM | D27: {=INDEX('MTA 28-09'!D:D,MATCH(B27,'MTA 28-09'!A:A,0))} -> 2048 | E27: {=INDEX('MTA 28-09'!F:F,MATCH(B27,'MTA 28-09'!A:A,0))} -> ATENDIDO | F27: {=INDEX('MTA 28-09'!I:I,MATCH(B27,'MTA 28-09'!A:A,0))} -> 46098 | G27: {=INDEX('MTA 28-09'!J:J,MATCH(B27,'MTA 28-09'!A:A,0))} -> C26155 | H27: email do dia 11/03 | L27: {=INDEX('MTA 28-09'!S:S,MATCH(B27,'MTA 28-09'!A:A,0))} -> C-97 | M27: {=INDEX('MTA 28-09'!T:T,MATCH(B27,'MTA 28-09'!A:A,0))} -> Contrato inexigibilidade EMBRAER | N27: {=INDEX('MTA 28-09'!U:U,MATCH(B27,'MTA 28-09'!A:A,0))} -> Publicação | O27: {=INDEX('MTA 28-09'!AC:AC,MATCH(B27,'MTA 28-09'!A:A,0))} -> 48359.38 | P27: {=INDEX('MTA 28-09'!N:N,MATCH(B27,'MTA 28-09'!A:A,0))} -> CELOG | Q27: {=INDEX('MTA 28-09'!Z:Z,MATCH(B27,'MTA 28-09'!A:A,0))} -> 339039 | R27: {=INDEX('MTA 28-09'!L:L,MATCH(B27,'MTA 28-09'!A:A,0))} -> A | S27: {=INDEX('MTA 28-09'!X:X,MATCH(B27,'MTA 28-09'!A:A,0))} -> REQUISIÇÃO | T27: {=INDEX('MTA 28-09'!W:W,MATCH(B27,'MTA 28-09'!A:A,0))} -> Não | U27: {=INDEX('MTA 28-09'!AE:AE,MATCH(B27,'MTA 28-09'!A:A,0))} -> 46107
A28: C-97 | B28: 10280 | C28: {=INDEX('MTA 28-09'!B:B,MATCH(B28,'MTA 28-09'!A:A,0))} -> SIM | D28: {=INDEX('MTA 28-09'!D:D,MATCH(B28,'MTA 28-09'!A:A,0))} -> 2048 | E28: {=INDEX('MTA 28-09'!F:F,MATCH(B28,'MTA 28-09'!A:A,0))} | F28: {=INDEX('MTA 28-09'!I:I,MATCH(B28,'MTA 28-09'!A:A,0))} | G28: {=INDEX('MTA 28-09'!J:J,MATCH(B28,'MTA 28-09'!A:A,0))} | H28: 46276 | I28: Atender | J28: LIVRE | L28: {=INDEX('MTA 28-09'!S:S,MATCH(B28,'MTA 28-09'!A:A,0))} -> C-97 | M28: {=INDEX('MTA 28-09'!T:T,MATCH(B28,'MTA 28-09'!A:A,0))} -> Requisição CABW | N28: {=INDEX('MTA 28-09'!U:U,MATCH(B28,'MTA 28-09'!A:A,0))} -> Requisição Consumíveis | O28: {=INDEX('MTA 28-09'!AC:AC,MATCH(B28,'MTA 28-09'!A:A,0))} -> 235062.94 | P28: {=INDEX('MTA 28-09'!N:N,MATCH(B28,'MTA 28-09'!A:A,0))} -> CABW | Q28: {=INDEX('MTA 28-09'!Z:Z,MATCH(B28,'MTA 28-09'!A:A,0))} -> 339030 | R28: {=INDEX('MTA 28-09'!L:L,MATCH(B28,'MTA 28-09'!A:A,0))} -> A | S28: {=INDEX('MTA 28-09'!X:X,MATCH(B28,'MTA 28-09'!A:A,0))} -> REQUISIÇÃO | T28: {=INDEX('MTA 28-09'!W:W,MATCH(B28,'MTA 28-09'!A:A,0))} -> Não | U28: {=INDEX('MTA 28-09'!AE:AE,MATCH(B28,'MTA 28-09'!A:A,0))} -> 46291
A29: C-97 | B29: 10281 | C29: {=INDEX('MTA 28-09'!B:B,MATCH(B29,'MTA 28-09'!A:A,0))} -> SIM | D29: {=INDEX('MTA 28-09'!D:D,MATCH(B29,'MTA 28-09'!A:A,0))} -> 2048 | E29: {=INDEX('MTA 28-09'!F:F,MATCH(B29,'MTA 28-09'!A:A,0))} -> ATENDIDO | F29: {=INDEX('MTA 28-09'!I:I,MATCH(B29,'MTA 28-09'!A:A,0))} -> 46192 | G29: {=INDEX('MTA 28-09'!J:J,MATCH(B29,'MTA 28-09'!A:A,0))} -> C26121 | H29: email do dia 25/05 | L29: {=INDEX('MTA 28-09'!S:S,MATCH(B29,'MTA 28-09'!A:A,0))} -> C-97 | M29: {=INDEX('MTA 28-09'!T:T,MATCH(B29,'MTA 28-09'!A:A,0))} -> Requisição CABW | N29: {=INDEX('MTA 28-09'!U:U,MATCH(B29,'MTA 28-09'!A:A,0))} -> Atualização de GPS | O29: {=INDEX('MTA 28-09'!AC:AC,MATCH(B29,'MTA 28-09'!A:A,0))} -> 37180 | P29: {=INDEX('MTA 28-09'!N:N,MATCH(B29,'MTA 28-09'!A:A,0))} -> CABW | Q29: {=INDEX('MTA 28-09'!Z:Z,MATCH(B29,'MTA 28-09'!A:A,0))} -> 339039 | R29: {=INDEX('MTA 28-09'!L:L,MATCH(B29,'MTA 28-09'!A:A,0))} -> A | S29: {=INDEX('MTA 28-09'!X:X,MATCH(B29,'MTA 28-09'!A:A,0))} -> REQUISIÇÃO | T29: {=INDEX('MTA 28-09'!W:W,MATCH(B29,'MTA 28-09'!A:A,0))} -> Não | U29: {=INDEX('MTA 28-09'!AE:AE,MATCH(B29,'MTA 28-09'!A:A,0))} -> 46291
A30: C-98 | B30: 10300 | C30: {=INDEX('MTA 28-09'!B:B,MATCH(B30,'MTA 28-09'!A:A,0))} -> SIM | D30: {=INDEX('MTA 28-09'!D:D,MATCH(B30,'MTA 28-09'!A:A,0))} -> 2048 | E30: {=INDEX('MTA 28-09'!F:F,MATCH(B30,'MTA 28-09'!A:A,0))} | F30: {=INDEX('MTA 28-09'!I:I,MATCH(B30,'MTA 28-09'!A:A,0))} | G30: {=INDEX('MTA 28-09'!J:J,MATCH(B30,'MTA 28-09'!A:A,0))} | H30: 46276 | I30: Atender | J30: LIVRE | L30: {=INDEX('MTA 28-09'!S:S,MATCH(B30,'MTA 28-09'!A:A,0))} -> C-98 | M30: {=INDEX('MTA 28-09'!T:T,MATCH(B30,'MTA 28-09'!A:A,0))} -> Requisição CABW | N30: {=INDEX('MTA 28-09'!U:U,MATCH(B30,'MTA 28-09'!A:A,0))} -> Requisição Consumíveis | O30: {=INDEX('MTA 28-09'!AC:AC,MATCH(B30,'MTA 28-09'!A:A,0))} -> 135000 | P30: {=INDEX('MTA 28-09'!N:N,MATCH(B30,'MTA 28-09'!A:A,0))} -> CABW | Q30: {=INDEX('MTA 28-09'!Z:Z,MATCH(B30,'MTA 28-09'!A:A,0))} -> 339030 | R30: {=INDEX('MTA 28-09'!L:L,MATCH(B30,'MTA 28-09'!A:A,0))} -> A | S30: {=INDEX('MTA 28-09'!X:X,MATCH(B30,'MTA 28-09'!A:A,0))} -> REQUISIÇÃO | T30: {=INDEX('MTA 28-09'!W:W,MATCH(B30,'MTA 28-09'!A:A,0))} -> Não | U30: {=INDEX('MTA 28-09'!AE:AE,MATCH(B30,'MTA 28-09'!A:A,0))} -> 46291
A31: IU-93M | B31: 10320 | C31: {=INDEX('MTA 28-09'!B:B,MATCH(B31,'MTA 28-09'!A:A,0))} -> NÃO | D31: {=INDEX('MTA 28-09'!D:D,MATCH(B31,'MTA 28-09'!A:A,0))} | E31: {=INDEX('MTA 28-09'!F:F,MATCH(B31,'MTA 28-09'!A:A,0))} | F31: {=INDEX('MTA 28-09'!I:I,MATCH(B31,'MTA 28-09'!A:A,0))} | G31: {=INDEX('MTA 28-09'!J:J,MATCH(B31,'MTA 28-09'!A:A,0))} | J31: restante livre | L31: {=INDEX('MTA 28-09'!S:S,MATCH(B31,'MTA 28-09'!A:A,0))} -> IU-93M | M31: {=INDEX('MTA 28-09'!T:T,MATCH(B31,'MTA 28-09'!A:A,0))} -> Requisição CABW | N31: {=INDEX('MTA 28-09'!U:U,MATCH(B31,'MTA 28-09'!A:A,0))} -> Atualização de GPS | O31: {=INDEX('MTA 28-09'!AC:AC,MATCH(B31,'MTA 28-09'!A:A,0))} -> 435113.38 | P31: {=INDEX('MTA 28-09'!N:N,MATCH(B31,'MTA 28-09'!A:A,0))} -> CABW | Q31: {=INDEX('MTA 28-09'!Z:Z,MATCH(B31,'MTA 28-09'!A:A,0))} -> 339039 | R31: {=INDEX('MTA 28-09'!L:L,MATCH(B31,'MTA 28-09'!A:A,0))} -> B | S31: {=INDEX('MTA 28-09'!X:X,MATCH(B31,'MTA 28-09'!A:A,0))} -> REQUISIÇÃO | T31: {=INDEX('MTA 28-09'!W:W,MATCH(B31,'MTA 28-09'!A:A,0))} -> Não | U31: {=INDEX('MTA 28-09'!AE:AE,MATCH(B31,'MTA 28-09'!A:A,0))} -> 46260
A32: IU-93M | B32: 10321 | C32: {=INDEX('MTA 28-09'!B:B,MATCH(B32,'MTA 28-09'!A:A,0))} -> SIM | D32: {=INDEX('MTA 28-09'!D:D,MATCH(B32,'MTA 28-09'!A:A,0))} -> 20XV | E32: {=INDEX('MTA 28-09'!F:F,MATCH(B32,'MTA 28-09'!A:A,0))} -> ATENDIDO | F32: {=INDEX('MTA 28-09'!I:I,MATCH(B32,'MTA 28-09'!A:A,0))} -> 46098 | G32: {=INDEX('MTA 28-09'!J:J,MATCH(B32,'MTA 28-09'!A:A,0))} -> C26059 | H32: email do dia 11/03 | L32: {=INDEX('MTA 28-09'!S:S,MATCH(B32,'MTA 28-09'!A:A,0))} -> IU-93M | M32: {=INDEX('MTA 28-09'!T:T,MATCH(B32,'MTA 28-09'!A:A,0))} -> Requisição CABW | N32: {=INDEX('MTA 28-09'!U:U,MATCH(B32,'MTA 28-09'!A:A,0))} -> Atualização de GPS | O32: {=INDEX('MTA 28-09'!AC:AC,MATCH(B32,'MTA 28-09'!A:A,0))} -> 133812 | P32: {=INDEX('MTA 28-09'!N:N,MATCH(B32,'MTA 28-09'!A:A,0))} -> CABW | Q32: {=INDEX('MTA 28-09'!Z:Z,MATCH(B32,'MTA 28-09'!A:A,0))} -> 339039 | R32: {=INDEX('MTA 28-09'!L:L,MATCH(B32,'MTA 28-09'!A:A,0))} -> A | S32: {=INDEX('MTA 28-09'!X:X,MATCH(B32,'MTA 28-09'!A:A,0))} -> REQUISIÇÃO | T32: {=INDEX('MTA 28-09'!W:W,MATCH(B32,'MTA 28-09'!A:A,0))} -> Não | U32: {=INDEX('MTA 28-09'!AE:AE,MATCH(B32,'MTA 28-09'!A:A,0))} -> 46107
A33: IU-93M | B33: 10322 | C33: {=INDEX('MTA 28-09'!B:B,MATCH(B33,'MTA 28-09'!A:A,0))} -> SIM | D33: {=INDEX('MTA 28-09'!D:D,MATCH(B33,'MTA 28-09'!A:A,0))} -> 20XV | E33: {=INDEX('MTA 28-09'!F:F,MATCH(B33,'MTA 28-09'!A:A,0))} -> ATENDIDO | F33: {=INDEX('MTA 28-09'!I:I,MATCH(B33,'MTA 28-09'!A:A,0))} -> 46210 | G33: {=INDEX('MTA 28-09'!J:J,MATCH(B33,'MTA 28-09'!A:A,0))} -> C26059 | H33: email do dia 19/06 | L33: {=INDEX('MTA 28-09'!S:S,MATCH(B33,'MTA 28-09'!A:A,0))} -> IU-93M | M33: {=INDEX('MTA 28-09'!T:T,MATCH(B33,'MTA 28-09'!A:A,0))} -> Requisição CABW | N33: {=INDEX('MTA 28-09'!U:U,MATCH(B33,'MTA 28-09'!A:A,0))} -> Atualização de GPS | O33: {=INDEX('MTA 28-09'!AC:AC,MATCH(B33,'MTA 28-09'!A:A,0))} -> 616082.32 | P33: {=INDEX('MTA 28-09'!N:N,MATCH(B33,'MTA 28-09'!A:A,0))} -> CABW | Q33: {=INDEX('MTA 28-09'!Z:Z,MATCH(B33,'MTA 28-09'!A:A,0))} -> 339039 | R33: {=INDEX('MTA 28-09'!L:L,MATCH(B33,'MTA 28-09'!A:A,0))} -> A | S33: {=INDEX('MTA 28-09'!X:X,MATCH(B33,'MTA 28-09'!A:A,0))} -> REQUISIÇÃO | T33: {=INDEX('MTA 28-09'!W:W,MATCH(B33,'MTA 28-09'!A:A,0))} -> Não | U33: {=INDEX('MTA 28-09'!AE:AE,MATCH(B33,'MTA 28-09'!A:A,0))} -> 46260
A34: IU-93M | B34: 10340 | C34: {=INDEX('MTA 28-09'!B:B,MATCH(B34,'MTA 28-09'!A:A,0))} -> SIM | D34: {=INDEX('MTA 28-09'!D:D,MATCH(B34,'MTA 28-09'!A:A,0))} -> 20XV | E34: {=INDEX('MTA 28-09'!F:F,MATCH(B34,'MTA 28-09'!A:A,0))} -> CANCELADO | F34: {=INDEX('MTA 28-09'!I:I,MATCH(B34,'MTA 28-09'!A:A,0))} | G34: {=INDEX('MTA 28-09'!J:J,MATCH(B34,'MTA 28-09'!A:A,0))} | H34: 1 | L34: {=INDEX('MTA 28-09'!S:S,MATCH(B34,'MTA 28-09'!A:A,0))} -> IU-93M | M34: {=INDEX('MTA 28-09'!T:T,MATCH(B34,'MTA 28-09'!A:A,0))} -> CNT 061/CAE-PAMALS/2020 | N34: {=INDEX('MTA 28-09'!U:U,MATCH(B34,'MTA 28-09'!A:A,0))} -> MPI autorizado pela DIRMAB | O34: {=INDEX('MTA 28-09'!AC:AC,MATCH(B34,'MTA 28-09'!A:A,0))} -> - | P34: {=INDEX('MTA 28-09'!N:N,MATCH(B34,'MTA 28-09'!A:A,0))} -> CELOG | Q34: {=INDEX('MTA 28-09'!Z:Z,MATCH(B34,'MTA 28-09'!A:A,0))} -> 339039 | R34: {=INDEX('MTA 28-09'!L:L,MATCH(B34,'MTA 28-09'!A:A,0))} -> A | S34: {=INDEX('MTA 28-09'!X:X,MATCH(B34,'MTA 28-09'!A:A,0))} -> SOB DEMANDA | T34: {=INDEX('MTA 28-09'!W:W,MATCH(B34,'MTA 28-09'!A:A,0))} -> SIM | U34: {=INDEX('MTA 28-09'!AE:AE,MATCH(B34,'MTA 28-09'!A:A,0))} -> 46107
A35: IU-93M | B35: 10341 | C35: {=INDEX('MTA 28-09'!B:B,MATCH(B35,'MTA 28-09'!A:A,0))} -> SIM | D35: {=INDEX('MTA 28-09'!D:D,MATCH(B35,'MTA 28-09'!A:A,0))} -> 20XV | E35: {=INDEX('MTA 28-09'!F:F,MATCH(B35,'MTA 28-09'!A:A,0))} -> ATENDIDO | F35: {=INDEX('MTA 28-09'!I:I,MATCH(B35,'MTA 28-09'!A:A,0))} -> 46191 | G35: {=INDEX('MTA 28-09'!J:J,MATCH(B35,'MTA 28-09'!A:A,0))} -> C26300 | L35: {=INDEX('MTA 28-09'!S:S,MATCH(B35,'MTA 28-09'!A:A,0))} -> IU-93M | M35: {=INDEX('MTA 28-09'!T:T,MATCH(B35,'MTA 28-09'!A:A,0))} -> CNT 061/CAE-PAMALS/2020 | N35: {=INDEX('MTA 28-09'!U:U,MATCH(B35,'MTA 28-09'!A:A,0))} -> MPI autorizado pela DIRMAB | O35: {=INDEX('MTA 28-09'!AC:AC,MATCH(B35,'MTA 28-09'!A:A,0))} -> 3000000 | P35: {=INDEX('MTA 28-09'!N:N,MATCH(B35,'MTA 28-09'!A:A,0))} -> CELOG | Q35: {=INDEX('MTA 28-09'!Z:Z,MATCH(B35,'MTA 28-09'!A:A,0))} -> 339030 | R35: {=INDEX('MTA 28-09'!L:L,MATCH(B35,'MTA 28-09'!A:A,0))} -> A | S35: {=INDEX('MTA 28-09'!X:X,MATCH(B35,'MTA 28-09'!A:A,0))} -> SOB DEMANDA | T35: {=INDEX('MTA 28-09'!W:W,MATCH(B35,'MTA 28-09'!A:A,0))} -> SIM | U35: {=INDEX('MTA 28-09'!AE:AE,MATCH(B35,'MTA 28-09'!A:A,0))}
A36: SSS | B36: 10360 | C36: {=INDEX('MTA 28-09'!B:B,MATCH(B36,'MTA 28-09'!A:A,0))} -> NÃO | D36: {=INDEX('MTA 28-09'!D:D,MATCH(B36,'MTA 28-09'!A:A,0))} | E36: {=INDEX('MTA 28-09'!F:F,MATCH(B36,'MTA 28-09'!A:A,0))} -> BLOQUEIO | F36: {=INDEX('MTA 28-09'!I:I,MATCH(B36,'MTA 28-09'!A:A,0))} | G36: {=INDEX('MTA 28-09'!J:J,MATCH(B36,'MTA 28-09'!A:A,0))} | L36: {=INDEX('MTA 28-09'!S:S,MATCH(B36,'MTA 28-09'!A:A,0))} -> APOIO | M36: {=INDEX('MTA 28-09'!T:T,MATCH(B36,'MTA 28-09'!A:A,0))} -> REQUISIÇÃO SSS TLV | N36: {=INDEX('MTA 28-09'!U:U,MATCH(B36,'MTA 28-09'!A:A,0))} -> AQUISIÇÃO ITENS SSS COM TEMPO LIMITE DE VIDA (CABW) 1/3 | O36: {=INDEX('MTA 28-09'!AC:AC,MATCH(B36,'MTA 28-09'!A:A,0))} -> 1679899.8 | P36: {=INDEX('MTA 28-09'!N:N,MATCH(B36,'MTA 28-09'!A:A,0))} -> CABW | Q36: {=INDEX('MTA 28-09'!Z:Z,MATCH(B36,'MTA 28-09'!A:A,0))} -> 339030 | R36: {=INDEX('MTA 28-09'!L:L,MATCH(B36,'MTA 28-09'!A:A,0))} -> B | S36: {=INDEX('MTA 28-09'!X:X,MATCH(B36,'MTA 28-09'!A:A,0))} -> REQUISIÇÃO | T36: {=INDEX('MTA 28-09'!W:W,MATCH(B36,'MTA 28-09'!A:A,0))} -> NÃO | U36: {=INDEX('MTA 28-09'!AE:AE,MATCH(B36,'MTA 28-09'!A:A,0))} -> 46049
A37: SSS | B37: 10380 | C37: {=INDEX('MTA 28-09'!B:B,MATCH(B37,'MTA 28-09'!A:A,0))} -> SIM | D37: {=INDEX('MTA 28-09'!D:D,MATCH(B37,'MTA 28-09'!A:A,0))} -> 2048 | E37: {=INDEX('MTA 28-09'!F:F,MATCH(B37,'MTA 28-09'!A:A,0))} -> ATENDIDO | F37: {=INDEX('MTA 28-09'!I:I,MATCH(B37,'MTA 28-09'!A:A,0))} -> 46063 | G37: {=INDEX('MTA 28-09'!J:J,MATCH(B37,'MTA 28-09'!A:A,0))} -> C26015 | H37: 1 | L37: {=INDEX('MTA 28-09'!S:S,MATCH(B37,'MTA 28-09'!A:A,0))} -> APOIO | M37: {=INDEX('MTA 28-09'!T:T,MATCH(B37,'MTA 28-09'!A:A,0))} -> REQUISIÇÃO PTA SSS | N37: {=INDEX('MTA 28-09'!U:U,MATCH(B37,'MTA 28-09'!A:A,0))} -> AQUISIÇÃO ITENS SSS CUMPRIR PTA (CABW) 1/2 | O37: {=INDEX('MTA 28-09'!AC:AC,MATCH(B37,'MTA 28-09'!A:A,0))} -> 760240.53 | P37: {=INDEX('MTA 28-09'!N:N,MATCH(B37,'MTA 28-09'!A:A,0))} -> CABW | Q37: {=INDEX('MTA 28-09'!Z:Z,MATCH(B37,'MTA 28-09'!A:A,0))} -> 339030 | R37: {=INDEX('MTA 28-09'!L:L,MATCH(B37,'MTA 28-09'!A:A,0))} -> A | S37: {=INDEX('MTA 28-09'!X:X,MATCH(B37,'MTA 28-09'!A:A,0))} -> REQUISIÇÃO | T37: {=INDEX('MTA 28-09'!W:W,MATCH(B37,'MTA 28-09'!A:A,0))} -> NÃO | U37: {=INDEX('MTA 28-09'!AE:AE,MATCH(B37,'MTA 28-09'!A:A,0))} -> 46107
A38: SSS | B38: 10400 | C38: {=INDEX('MTA 28-09'!B:B,MATCH(B38,'MTA 28-09'!A:A,0))} -> SIM | D38: {=INDEX('MTA 28-09'!D:D,MATCH(B38,'MTA 28-09'!A:A,0))} -> 2048 | E38: {=INDEX('MTA 28-09'!F:F,MATCH(B38,'MTA 28-09'!A:A,0))} | F38: {=INDEX('MTA 28-09'!I:I,MATCH(B38,'MTA 28-09'!A:A,0))} | G38: {=INDEX('MTA 28-09'!J:J,MATCH(B38,'MTA 28-09'!A:A,0))} | H38: 46276 | I38: Atender | L38: {=INDEX('MTA 28-09'!S:S,MATCH(B38,'MTA 28-09'!A:A,0))} -> APOIO | M38: {=INDEX('MTA 28-09'!T:T,MATCH(B38,'MTA 28-09'!A:A,0))} -> REQUISIÇÃO PTA SSS | N38: {=INDEX('MTA 28-09'!U:U,MATCH(B38,'MTA 28-09'!A:A,0))} -> AQUISIÇÃO DE ITENS SSS PARA CUMPRIR PTA | O38: {=INDEX('MTA 28-09'!AC:AC,MATCH(B38,'MTA 28-09'!A:A,0))} -> 5172.75 | P38: {=INDEX('MTA 28-09'!N:N,MATCH(B38,'MTA 28-09'!A:A,0))} -> CABW | Q38: {=INDEX('MTA 28-09'!Z:Z,MATCH(B38,'MTA 28-09'!A:A,0))} -> 339030 | R38: {=INDEX('MTA 28-09'!L:L,MATCH(B38,'MTA 28-09'!A:A,0))} -> A | S38: {=INDEX('MTA 28-09'!X:X,MATCH(B38,'MTA 28-09'!A:A,0))} -> REQUISIÇÃO | T38: {=INDEX('MTA 28-09'!W:W,MATCH(B38,'MTA 28-09'!A:A,0))} -> NÃO | U38: {=INDEX('MTA 28-09'!AE:AE,MATCH(B38,'MTA 28-09'!A:A,0))} -> 46049
A39: T-27 | B39: 10420 | C39: {=INDEX('MTA 28-09'!B:B,MATCH(B39,'MTA 28-09'!A:A,0))} -> SIM | D39: {=INDEX('MTA 28-09'!D:D,MATCH(B39,'MTA 28-09'!A:A,0))} -> 2048 | E39: {=INDEX('MTA 28-09'!F:F,MATCH(B39,'MTA 28-09'!A:A,0))} -> ATENDIDO | F39: {=INDEX('MTA 28-09'!I:I,MATCH(B39,'MTA 28-09'!A:A,0))} -> 46041 | G39: {=INDEX('MTA 28-09'!J:J,MATCH(B39,'MTA 28-09'!A:A,0))} -> C26054 | H39: 1 | L39: {=INDEX('MTA 28-09'!S:S,MATCH(B39,'MTA 28-09'!A:A,0))} -> T-27 | M39: {=INDEX('MTA 28-09'!T:T,MATCH(B39,'MTA 28-09'!A:A,0))} -> CTT 009/CELOG-PAMALS/2025 – Aquisição de Consumíveis | N39: {=INDEX('MTA 28-09'!U:U,MATCH(B39,'MTA 28-09'!A:A,0))} -> Sob demanda 1/8 | O39: {=INDEX('MTA 28-09'!AC:AC,MATCH(B39,'MTA 28-09'!A:A,0))} -> 1130000 | P39: {=INDEX('MTA 28-09'!N:N,MATCH(B39,'MTA 28-09'!A:A,0))} -> CELOG | Q39: {=INDEX('MTA 28-09'!Z:Z,MATCH(B39,'MTA 28-09'!A:A,0))} -> 339030 | R39: {=INDEX('MTA 28-09'!L:L,MATCH(B39,'MTA 28-09'!A:A,0))} -> A | S39: {=INDEX('MTA 28-09'!X:X,MATCH(B39,'MTA 28-09'!A:A,0))} -> SOB DEMANDA | T39: {=INDEX('MTA 28-09'!W:W,MATCH(B39,'MTA 28-09'!A:A,0))} -> Não | U39: {=INDEX('MTA 28-09'!AE:AE,MATCH(B39,'MTA 28-09'!A:A,0))} -> 46107
A40: A-29 | B40: 10440 | C40: {=INDEX('MTA 28-09'!B:B,MATCH(B40,'MTA 28-09'!A:A,0))} -> SIM | D40: {=INDEX('MTA 28-09'!D:D,MATCH(B40,'MTA 28-09'!A:A,0))} -> 2048 | E40: {=INDEX('MTA 28-09'!F:F,MATCH(B40,'MTA 28-09'!A:A,0))} -> ATENDIDO | F40: {=INDEX('MTA 28-09'!I:I,MATCH(B40,'MTA 28-09'!A:A,0))} -> 46041 | G40: {=INDEX('MTA 28-09'!J:J,MATCH(B40,'MTA 28-09'!A:A,0))} -> C26059 | H40: 1 | L40: {=INDEX('MTA 28-09'!S:S,MATCH(B40,'MTA 28-09'!A:A,0))} -> A-29 | M40: {=INDEX('MTA 28-09'!T:T,MATCH(B40,'MTA 28-09'!A:A,0))} -> CTT 102/CELOG-PAMALS/2023 – EMBRAER - PSLI | N40: {=INDEX('MTA 28-09'!U:U,MATCH(B40,'MTA 28-09'!A:A,0))} -> Módulo Extra - Sob demanda 1/4 | O40: {=INDEX('MTA 28-09'!AC:AC,MATCH(B40,'MTA 28-09'!A:A,0))} -> 1294030.6 | P40: {=INDEX('MTA 28-09'!N:N,MATCH(B40,'MTA 28-09'!A:A,0))} -> CELOG | Q40: {=INDEX('MTA 28-09'!Z:Z,MATCH(B40,'MTA 28-09'!A:A,0))} -> 339039 | R40: {=INDEX('MTA 28-09'!L:L,MATCH(B40,'MTA 28-09'!A:A,0))} -> A | S40: {=INDEX('MTA 28-09'!X:X,MATCH(B40,'MTA 28-09'!A:A,0))} -> SOB DEMANDA | T40: {=INDEX('MTA 28-09'!W:W,MATCH(B40,'MTA 28-09'!A:A,0))} -> Não | U40: {=INDEX('MTA 28-09'!AE:AE,MATCH(B40,'MTA 28-09'!A:A,0))} -> 46107
...

Sheet Indução de material
B1: Previsão Serviço/material induzido SEM orçamento aprovado | C1: Serviço/material induzido COM orçamento aprovado
A2: 124/CAE-PAMALS/2022 | B2: 0 | C2: 1752159.1
A3: 096/CAE-PAMALS/2021 | B3: 1500000 | C3: 1125839.4
A4: 048/CAE-PAMALS/2022 | B4: 0 | C4: 222000.98
A5: 024/CELOG-PAMALS/2022 | B5: 26866.71 | C5: 2318718
A6: 040/CELOG-PAMALS/2022 | B6: 390000 | C6: 0
A7: 012/CELOG-PAMALS/2026
A8: 039/CELOG-PAMALS/2025 | B8: 0 | C8: 26684804
A9: 102/CELOG-PAMALS/2023 | B9: =20000+50000+40000+180000*20+1500000+460000+1000000 -> 6670000 | C9: =6833000+5756655+600000+500000+150000 -> 13839655
A10: 040/CELOG-PAMALS/2025 | B10: 242000 | C10: 288553
A11: 028/CELOG-PAMALS/2025 | B11: 0 | C11: 3671861.8
A12: 049/CELOG-PAMALS/2024 | B12: 0 | C12: 5882093.5
A13: 039/CABW-PAMALS/2024 | B13: 0 | C13: 4185411.6
A14: 005/CELOG-PAMALS/2025 | B14: 0 | C14: 0
A15: 009/CELOG-PAMALS/2025 | B15: 0 | C15: 3251894.3
A16: 016/CELOG-PAMALS/2025 | B16: 0 | C16: 28666.97
A17: 032/CELOG-PAMALS/2025 | B17: 0 | C17: 350432

Sheet PAINEL
A1: Célula
B2: A | C2: B | D2: C | E2: D | F2: Valor já atendido | G2: Valor aprovado | H2: Solicitado | I2: Parcela Fixa/HV não solicitado | J2: Valor a solicitar
A3: A-29 | B3: =SUMIFS('Solicitações'!$O:$O,'Solicitações'!$L:$L,$A3,'Solicitações'!$R:$R,B$2,'Solicitações'!$T:$T,"NÃO")-SUMIFS('Solicitações'!$O:$O,'Solicitações'!$L:$L,$A3,'Solicitações'!$R:$R,B$2,'Solicitações'!$T:$T,"NÃO",'Solicitações'!$C:$C,"RAP)") -> 1.0093971e+08 | C3: =SUMIFS('Solicitações'!$O:$O,'Solicitações'!$L:$L,$A3,'Solicitações'!$R:$R,C$2,'Solicitações'!$T:$T,"NÃO")-SUMIFS('Solicitações'!$O:$O,'Solicitações'!$L:$L,$A3,'Solicitações'!$R:$R,C$2,'Solicitações'!$T:$T,"NÃO",'Solicitações'!$C:$C,"RAP)") -> 150000 | D3: =SUMIFS('Solicitações'!$O:$O,'Solicitações'!$L:$L,$A3,'Solicitações'!$R:$R,D$2,'Solicitações'!$T:$T,"NÃO")-SUMIFS('Solicitações'!$O:$O,'Solicitações'!$L:$L,$A3,'Solicitações'!$R:$R,D$2,'Solicitações'!$T:$T,"NÃO",'Solicitações'!$C:$C,"RAP)") -> 23712543 | E3: =SUMIFS('Solicitações'!$O:$O,'Solicitações'!$L:$L,$A3,'Solicitações'!$R:$R,E$2,'Solicitações'!$T:$T,"NÃO")-SUMIFS('Solicitações'!$O:$O,'Solicitações'!$L:$L,$A3,'Solicitações'!$R:$R,E$2,'Solicitações'!$T:$T,"NÃO",'Solicitações'!$C:$C,"RAP)") -> 8561736.7 | F3: =SUMIFS('Solicitações'!$O:$O,'Solicitações'!$L:$L,$A3,'Solicitações'!$T:$T,"NÃO",'Solicitações'!E:E,"ATENDIDO")-SUMIFS('Solicitações'!$O:$O,'Solicitações'!$L:$L,$A3,'Solicitações'!$T:$T,"NÃO",'Solicitações'!E:E,"ATENDIDO",'Solicitações'!$R:$R,"RAP") -> 68490679 | G3: =SUMIFS('Solicitações'!$O:$O,'Solicitações'!$L:$L,$A3,'Solicitações'!$T:$T,"NÃO",'Solicitações'!C:C,"SIM")-SUMIFS('Solicitações'!$O:$O,'Solicitações'!$L:$L,$A3,'Solicitações'!$R:$R,"RAP",'Solicitações'!$T:$T,"NÃO") -> 1.0950145e+08 | H3: =SUMIFS('Solicitações'!$O:$O,'Solicitações'!$L:$L,$A3,'Solicitações'!$T:$T,"NÃO",'Solicitações'!E:E,"<>ATENDIDO",'Solicitações'!I:I,"<>",'Solicitações'!C:C,"SIM") -> 38672034 | I3: =SUMIFS('Solicitações'!$O:$O,'Solicitações'!$L:$L,$A3,'Solicitações'!$T:$T,"NÃO",'Solicitações'!E:E,"<>ATENDIDO",'Solicitações'!I:I,"",'Solicitações'!S:S,"HORA DE VOO",'Solicitações'!C:C,"SIM")+SUMIFS('Solicitações'!$O:$O,'Solicitações'!$L:$L,$A3,'Solicitações'!$T:$T,"NÃO",'Solicitações'!E:E,"<>ATENDIDO",'Solicitações'!I:I,"",'Solicitações'!S:S,"PARCELA FIXA",'Solicitações'!C:C,"SIM")-(SUMIFS('Solicitações'!$O:$O,'Solicitações'!$L:$L,$A3,'Solicitações'!$T:$T,"NÃO",'Solicitações'!E:E,"<>ATENDIDO",'Solicitações'!I:I,"",'Solicitações'!S:S,"HORA DE VOO",'Solicitações'!C:C,"SIM",'Solicitações'!$R:$R,"RAP")+SUMIFS('Solicitações'!$O:$O,'Solicitações'!$L:$L,$A3,'Solicitações'!$T:$T,"NÃO",'Solicitações'!E:E,"<>ATENDIDO",'Solicitações'!I:I,"",'Solicitações'!S:S,"PARCELA FIXA",'Solicitações'!C:C,"SIM",'Solicitações'!$R:$R,"RAP")) -> 2310000 | J3: =G3-F3-H3-I3 -> 28736.69
A4: C-95M | B4: =SUMIFS('Solicitações'!$O:$O,'Solicitações'!$L:$L,$A4,'Solicitações'!$R:$R,B$2,'Solicitações'!$T:$T,"NÃO")-SUMIFS('Solicitações'!$O:$O,'Solicitações'!$L:$L,$A4,'Solicitações'!$R:$R,B$2,'Solicitações'!$T:$T,"NÃO",'Solicitações'!$C:$C,"RAP)") -> 20604593 | C4: =SUMIFS('Solicitações'!$O:$O,'Solicitações'!$L:$L,$A4,'Solicitações'!$R:$R,C$2,'Solicitações'!$T:$T,"NÃO")-SUMIFS('Solicitações'!$O:$O,'Solicitações'!$L:$L,$A4,'Solicitações'!$R:$R,C$2,'Solicitações'!$T:$T,"NÃO",'Solicitações'!$C:$C,"RAP)") -> 8657582.3 | D4: =SUMIFS('Solicitações'!$O:$O,'Solicitações'!$L:$L,$A4,'Solicitações'!$R:$R,D$2,'Solicitações'!$T:$T,"NÃO")-SUMIFS('Solicitações'!$O:$O,'Solicitações'!$L:$L,$A4,'Solicitações'!$R:$R,D$2,'Solicitações'!$T:$T,"NÃO",'Solicitações'!$C:$C,"RAP)") -> 15993894 | E4: =SUMIFS('Solicitações'!$O:$O,'Solicitações'!$L:$L,$A4,'Solicitações'!$R:$R,E$2,'Solicitações'!$T:$T,"NÃO")-SUMIFS('Solicitações'!$O:$O,'Solicitações'!$L:$L,$A4,'Solicitações'!$R:$R,E$2,'Solicitações'!$T:$T,"NÃO",'Solicitações'!$C:$C,"RAP)") -> 0 | F4: =SUMIFS('Solicitações'!$O:$O,'Solicitações'!$L:$L,$A4,'Solicitações'!$T:$T,"NÃO",'Solicitações'!E:E,"ATENDIDO")-SUMIFS('Solicitações'!$O:$O,'Solicitações'!$L:$L,$A4,'Solicitações'!$T:$T,"NÃO",'Solicitações'!E:E,"ATENDIDO",'Solicitações'!$R:$R,"RAP") -> 18284399 | G4: =SUMIFS('Solicitações'!$O:$O,'Solicitações'!$L:$L,$A4,'Solicitações'!$T:$T,"NÃO",'Solicitações'!C:C,"SIM")-SUMIFS('Solicitações'!$O:$O,'Solicitações'!$L:$L,$A4,'Solicitações'!$R:$R,"RAP",'Solicitações'!$T:$T,"NÃO") -> 20604593 | H4: =SUMIFS('Solicitações'!$O:$O,'Solicitações'!$L:$L,$A4,'Solicitações'!$T:$T,"NÃO",'Solicitações'!E:E,"<>ATENDIDO",'Solicitações'!I:I,"<>",'Solicitações'!C:C,"SIM") -> 2320194.4 | I4: =SUMIFS('Solicitações'!$O:$O,'Solicitações'!$L:$L,$A4,'Solicitações'!$T:$T,"NÃO",'Solicitações'!E:E,"<>ATENDIDO",'Solicitações'!I:I,"",'Solicitações'!S:S,"HORA DE VOO",'Solicitações'!C:C,"SIM")+SUMIFS('Solicitações'!$O:$O,'Solicitações'!$L:$L,$A4,'Solicitações'!$T:$T,"NÃO",'Solicitações'!E:E,"<>ATENDIDO",'Solicitações'!I:I,"",'Solicitações'!S:S,"PARCELA FIXA",'Solicitações'!C:C,"SIM")-(SUMIFS('Solicitações'!$O:$O,'Solicitações'!$L:$L,$A4,'Solicitações'!$T:$T,"NÃO",'Solicitações'!E:E,"<>ATENDIDO",'Solicitações'!I:I,"",'Solicitações'!S:S,"HORA DE VOO",'Solicitações'!C:C,"SIM",'Solicitações'!$R:$R,"RAP")+SUMIFS('Solicitações'!$O:$O,'Solicitações'!$L:$L,$A4,'Solicitações'!$T:$T,"NÃO",'Solicitações'!E:E,"<>ATENDIDO",'Solicitações'!I:I,"",'Solicitações'!S:S,"PARCELA FIXA",'Solicitações'!C:C,"SIM",'Solicitações'!$R:$R,"RAP")) -> 0 | J4: =G4-F4-H4-I4 -> 2.3283064e-09
A5: C-97 | B5: =SUMIFS('Solicitações'!$O:$O,'Solicitações'!$L:$L,$A5,'Solicitações'!$R:$R,B$2,'Solicitações'!$T:$T,"NÃO")-SUMIFS('Solicitações'!$O:$O,'Solicitações'!$L:$L,$A5,'Solicitações'!$R:$R,B$2,'Solicitações'!$T:$T,"NÃO",'Solicitações'!$C:$C,"RAP)") -> 21882444 | C5: =SUMIFS('Solicitações'!$O:$O,'Solicitações'!$L:$L,$A5,'Solicitações'!$R:$R,C$2,'Solicitações'!$T:$T,"NÃO")-SUMIFS('Solicitações'!$O:$O,'Solicitações'!$L:$L,$A5,'Solicitações'!$R:$R,C$2,'Solicitações'!$T:$T,"NÃO",'Solicitações'!$C:$C,"RAP)") -> 9805560.9 | D5: =SUMIFS('Solicitações'!$O:$O,'Solicitações'!$L:$L,$A5,'Solicitações'!$R:$R,D$2,'Solicitações'!$T:$T,"NÃO")-SUMIFS('Solicitações'!$O:$O,'Solicitações'!$L:$L,$A5,'Solicitações'!$R:$R,D$2,'Solicitações'!$T:$T,"NÃO",'Solicitações'!$C:$C,"RAP)") -> 23958627 | E5: =SUMIFS('Solicitações'!$O:$O,'Solicitações'!$L:$L,$A5,'Solicitações'!$R:$R,E$2,'Solicitações'!$T:$T,"NÃO")-SUMIFS('Solicitações'!$O:$O,'Solicitações'!$L:$L,$A5,'Solicitações'!$R:$R,E$2,'Solicitações'!$T:$T,"NÃO",'Solicitações'!$C:$C,"RAP)") -> 10120308 | F5: =SUMIFS('Solicitações'!$O:$O,'Solicitações'!$L:$L,$A5,'Solicitações'!$T:$T,"NÃO",'Solicitações'!E:E,"ATENDIDO")-SUMIFS('Solicitações'!$O:$O,'Solicitações'!$L:$L,$A5,'Solicitações'!$T:$T,"NÃO",'Solicitações'!E:E,"ATENDIDO",'Solicitações'!$R:$R,"RAP") -> 27192694 | G5: =SUMIFS('Solicitações'!$O:$O,'Solicitações'!$L:$L,$A5,'Solicitações'!$T:$T,"NÃO",'Solicitações'!C:C,"SIM")-SUMIFS('Solicitações'!$O:$O,'Solicitações'!$L:$L,$A5,'Solicitações'!$R:$R,"RAP",'Solicitações'!$T:$T,"NÃO") -> 29512752 | H5: =SUMIFS('Solicitações'!$O:$O,'Solicitações'!$L:$L,$A5,'Solicitações'!$T:$T,"NÃO",'Solicitações'!E:E,"<>ATENDIDO",'Solicitações'!I:I,"<>",'Solicitações'!C:C,"SIM") -> 345782.57 | I5: =SUMIFS('Solicitações'!$O:$O,'Solicitações'!$L:$L,$A5,'Solicitações'!$T:$T,"NÃO",'Solicitações'!E:E,"<>ATENDIDO",'Solicitações'!I:I,"",'Solicitações'!S:S,"HORA DE VOO",'Solicitações'!C:C,"SIM")+SUMIFS('Solicitações'!$O:$O,'Solicitações'!$L:$L,$A5,'Solicitações'!$T:$T,"NÃO",'Solicitações'!E:E,"<>ATENDIDO",'Solicitações'!I:I,"",'Solicitações'!S:S,"PARCELA FIXA",'Solicitações'!C:C,"SIM")-(SUMIFS('Solicitações'!$O:$O,'Solicitações'!$L:$L,$A5,'Solicitações'!$T:$T,"NÃO",'Solicitações'!E:E,"<>ATENDIDO",'Solicitações'!I:I,"",'Solicitações'!S:S,"HORA DE VOO",'Solicitações'!C:C,"SIM",'Solicitações'!$R:$R,"RAP")+SUMIFS('Solicitações'!$O:$O,'Solicitações'!$L:$L,$A5,'Solicitações'!$T:$T,"NÃO",'Solicitações'!E:E,"<>ATENDIDO",'Solicitações'!I:I,"",'Solicitações'!S:S,"PARCELA FIXA",'Solicitações'!C:C,"SIM",'Solicitações'!$R:$R,"RAP")) -> 0 | J5: =G5-F5-H5-I5 -> 1974275.1
A6: C-98 | B6: =SUMIFS('Solicitações'!$O:$O,'Solicitações'!$L:$L,$A6,'Solicitações'!$R:$R,B$2,'Solicitações'!$T:$T,"NÃO")-SUMIFS('Solicitações'!$O:$O,'Solicitações'!$L:$L,$A6,'Solicitações'!$R:$R,B$2,'Solicitações'!$T:$T,"NÃO",'Solicitações'!$C:$C,"RAP)") -> 18111550 | C6: =SUMIFS('Solicitações'!$O:$O,'Solicitações'!$L:$L,$A6,'Solicitações'!$R:$R,C$2,'Solicitações'!$T:$T,"NÃO")-SUMIFS('Solicitações'!$O:$O,'Solicitações'!$L:$L,$A6,'Solicitações'!$R:$R,C$2,'Solicitações'!$T:$T,"NÃO",'Solicitações'!$C:$C,"RAP)") -> 0 | D6: =SUMIFS('Solicitações'!$O:$O,'Solicitações'!$L:$L,$A6,'Solicitações'!$R:$R,D$2,'Solicitações'!$T:$T,"NÃO")-SUMIFS('Solicitações'!$O:$O,'Solicitações'!$L:$L,$A6,'Solicitações'!$R:$R,D$2,'Solicitações'!$T:$T,"NÃO",'Solicitações'!$C:$C,"RAP)") -> 3129713.5 | E6: =SUMIFS('Solicitações'!$O:$O,'Solicitações'!$L:$L,$A6,'Solicitações'!$R:$R,E$2,'Solicitações'!$T:$T,"NÃO")-SUMIFS('Solicitações'!$O:$O,'Solicitações'!$L:$L,$A6,'Solicitações'!$R:$R,E$2,'Solicitações'!$T:$T,"NÃO",'Solicitações'!$C:$C,"RAP)") -> 4460068.7 | F6: =SUMIFS('Solicitações'!$O:$O,'Solicitações'!$L:$L,$A6,'Solicitações'!$T:$T,"NÃO",'Solicitações'!E:E,"ATENDIDO")-SUMIFS('Solicitações'!$O:$O,'Solicitações'!$L:$L,$A6,'Solicitações'!$T:$T,"NÃO",'Solicitações'!E:E,"ATENDIDO",'Solicitações'!$R:$R,"RAP") -> 8992525.3 | G6: =SUMIFS('Solicitações'!$O:$O,'Solicitações'!$L:$L,$A6,'Solicitações'!$T:$T,"NÃO",'Solicitações'!C:C,"SIM")-SUMIFS('Solicitações'!$O:$O,'Solicitações'!$L:$L,$A6,'Solicitações'!$R:$R,"RAP",'Solicitações'!$T:$T,"NÃO") -> 20074528 | H6: =SUMIFS('Solicitações'!$O:$O,'Solicitações'!$L:$L,$A6,'Solicitações'!$T:$T,"NÃO",'Solicitações'!E:E,"<>ATENDIDO",'Solicitações'!I:I,"<>",'Solicitações'!C:C,"SIM") -> 11082002 | I6: =SUMIFS('Solicitações'!$O:$O,'Solicitações'!$L:$L,$A6,'Solicitações'!$T:$T,"NÃO",'Solicitações'!E:E,"<>ATENDIDO",'Solicitações'!I:I,"",'Solicitações'!S:S,"HORA DE VOO",'Solicitações'!C:C,"SIM")+SUMIFS('Solicitações'!$O:$O,'Solicitações'!$L:$L,$A6,'Solicitações'!$T:$T,"NÃO",'Solicitações'!E:E,"<>ATENDIDO",'Solicitações'!I:I,"",'Solicitações'!S:S,"PARCELA FIXA",'Solicitações'!C:C,"SIM")-(SUMIFS('Solicitações'!$O:$O,'Solicitações'!$L:$L,$A6,'Solicitações'!$T:$T,"NÃO",'Solicitações'!E:E,"<>ATENDIDO",'Solicitações'!I:I,"",'Solicitações'!S:S,"HORA DE VOO",'Solicitações'!C:C,"SIM",'Solicitações'!$R:$R,"RAP")+SUMIFS('Solicitações'!$O:$O,'Solicitações'!$L:$L,$A6,'Solicitações'!$T:$T,"NÃO",'Solicitações'!E:E,"<>ATENDIDO",'Solicitações'!I:I,"",'Solicitações'!S:S,"PARCELA FIXA",'Solicitações'!C:C,"SIM",'Solicitações'!$R:$R,"RAP")) -> 0 | J6: =G6-F6-H6-I6 -> 0
A7: T-27 | B7: =SUMIFS('Solicitações'!$O:$O,'Solicitações'!$L:$L,$A7,'Solicitações'!$R:$R,B$2,'Solicitações'!$T:$T,"NÃO")-SUMIFS('Solicitações'!$O:$O,'Solicitações'!$L:$L,$A7,'Solicitações'!$R:$R,B$2,'Solicitações'!$T:$T,"NÃO",'Solicitações'!$C:$C,"RAP)") -> 14322283 | C7: =SUMIFS('Solicitações'!$O:$O,'Solicitações'!$L:$L,$A7,'Solicitações'!$R:$R,C$2,'Solicitações'!$T:$T,"NÃO")-SUMIFS('Solicitações'!$O:$O,'Solicitações'!$L:$L,$A7,'Solicitações'!$R:$R,C$2,'Solicitações'!$T:$T,"NÃO",'Solicitações'!$C:$C,"RAP)") -> 0 | D7: =SUMIFS('Solicitações'!$O:$O,'Solicitações'!$L:$L,$A7,'Solicitações'!$R:$R,D$2,'Solicitações'!$T:$T,"NÃO")-SUMIFS('Solicitações'!$O:$O,'Solicitações'!$L:$L,$A7,'Solicitações'!$R:$R,D$2,'Solicitações'!$T:$T,"NÃO",'Solicitações'!$C:$C,"RAP)") -> 4613603.1 | E7: =SUMIFS('Solicitações'!$O:$O,'Solicitações'!$L:$L,$A7,'Solicitações'!$R:$R,E$2,'Solicitações'!$T:$T,"NÃO")-SUMIFS('Solicitações'!$O:$O,'Solicitações'!$L:$L,$A7,'Solicitações'!$R:$R,E$2,'Solicitações'!$T:$T,"NÃO",'Solicitações'!$C:$C,"RAP)") -> 5073979 | F7: =SUMIFS('Solicitações'!$O:$O,'Solicitações'!$L:$L,$A7,'Solicitações'!$T:$T,"NÃO",'Solicitações'!E:E,"ATENDIDO")-SUMIFS('Solicitações'!$O:$O,'Solicitações'!$L:$L,$A7,'Solicitações'!$T:$T,"NÃO",'Solicitações'!E:E,"ATENDIDO",'Solicitações'!$R:$R,"RAP") -> 9714849.5 | G7: =SUMIFS('Solicitações'!$O:$O,'Solicitações'!$L:$L,$A7,'Solicitações'!$T:$T,"NÃO",'Solicitações'!C:C,"SIM")-SUMIFS('Solicitações'!$O:$O,'Solicitações'!$L:$L,$A7,'Solicitações'!$R:$R,"RAP",'Solicitações'!$T:$T,"NÃO") -> 19396262 | H7: =SUMIFS('Solicitações'!$O:$O,'Solicitações'!$L:$L,$A7,'Solicitações'!$T:$T,"NÃO",'Solicitações'!E:E,"<>ATENDIDO",'Solicitações'!I:I,"<>",'Solicitações'!C:C,"SIM") -> 9681412.2 | I7: =SUMIFS('Solicitações'!$O:$O,'Solicitações'!$L:$L,$A7,'Solicitações'!$T:$T,"NÃO",'Solicitações'!E:E,"<>ATENDIDO",'Solicitações'!I:I,"",'Solicitações'!S:S,"HORA DE VOO",'Solicitações'!C:C,"SIM")+SUMIFS('Solicitações'!$O:$O,'Solicitações'!$L:$L,$A7,'Solicitações'!$T:$T,"NÃO",'Solicitações'!E:E,"<>ATENDIDO",'Solicitações'!I:I,"",'Solicitações'!S:S,"PARCELA FIXA",'Solicitações'!C:C,"SIM")-(SUMIFS('Solicitações'!$O:$O,'Solicitações'!$L:$L,$A7,'Solicitações'!$T:$T,"NÃO",'Solicitações'!E:E,"<>ATENDIDO",'Solicitações'!I:I,"",'Solicitações'!S:S,"HORA DE VOO",'Solicitações'!C:C,"SIM",'Solicitações'!$R:$R,"RAP")+SUMIFS('Solicitações'!$O:$O,'Solicitações'!$L:$L,$A7,'Solicitações'!$T:$T,"NÃO",'Solicitações'!E:E,"<>ATENDIDO",'Solicitações'!I:I,"",'Solicitações'!S:S,"PARCELA FIXA",'Solicitações'!C:C,"SIM",'Solicitações'!$R:$R,"RAP")) -> 0 | J7: =G7-F7-H7-I7 -> 1.8626451e-09
