Workbook

Sheet Giro Ideal
A1: INFORMATIVO | H1: ESTOQUE FAB | Z1: SUGESTÃO DE REESTOQUE (OPUS) | AO1: SUGESTÃO DE ESTOQUE (OPUS)
A2: PN | B2: Discrepancia | C2: CFF | D2: NOMECLATURA | E2: QPA | F2: PREÇO | G2: TIPO | H2: QTD TOTAL DE CADA PN (FAB) | K2: PAMALS | L2: BABE | M2: BABR | N2: BACG | O2: BAMN | P2: BANT | Q2: BACI | R2: BABV | S2: BAPV | T2: CLA | U2: BASM | V2: DACTAII | W2: EEAR | X2: EPCAR | Z2: PAMALS | AA2: BABE | AB2: BABR | AC2: BACG | AD2: BAMN | AE2: BANT | AF2: BACI | AG2: BABV | AH2: BAPV | AI2: CLA | AJ2: BASM | AK2: DACTAII | AL2: EEAR | AM2: EPCAR | AO2: QTD TOTAL DE CADA PN (SUGESTÃO OPUS) | AP2: PAMALS | AQ2: BABE | AR2: BABR | AS2: BACG | AT2: BAMN | AU2: BANT | AV2: BACI | AW2: BABV | AX2: BAPV | AY2: CLA | AZ2: BASM | BA2: DACTAII | BB2: EEAR | BC2: EPCAR
A3: 453-5000-710 | C3: 18560 | D3: EMERGENCY LOCATOR TRANSMITTER | E3: 1 | F3: 1065.31 | G3: REPARÁVEL | H3: 1 | K3: 1 | L3: 0 | M3: 0 | N3: 0 | O3: 0 | P3: 0 | Q3: 0 | R3: 0 | S3: 0 | T3: 0 | U3: 0 | V3: 0 | W3: 0 | X3: 0 | AD3: 1 | AG3: - | AH3: - | AI3: - | AJ3: - | AK3: - | AL3: - | AM3: - | AO3: 10 | AP3: 1 | AQ3: 2 | AR3: 1 | AS3: 1 | AT3: 2 | AU3: 1 | AV3: 2 | AW3: - | AX3: - | AY3: - | AZ3: - | BA3: - | BB3: - | BC3: -
A4: 2622083-18 | D4: GUINHOL DO FLAPE | E4: 1 | F4: 1035.2 | G4: REPARÁVEL | H4: 8 | K4: 6 | L4: 0 | M4: 0 | N4: 0 | O4: 1 | P4: 0 | Q4: 0 | R4: 0 | S4: 0 | T4: 0 | U4: 1 | V4: 0 | W4: 0 | X4: 0 | Z4: 1 | AA4: 1 | AB4: 1 | AC4: 1 | AD4: 2 | AE4: 1 | AF4: 1 | AG4: - | AH4: - | AI4: - | AJ4: - | AK4: - | AL4: - | AM4: - | AO4: 8 | AP4: 1 | AQ4: 1 | AR4: 1 | AS4: 1 | AT4: 2 | AU4: 1 | AV4: 1 | AW4: - | AX4: - | AY4: - | AZ4: - | BA4: - | BB4: - | BC4: -
A5: 2613440-1 | D5: HASTE DIANT. COMANDO DO PROFUNDOR | E5: 1 | F5: 858.78 | G5: REPARÁVEL | H5: 2 | K5: 1 | L5: 1 | M5: 0 | N5: 0 | O5: 0 | P5: 0 | Q5: 0 | R5: 0 | S5: 0 | T5: 0 | U5: 0 | V5: 0 | W5: 0 | X5: 0 | AD5: 1 | AF5: 1 | AG5: - | AH5: - | AI5: - | AJ5: - | AK5: - | AL5: - | AM5: - | AO5: 2 | AT5: 1 | AV5: 1 | AW5: - | AX5: - | AY5: - | AZ5: - | BA5: - | BB5: - | BC5: -
A6: 9514A-1 | D6: BOMBA DE CIRCULAÇÃO DO TKS | E6: 2 | F6: 12095.62 | G6: REPARÁVEL | H6: 0 | K6: 0 | L6: 0 | M6: 0 | N6: 0 | O6: 0 | P6: 0 | Q6: 0 | R6: 0 | S6: 0 | T6: 0 | U6: 0 | V6: 0 | W6: 0 | X6: 0 | AG6: - | AH6: - | AI6: - | AJ6: - | AK6: - | AL6: - | AM6: - | AO6: 0 | AW6: - | AX6: - | AY6: - | AZ6: - | BA6: - | BB6: - | BC6: -
A7: 2641014-1 | D7: MOLA CENTRAL TREM DE POUSO PRINCIPAL | E7: 1 | F7: 6539.14 | G7: REPARÁVEL | H7: 4 | K7: 4 | L7: 0 | M7: 0 | N7: 0 | O7: 0 | P7: 0 | Q7: 0 | R7: 0 | S7: 0 | T7: 0 | U7: 0 | V7: 0 | W7: 0 | X7: 0 | AA7: 1 | AD7: 1 | AE7: 1 | AF7: 1 | AG7: - | AH7: - | AI7: - | AJ7: - | AK7: - | AL7: - | AM7: - | AO7: 4 | AQ7: 1 | AT7: 1 | AU7: 1 | AV7: 1 | AW7: - | AX7: - | AY7: - | AZ7: - | BA7: - | BB7: - | BC7: -
A8: 2641012-1 | D8: TRUNNION LH | E8: 1 | F8: 1864.06 | G8: REPARÁVEL | H8: 13 | K8: 9 | L8: 0 | M8: 0 | N8: 0 | O8: 0 | P8: 1 | Q8: 0 | R8: 0 | S8: 0 | T8: 2 | U8: 0 | V8: 1 | W8: 0 | X8: 0 | Z8: 1 | AA8: 2 | AB8: 2 | AC8: 2 | AD8: 2 | AE8: 2 | AF8: 2 | AG8: - | AH8: - | AI8: - | AJ8: - | AK8: - | AL8: - | AM8: - | AO8: 13 | AP8: 1 | AQ8: 2 | AR8: 2 | AS8: 2 | AT8: 2 | AU8: 2 | AV8: 2 | AW8: - | AX8: - | AY8: - | AZ8: - | BA8: - | BB8: - | BC8: -
A9: 2641012-2 | D9: TRUNNION RH | E9: 1 | F9: 2084.42 | G9: REPARÁVEL | H9: 7 | K9: 6 | L9: 0 | M9: 0 | N9: 0 | O9: 0 | P9: 0 | Q9: 0 | R9: 0 | S9: 0 | T9: 0 | U9: 0 | V9: 0 | W9: 1 | X9: 0 | Z9: 1 | AA9: 1 | AB9: 1 | AC9: 1 | AD9: 1 | AE9: 1 | AF9: 1 | AG9: - | AH9: - | AI9: - | AJ9: - | AK9: - | AL9: - | AM9: - | AO9: 7 | AP9: 1 | AQ9: 1 | AR9: 1 | AS9: 1 | AT9: 1 | AU9: 1 | AV9: 1 | AW9: - | AX9: - | AY9: - | AZ9: - | BA9: - | BB9: - | BC9: -
A10: 2641013-1 | D10: MOLA TREM DE POUSO PRINCIPAL | E10: 1 | F10: 3133.82 | G10: REPARÁVEL | H10: 8 | K10: 8 | L10: 0 | M10: 0 | N10: 0 | O10: 0 | P10: 0 | Q10: 0 | R10: 0 | S10: 0 | T10: 0 | U10: 0 | V10: 0 | W10: 0 | X10: 0 | Z10: 1 | AA10: 1 | AB10: 1 | AC10: 1 | AD10: 2 | AE10: 1 | AF10: 1 | AG10: - | AH10: - | AI10: - | AJ10: - | AK10: - | AL10: - | AM10: - | AO10: 8 | AP10: 1 | AQ10: 1 | AR10: 1 | AS10: 1 | AT10: 2 | AU10: 1 | AV10: 1 | AW10: - | AX10: - | AY10: - | AZ10: - | BA10: - | BB10: - | BC10: -
A11: 2641008-1 | D11: PINO FIXAÇÃO TREM DE POUSO PRINCIPAL | E11: 1 | F11: 270.71 | G11: REPARÁVEL | H11: 16 | K11: 16 | L11: 0 | M11: 0 | N11: 0 | O11: 0 | P11: 0 | Q11: 0 | R11: 0 | S11: 0 | T11: 0 | U11: 0 | V11: 0 | W11: 0 | X11: 0 | Z11: 2 | AA11: 2 | AB11: 2 | AC11: 2 | AD11: 3 | AE11: 2 | AF11: 3 | AG11: - | AH11: - | AI11: - | AJ11: - | AK11: - | AL11: - | AM11: - | AO11: 16 | AP11: 2 | AQ11: 2 | AR11: 2 | AS11: 2 | AT11: 3 | AU11: 2 | AV11: 3 | AW11: - | AX11: - | AY11: - | AZ11: - | BA11: - | BB11: - | BC11: -
A12: 2641011-1 | C12: 7EK50 | D12: EIXO DO TREM DE POUSO PRINCIPAL | E12: 1 | F12: 1000.69 | G12: REPARÁVEL | H12: 6 | K12: 3 | L12: 0 | M12: 0 | N12: 0 | O12: 0 | P12: 1 | Q12: 0 | R12: 0 | S12: 2 | T12: 0 | U12: 0 | V12: 0 | W12: 0 | X12: 0 | AA12: 1 | AB12: 1 | AC12: 1 | AD12: 1 | AE12: 1 | AF12: 1 | AG12: - | AH12: - | AI12: - | AJ12: - | AK12: - | AL12: - | AM12: - | AO12: 7 | AP12: 1 | AQ12: 1 | AR12: 1 | AS12: 1 | AT12: 1 | AU12: 1 | AV12: 1 | AW12: - | AX12: - | AY12: - | AZ12: - | BA12: - | BB12: - | BC12: -
A13: 2641010-1 | D13: SUPORTE DO EIXO DE TREM DE POUSO PRINCIPAL | E13: 1 | F13: 825.08 | G13: REPARÁVEL | H13: 20 | K13: 18 | L13: 0 | M13: 0 | N13: 0 | O13: 0 | P13: 0 | Q13: 0 | R13: 0 | S13: 2 | T13: 0 | U13: 0 | V13: 0 | W13: 0 | X13: 0 | Z13: 2 | AA13: 3 | AB13: 3 | AC13: 2 | AD13: 4 | AE13: 3 | AF13: 3 | AG13: - | AH13: - | AI13: - | AJ13: - | AK13: - | AL13: - | AM13: - | AO13: 20 | AP13: 2 | AQ13: 3 | AR13: 3 | AS13: 2 | AT13: 4 | AU13: 3 | AV13: 3 | AW13: - | AX13: - | AY13: - | AZ13: - | BA13: - | BB13: - | BC13: -
A14: 2643062-1 | D14: MOLA DE TREM DE POUSO AUXILIAR | E14: 1 | F14: 2495.05 | G14: REPARÁVEL | H14: 8 | K14: 6 | L14: 0 | M14: 0 | N14: 0 | O14: 0 | P14: 0 | Q14: 0 | R14: 1 | S14: 0 | T14: 1 | U14: 0 | V14: 0 | W14: 0 | X14: 0 | Z14: 1 | AA14: 1 | AB14: 1 | AC14: 1 | AD14: 2 | AE14: 1 | AF14: 1 | AG14: - | AH14: - | AI14: - | AJ14: - | AK14: - | AL14: - | AM14: - | AO14: 8 | AP14: 1 | AQ14: 1 | AR14: 1 | AS14: 1 | AT14: 2 | AU14: 1 | AV14: 1 | AW14: - | AX14: - | AY14: - | AZ14: - | BA14: - | BB14: - | BC14: -
A15: 2643045-1 | B15: 2643045-202 | C15: 7EK50 | D15: TREM DE POUSO AUXILIAR | E15: 1 | F15: 39536.05 | G15: REPARÁVEL | H15: 0 | K15: 0 | L15: 0 | M15: 0 | N15: 0 | O15: 0 | P15: 0 | Q15: 0 | R15: 0 | S15: 0 | T15: 0 | U15: 0 | V15: 0 | W15: 0 | X15: 0 | AG15: - | AH15: - | AI15: - | AJ15: - | AK15: - | AL15: - | AM15: - | AO15: 1 | AT15: 1 | AW15: - | AX15: - | AY15: - | AZ15: - | BA15: - | BB15: - | BC15: -
A16: 2643030-1 | D16: SUPORTE DA MOLA DO TREM DE POUSO AUXILIAR | E16: 1 | F16: 958.28 | G16: REPARÁVEL | H16: 9 | K16: 3 | L16: 0 | M16: 1 | N16: 1 | O16: 0 | P16: 2 | Q16: 0 | R16: 1 | S16: 0 | T16: 0 | U16: 1 | V16: 0 | W16: 0 | X16: 0 | Z16: 1 | AA16: 1 | AB16: 1 | AC16: 1 | AD16: 2 | AE16: 1 | AF16: 2 | AG16: - | AH16: - | AI16: - | AJ16: - | AK16: - | AL16: - | AM16: - | AO16: 9 | AP16: 1 | AQ16: 1 | AR16: 1 | AS16: 1 | AT16: 2 | AU16: 1 | AV16: 2 | AW16: - | AX16: - | AY16: - | AZ16: - | BA16: - | BB16: - | BC16: -
A17: 2643031-1 | D17: GARFO DA MOLA DO TREM DE POUSO AUXILIAR | E17: 1 | F17: 831.34 | G17: REPARÁVEL | H17: 4 | K17: 4 | L17: 0 | M17: 0 | N17: 0 | O17: 0 | P17: 0 | Q17: 0 | R17: 0 | S17: 0 | T17: 0 | U17: 0 | V17: 0 | W17: 0 | X17: 0 | AA17: 1 | AD17: 1 | AE17: 1 | AF17: 1 | AG17: - | AH17: - | AI17: - | AJ17: - | AK17: - | AL17: - | AM17: - | AO17: 4 | AQ17: 1 | AT17: 1 | AU17: 1 | AV17: 1 | AW17: - | AX17: - | AY17: - | AZ17: - | BA17: - | BB17: - | BC17: -
A18: 162-11800 | C18: 33269 | D18: SEMI-CUBO EXTERNO PRINCIPAL | E18: 2 | F18: 526.97 | G18: REPARÁVEL | H18: 7 | K18: 3 | L18: 0 | M18: 0 | N18: 0 | O18: 0 | P18: 0 | Q18: 0 | R18: 0 | S18: 2 | T18: 1 | U18: 0 | V18: 1 | W18: 0 | X18: 0 | Z18: 1 | AA18: 1 | AB18: 1 | AC18: 1 | AD18: 1 | AE18: 1 | AF18: 1 | AG18: - | AH18: - | AI18: - | AJ18: - | AK18: - | AL18: - | AM18: - | AO18: 8 | AP18: 1 | AQ18: 1 | AR18: 1 | AS18: 1 | AT18: 2 | AU18: 1 | AV18: 1 | AW18: - | AX18: - | AY18: - | AZ18: - | BA18: - | BB18: - | BC18: -
A19: 161-12800 | D19: SEMI-CUBO INTERNO PRINCIPAL | E19: 2 | F19: 485.68 | G19: REPARÁVEL | H19: 10 | K19: 3 | L19: 0 | M19: 0 | N19: 0 | O19: 2 | P19: 0 | Q19: 0 | R19: 0 | S19: 2 | T19: 1 | U19: 1 | V19: 1 | W19: 0 | X19: 0 | Z19: 1 | AA19: 2 | AB19: 1 | AC19: 1 | AD19: 2 | AE19: 1 | AF19: 2 | AG19: - | AH19: - | AI19: - | AJ19: - | AK19: - | AL19: - | AM19: - | AO19: 10 | AP19: 1 | AQ19: 2 | AR19: 1 | AS19: 1 | AT19: 2 | AU19: 1 | AV19: 2 | AW19: - | AX19: - | AY19: - | AZ19: - | BA19: - | BB19: - | BC19: -
A20: 161-117-00 | C20: 7EK50 | D20: SEMI-CUBO EXTERNO NARIZ | E20: 1 | F20: 1569.44 | G20: REPARÁVEL | H20: 0 | K20: 0 | L20: 0 | M20: 0 | N20: 0 | O20: 0 | P20: 0 | Q20: 0 | R20: 0 | S20: 0 | T20: 0 | U20: 0 | V20: 0 | W20: 0 | X20: 0 | AG20: - | AH20: - | AI20: - | AJ20: - | AK20: - | AL20: - | AM20: - | AO20: 7 | AP20: 1 | AQ20: 1 | AR20: 1 | AS20: 1 | AT20: 1 | AU20: 1 | AV20: 1 | AW20: - | AX20: - | AY20: - | AZ20: - | BA20: - | BB20: - | BC20: -
A21: 162-107-00 | C21: 7EK50 | D21: SEMI-CUBO INTERNO NARIZ | E21: 1 | F21: 1569.44 | G21: REPARÁVEL | H21: 0 | K21: 0 | L21: 0 | M21: 0 | N21: 0 | O21: 0 | P21: 0 | Q21: 0 | R21: 0 | S21: 0 | T21: 0 | U21: 0 | V21: 0 | W21: 0 | X21: 0 | AG21: - | AH21: - | AI21: - | AJ21: - | AK21: - | AL21: - | AM21: - | AO21: 7 | AP21: 1 | AQ21: 1 | AR21: 1 | AS21: 1 | AT21: 1 | AU21: 1 | AV21: 1 | AW21: - | AX21: - | AY21: - | AZ21: - | BA21: - | BB21: - | BC21: -
A22: C482001-0402 | C22: 7EK50 | D22: VÁLVULA DE ALÍVIO DE VÁCUO | E22: 1 | F22: 1005.81 | G22: REPARÁVEL | H22: 3 | K22: 2 | L22: 0 | M22: 0 | N22: 0 | O22: 1 | P22: 0 | Q22: 0 | R22: 0 | S22: 0 | T22: 0 | U22: 0 | V22: 0 | W22: 0 | X22: 0 | AA22: 1 | AB22: 1 | AE22: 1 | AG22: - | AH22: - | AI22: - | AJ22: - | AK22: - | AL22: - | AM22: - | AO22: 7 | AP22: 1 | AQ22: 1 | AR22: 1 | AS22: 1 | AT22: 1 | AU22: 1 | AV22: 1 | AW22: - | AX22: - | AY22: - | AZ22: - | BA22: - | BB22: - | BC22: -
A23: A210507 | D23: GOVERNADOR DE SOBREVELOCIDADE | E23: 1 | F23: 3128.59 | G23: REPARÁVEL | H23: 9 | K23: 9 | L23: 0 | M23: 0 | N23: 0 | O23: 0 | P23: 0 | Q23: 0 | R23: 0 | S23: 0 | T23: 0 | U23: 0 | V23: 0 | W23: 0 | X23: 0 | Z23: 1 | AA23: 1 | AB23: 1 | AC23: 1 | AD23: 2 | AE23: 1 | AF23: 2 | AG23: - | AH23: - | AI23: - | AJ23: - | AK23: - | AL23: - | AM23: - | AO23: 9 | AP23: 1 | AQ23: 1 | AR23: 1 | AS23: 1 | AT23: 2 | AU23: 1 | AV23: 2 | AW23: - | AX23: - | AY23: - | AZ23: - | BA23: - | BB23: - | BC23: -
A24: 2651022-1 | C24: 7EK50 | D24: ANEL DO BERÇO DO MONTANTE | E24: 1 | F24: 6062.85 | G24: REPARÁVEL | H24: 3 | K24: 3 | L24: 0 | M24: 0 | N24: 0 | O24: 0 | P24: 0 | Q24: 0 | R24: 0 | S24: 0 | T24: 0 | U24: 0 | V24: 0 | W24: 0 | X24: 0 | AA24: 1 | AD24: 1 | AF24: 1 | AG24: - | AH24: - | AI24: - | AJ24: - | AK24: - | AL24: - | AM24: - | AO24: 6 | AQ24: 1 | AR24: 1 | AS24: 1 | AT24: 1 | AU24: 1 | AV24: 1 | AW24: - | AX24: - | AY24: - | AZ24: - | BA24: - | BB24: - | BC24: -
A25: 2651023-1 | C25: 7EK50 | D25: BERÇO DO MOTOR | E25: 1 | F25: 5469.37 | G25: REPARÁVEL | H25: 1 | K25: 1 | L25: 0 | M25: 0 | N25: 0 | O25: 0 | P25: 0 | Q25: 0 | R25: 0 | S25: 0 | T25: 0 | U25: 0 | V25: 0 | W25: 0 | X25: 0 | AD25: 1 | AG25: - | AH25: - | AI25: - | AJ25: - | AK25: - | AL25: - | AM25: - | AO25: 6 | AQ25: 1 | AR25: 1 | AS25: 1 | AT25: 1 | AU25: 1 | AV25: 1 | AW25: - | AX25: - | AY25: - | AZ25: - | BA25: - | BB25: - | BC25: -
A26: EMU-A-010-3 | D26: PROCESSADOR SISTEMA ADAS+ | E26: 1 | F26: 17500 | G26: REPARÁVEL | H26: 36 | K26: 35 | L26: 1 | M26: 0 | N26: 0 | O26: 0 | P26: 0 | Q26: 0 | R26: 0 | S26: 0 | T26: 0 | U26: 0 | V26: 0 | W26: 0 | X26: 0 | Z26: 4 | AA26: 4 | AB26: 4 | AC26: 4 | AD26: 10 | AE26: 4 | AF26: 6 | AG26: - | AH26: - | AI26: - | AJ26: - | AK26: - | AL26: - | AM26: - | AO26: 36 | AP26: 4 | AQ26: 4 | AR26: 4 | AS26: 4 | AT26: 10 | AU26: 4 | AV26: 6 | AW26: - | AX26: - | AY26: - | AZ26: - | BA26: - | BB26: - | BC26: -
A27: DAAS-A-010-1 | D27: PROCESSADOR SISTEMA ADAS-D | E27: 1 | F27: 16751.8 | G27: REPARÁVEL | H27: 1 | K27: 1 | L27: 0 | M27: 0 | N27: 0 | O27: 0 | P27: 0 | Q27: 0 | R27: 0 | S27: 0 | T27: 0 | U27: 0 | V27: 0 | W27: 0 | X27: 0 | AD27: 1 | AG27: - | AH27: - | AI27: - | AJ27: - | AK27: - | AL27: - | AM27: - | AO27: 1 | AT27: 1 | AW27: - | AX27: - | AY27: - | AZ27: - | BA27: - | BB27: - | BC27: -
A28: 200SGL119Q | D28: ARRANQUE GERADOR | E28: 1 | F28: 20999.78 | G28: REPARÁVEL | H28: 6 | K28: 5 | L28: 0 | M28: 0 | N28: 1 | O28: 0 | P28: 0 | Q28: 0 | R28: 0 | S28: 0 | T28: 0 | U28: 0 | V28: 0 | W28: 0 | X28: 0 | AA28: 1 | AB28: 1 | AC28: 1 | AD28: 1 | AE28: 1 | AF28: 1 | AG28: - | AH28: - | AI28: - | AJ28: - | AK28: - | AL28: - | AM28: - | AO28: 6 | AQ28: 1 | AR28: 1 | AS28: 1 | AT28: 1 | AU28: 1 | AV28: 1 | AW28: - | AX28: - | AY28: - | AZ28: - | BA28: - | BB28: - | BC28: -
A29: 065-0061-36 | D29: ACTUATOR TRIM (KS272A) | E29: 1 | F29: 8905.83 | G29: REPARÁVEL | H29: 5 | K29: 5 | L29: 0 | M29: 0 | N29: 0 | O29: 0 | P29: 0 | Q29: 0 | R29: 0 | S29: 0 | T29: 0 | U29: 0 | V29: 0 | W29: 0 | X29: 0 | Z29: 1 | AA29: 1 | AB29: 1 | AC29: 1 | AE29: 1 | AG29: - | AH29: - | AI29: - | AJ29: - | AK29: - | AL29: - | AM29: - | AO29: 5 | AP29: 1 | AQ29: 1 | AR29: 1 | AS29: 1 | AU29: 1 | AW29: - | AX29: - | AY29: - | AZ29: - | BA29: - | BB29: - | BC29: -
A30: 066-3059-01 | C30: 22373 | D30: ADF INDICATOR - DUAL (KI228) ADF INDICATOR - SINGLE (KI227) | E30: 1 | F30: 917.42 | G30: REPARÁVEL | H30: 1 | K30: 0 | L30: 0 | M30: 0 | N30: 0 | O30: 0 | P30: 0 | Q30: 0 | R30: 1 | S30: 0 | T30: 0 | U30: 0 | V30: 0 | W30: 0 | X30: 0 | AE30: 1 | AG30: - | AH30: - | AI30: - | AJ30: - | AK30: - | AL30: - | AM30: - | AO30: 7 | AP30: 1 | AQ30: 1 | AR30: 1 | AS30: 1 | AT30: 1 | AU30: 1 | AV30: 1 | AW30: - | AX30: - | AY30: - | AZ30: - | BA30: - | BB30: - | BC30: -
A31: C661065-0237 | D31: AIRSPEED INDICATOR | E31: 1 | F31: 1034.96 | G31: REPARÁVEL | H31: 13 | K31: 13 | L31: 0 | M31: 0 | N31: 0 | O31: 0 | P31: 0 | Q31: 0 | R31: 0 | S31: 0 | T31: 0 | U31: 0 | V31: 0 | W31: 0 | X31: 0 | Z31: 2 | AA31: 2 | AB31: 2 | AC31: 2 | AD31: 2 | AE31: 2 | AF31: 1 | AG31: - | AH31: - | AI31: - | AJ31: - | AK31: - | AL31: - | AM31: - | AO31: 13 | AP31: 2 | AQ31: 2 | AR31: 2 | AS31: 2 | AT31: 2 | AU31: 2 | AV31: 1 | AW31: - | AX31: - | AY31: - | AZ31: - | BA31: - | BB31: - | BC31: -
A32: 011-00134-00 | D32: ANTENNA ACCESSORY | E32: 1 | F32: 532.33 | G32: REPARÁVEL | H32: 38 | K32: 38 | L32: 0 | M32: 0 | N32: 0 | O32: 0 | P32: 0 | Q32: 0 | R32: 0 | S32: 0 | T32: 0 | U32: 0 | V32: 0 | W32: 0 | X32: 0 | Z32: - | AA32: 4 | AB32: - | AC32: - | AD32: 23 | AE32: - | AF32: 11 | AG32: - | AH32: - | AI32: - | AJ32: - | AK32: - | AL32: - | AM32: - | AO32: 38 | AP32: - | AQ32: 4 | AR32: - | AS32: - | AT32: 23 | AU32: - | AV32: 11 | AW32: - | AX32: - | AY32: - | AZ32: - | BA32: - | BB32: - | BC32: -
A33: 071-1378-00 | D33: ANTENNA RADAR | E33: 1 | F33: 13787.11 | G33: REPARÁVEL | H33: 8 | K33: 8 | L33: 0 | M33: 0 | N33: 0 | O33: 0 | P33: 0 | Q33: 0 | R33: 0 | S33: 0 | T33: 0 | U33: 0 | V33: 0 | W33: 0 | X33: 0 | Z33: - | AA33: 2 | AB33: - | AC33: - | AD33: 3 | AE33: - | AF33: 3 | AG33: - | AH33: - | AI33: - | AJ33: - | AK33: - | AL33: - | AM33: - | AO33: 8 | AP33: - | AQ33: 2 | AR33: - | AS33: - | AT33: 3 | AU33: - | AV33: 3 | AW33: - | AX33: - | AY33: - | AZ33: - | BA33: - | BB33: - | BC33: -
A34: CI268-60 | D34: ANTENNA VHF COMM | E34: 1 | F34: 1399.52 | G34: REPARÁVEL | H34: 9 | K34: 7 | L34: 0 | M34: 1 | N34: 0 | O34: 0 | P34: 0 | Q34: 0 | R34: 0 | S34: 1 | T34: 0 | U34: 0 | V34: 0 | W34: 0 | X34: 0 | Z34: - | AA34: 2 | AB34: - | AC34: - | AD34: 4 | AE34: - | AF34: 3 | AG34: - | AH34: - | AI34: - | AJ34: - | AK34: - | AL34: - | AM34: - | AO34: 9 | AP34: - | AQ34: 2 | AR34: - | AS34: - | AT34: 4 | AU34: - | AV34: 3 | AW34: - | AX34: - | AY34: - | AZ34: - | BA34: - | BB34: - | BC34: -
A35: 066-1055-00 | D35: AUDIO CONTROL PANEL (KMA-24) | E35: 1 | F35: 1742.25 | G35: REPARÁVEL | H35: 13 | K35: 12 | L35: 0 | M35: 0 | N35: 0 | O35: 0 | P35: 0 | Q35: 0 | R35: 0 | S35: 0 | T35: 1 | U35: 0 | V35: 0 | W35: 0 | X35: 0 | Z35: 2 | AA35: 2 | AB35: 2 | AC35: 2 | AD35: 2 | AE35: 2 | AF35: 1 | AG35: - | AH35: - | AI35: - | AJ35: - | AK35: - | AL35: - | AM35: - | AO35: 13 | AP35: 2 | AQ35: 2 | AR35: 2 | AS35: 2 | AT35: 2 | AU35: 2 | AV35: 1 | AW35: - | AX35: - | AY35: - | AZ35: - | BA35: - | BB35: - | BC35: -
A36: 065-0042-03 | D36: AUTOPILOT COMPUTER | E36: 1 | F36: 10292.41 | G36: REPARÁVEL | H36: 10 | K36: 8 | L36: 0 | M36: 0 | N36: 0 | O36: 0 | P36: 0 | Q36: 0 | R36: 0 | S36: 0 | T36: 0 | U36: 0 | V36: 0 | W36: 2 | X36: 0 | Z36: - | AA36: 3 | AB36: - | AC36: - | AD36: 4 | AE36: - | AF36: 3 | AG36: - | AH36: - | AI36: - | AJ36: - | AK36: - | AL36: - | AM36: - | AO36: 10 | AP36: - | AQ36: 3 | AR36: - | AS36: - | AT36: 4 | AU36: - | AV36: 3 | AW36: - | AX36: - | AY36: - | AZ36: - | BA36: - | BB36: - | BC36: -
A37: 24535-026 | D37: BATTERY BATTERY NICKEL CADMIUM BATTERY NONRECHARGEABLE BATTERY STORAGE BATTERY-MARATHON TSP410 NICAD | E37: 1 | F37: 3379.72 | G37: REPARÁVEL | H37: 6 | K37: 6 | L37: 0 | M37: 0 | N37: 0 | O37: 0 | P37: 0 | Q37: 0 | R37: 0 | S37: 0 | T37: 0 | U37: 0 | V37: 0 | W37: 0 | X37: 0 | Z37: - | AA37: 1 | AB37: - | AC37: - | AD37: 3 | AE37: - | AF37: 2 | AG37: - | AH37: - | AI37: - | AJ37: - | AK37: - | AL37: - | AM37: - | AO37: 6 | AP37: - | AQ37: 1 | AR37: - | AS37: - | AT37: 3 | AU37: - | AV37: 2 | AW37: - | AX37: - | AY37: - | AZ37: - | BA37: - | BB37: - | BC37: -
A38: 2682001-1 | C38: 7EK50 | D38: BRAKE CYL MAST | E38: 2 | F38: 633.28 | G38: REPARÁVEL | H38: 0 | K38: 0 | L38: 0 | M38: 0 | N38: 0 | O38: 0 | P38: 0 | Q38: 0 | R38: 0 | S38: 0 | T38: 0 | U38: 0 | V38: 0 | W38: 0 | X38: 0 | AG38: - | AH38: - | AI38: - | AJ38: - | AK38: - | AL38: - | AM38: - | AO38: 8 | AP38: 1 | AQ38: 1 | AR38: 1 | AS38: 1 | AT38: 2 | AU38: 1 | AV38: 1 | AW38: - | AX38: - | AY38: - | AZ38: - | BA38: - | BB38: - | BC38: -
A39: 164-22201 | C39: 7EK50 | D39: BRAKE DISC | E39: 2 | F39: 203.83 | G39: REPARÁVEL | H39: 0 | K39: 0 | L39: 0 | M39: 0 | N39: 0 | O39: 0 | P39: 0 | Q39: 0 | R39: 0 | S39: 0 | T39: 0 | U39: 0 | V39: 0 | W39: 0 | X39: 0 | AG39: - | AH39: - | AI39: - | AJ39: - | AK39: - | AL39: - | AM39: - | AO39: 7 | AP39: 1 | AQ39: 1 | AR39: 1 | AS39: 1 | AT39: 1 | AU39: 1 | AV39: 1 | AW39: - | AX39: - | AY39: - | AZ39: - | BA39: - | BB39: - | BC39: -
A40: 064-1019-05 | C40: 22373 | D40: VHF TRANSCEIVE KY196 | E40: 1 | F40: 1412.98 | G40: REPARÁVEL | H40: 1 | K40: 0 | L40: 0 | M40: 0 | N40: 0 | O40: 0 | P40: 0 | Q40: 0 | R40: 0 | S40: 0 | T40: 1 | U40: 0 | V40: 0 | W40: 0 | X40: 0 | AE40: 1 | AG40: - | AH40: - | AI40: - | AJ40: - | AK40: - | AL40: - | AM40: - | AO40: 5 | AP40: 1 | AQ40: 1 | AR40: 1 | AS40: 1 | AU40: 1 | AW40: - | AX40: - | AY40: - | AZ40: - | BA40: - | BB40: - | BC40: -
...

Sheet Divulgação
B1: HOJE: | D1: =TODAY() -> 46310
B2: DATA DE DOWNLOAD SILOMS | D2: 46296
B3: INFORMAÇÕES DO SILOMS | L3: INFORMAÇÕES DA EMPRESA | T3: COMREC/ACERTO VIRTUAL
A4: Qt | B4: OS | C4: PN | D4: CFF | E4: NOMENCLATURA | F4: SN | G4: DATA INICIO | H4: UNIDADE SOLIC. | I4: ST_OS | J4: TAT SILOMS | K4: OBSERVAÇÃO COORDENADORIA / FISCAL | L4: TAT | M4: OBSERVAÇÃO VEE ONE | N4: Data de devolução empresa | O4: ONDE SE ENCONTRA | P4: RECIBO CASO TENHA | Q4: CONDIÇÃO | R4: SN TROCADO (EXCHANGE) | T4: TERMO DE RECEBIMENTO | U4: TERMO DE RECEBIMENTO | V4: DATA DO TERMO | W4: RECEBIMENTO DO TERMO | X4: SOLICITAR ACERTO à Vee One | Y4: SOLICITAR CONCLUSÃO OS | Z4: OS CONCLUÍDA | AA4: SOLICITAR RECEBIMENTO | AB4: ITEM RECEBIDO | AC4: SOLICITAR ARMAZENAGEM | AD4: ITEM ARMAZENADO | AE4: TRANSFERIR E SOLICITAR ATENDIMENTO TSAU | AF4: SOLICITAR TRANSFERÊNCIA TSAE | AG4: ENVIO | AH4: SOL REC OPERADOR | AI4: REC OPERADOR
A5: 1 | B5: 3040249831 | C5: {=IFERROR(_xlfn.XLOOKUP($B5,'Histórico'!$B:$B,'Histórico'!$I:$I),"")} -> 066-01141-5101 | D5: {=IFERROR(_xlfn.XLOOKUP($B5,'Histórico'!$B:$B,'Histórico'!$J:$J),"")} -> 22373 | E5: {=IFERROR(_xlfn.XLOOKUP($B5,'Histórico'!$B:$B,'Histórico'!$K:$K),"")} -> RECEIVER-TRANSMITTER,RADIO (KT71) | F5: {=IFERROR(_xlfn.XLOOKUP($B5,'Histórico'!$B:$B,'Histórico'!$L:$L),"")} -> 3859 | G5: {=IFERROR(_xlfn.XLOOKUP($B5,'Histórico'!$B:$B,'Histórico'!$F:$F),"")} -> 10/02/2025 | H5: {=IFERROR(_xlfn.XLOOKUP($B5,'Histórico'!$B:$B,'Histórico'!$AA:$AA),"")} -> PAMALS | I5: {=IFERROR(_xlfn.XLOOKUP($B5,Atual!$B:$B,Atual!$E:$E),"OS concluída")} -> REC | J5: =IF(G5="","",IF(I5="OS concluída","",$D$1-G5)) -> 612 | L5: =IF(N5="","",IFERROR(N5-G5,"NÃO APLICÁVEL")) -> NÃO APLICÁVEL | N5: {=IFERROR(_xlfn.XLOOKUP($B5,EMPRESA_1!A:A,EMPRESA_1!J:J),"")} -> EM REPARO | O5: {=IFERROR(_xlfn.XLOOKUP(B5,EMPRESA_1!A:A,EMPRESA_1!K:K),"")} -> LEAP | P5: {=IFERROR(_xlfn.XLOOKUP(B5,EMPRESA_1!A:A,EMPRESA_1!L:L),"")} | Q5: {=IFERROR(_xlfn.XLOOKUP(B5,EMPRESA_1!A:A,EMPRESA_1!J:J),"")} -> EM REPARO | R5: {=IFERROR(_xlfn.XLOOKUP(B5,EMPRESA_1!A:A,EMPRESA_1!M:M),"")} | T5: {=IFERROR(_xlfn.XLOOKUP($F5,'Acerto virtual'!$E:$E,'Acerto virtual'!F:F),"")} | U5: {=IFERROR(_xlfn.XLOOKUP($F5,'Acerto virtual'!$E:$E,'Acerto virtual'!G:G),"")} | V5: {=IFERROR(_xlfn.XLOOKUP($F5,'Acerto virtual'!$E:$E,'Acerto virtual'!H:H),"")} | W5: {=IFERROR(_xlfn.XLOOKUP($F5,'Acerto virtual'!$E:$E,'Acerto virtual'!I:I),"")} | X5: {=IFERROR(_xlfn.XLOOKUP($F5,'Acerto virtual'!$E:$E,'Acerto virtual'!J:J),"")} | Y5: {=IFERROR(_xlfn.XLOOKUP($F5,'Acerto virtual'!$E:$E,'Acerto virtual'!K:K),"")} | Z5: {=IFERROR(_xlfn.XLOOKUP($F5,'Acerto virtual'!$E:$E,'Acerto virtual'!L:L),"")} | AA5: {=IFERROR(_xlfn.XLOOKUP($F5,'Acerto virtual'!$E:$E,'Acerto virtual'!M:M),"")} | AB5: {=IFERROR(_xlfn.XLOOKUP($F5,'Acerto virtual'!$E:$E,'Acerto virtual'!N:N),"")} | AC5: {=IFERROR(_xlfn.XLOOKUP($F5,'Acerto virtual'!$E:$E,'Acerto virtual'!O:O),"")} | AD5: {=IFERROR(_xlfn.XLOOKUP($F5,'Acerto virtual'!$E:$E,'Acerto virtual'!P:P),"")} | AE5: {=IFERROR(_xlfn.XLOOKUP($F5,'Acerto virtual'!$E:$E,'Acerto virtual'!Q:Q),"")} | AF5: {=IFERROR(_xlfn.XLOOKUP($F5,'Acerto virtual'!$E:$E,'Acerto virtual'!R:R),"")} | AG5: {=IFERROR(_xlfn.XLOOKUP($F5,'Acerto virtual'!$E:$E,'Acerto virtual'!S:S),"")} | AH5: {=IFERROR(_xlfn.XLOOKUP($F5,'Acerto virtual'!$E:$E,'Acerto virtual'!T:T),"")} | AI5: {=IFERROR(_xlfn.XLOOKUP($F5,'Acerto virtual'!$E:$E,'Acerto virtual'!U:U),"")}
A6: 2 | B6: 3040250248 | C6: {=IFERROR(_xlfn.XLOOKUP($B6,'Histórico'!$B:$B,'Histórico'!$I:$I),"")} -> 452-0133 | D6: {=IFERROR(_xlfn.XLOOKUP($B6,'Histórico'!$B:$B,'Histórico'!$J:$J),"")} -> 78286 | E6: {=IFERROR(_xlfn.XLOOKUP($B6,'Histórico'!$B:$B,'Histórico'!$K:$K),"")} -> BATTERY,NONRECHARGEABLE | F6: {=IFERROR(_xlfn.XLOOKUP($B6,'Histórico'!$B:$B,'Histórico'!$L:$L),"")} -> 382750-016 | G6: {=IFERROR(_xlfn.XLOOKUP($B6,'Histórico'!$B:$B,'Histórico'!$F:$F),"")} -> 26/02/2025 | H6: {=IFERROR(_xlfn.XLOOKUP($B6,'Histórico'!$B:$B,'Histórico'!$AA:$AA),"")} -> BABR | I6: {=IFERROR(_xlfn.XLOOKUP($B6,Atual!$B:$B,Atual!$E:$E),"OS concluída")} -> REC | J6: =IF(G6="","",IF(I6="OS concluída","",$D$1-G6)) -> 596 | L6: =IF(N6="","",IFERROR(N6-G6,"NÃO APLICÁVEL")) -> NÃO APLICÁVEL | N6: {=IFERROR(_xlfn.XLOOKUP($B6,EMPRESA_1!A:A,EMPRESA_1!J:J),"")} -> CONDENADO | O6: {=IFERROR(_xlfn.XLOOKUP(B6,EMPRESA_1!A:A,EMPRESA_1!K:K),"")} -> VEE ONE | P6: {=IFERROR(_xlfn.XLOOKUP(B6,EMPRESA_1!A:A,EMPRESA_1!L:L),"")} | Q6: {=IFERROR(_xlfn.XLOOKUP(B6,EMPRESA_1!A:A,EMPRESA_1!J:J),"")} -> CONDENADO | R6: {=IFERROR(_xlfn.XLOOKUP(B6,EMPRESA_1!A:A,EMPRESA_1!M:M),"")} | T6: {=IFERROR(_xlfn.XLOOKUP($F6,'Acerto virtual'!$E:$E,'Acerto virtual'!F:F),"")} | U6: {=IFERROR(_xlfn.XLOOKUP($F6,'Acerto virtual'!$E:$E,'Acerto virtual'!G:G),"")} | V6: {=IFERROR(_xlfn.XLOOKUP($F6,'Acerto virtual'!$E:$E,'Acerto virtual'!H:H),"")} | W6: {=IFERROR(_xlfn.XLOOKUP($F6,'Acerto virtual'!$E:$E,'Acerto virtual'!I:I),"")} | X6: {=IFERROR(_xlfn.XLOOKUP($F6,'Acerto virtual'!$E:$E,'Acerto virtual'!J:J),"")} | Y6: {=IFERROR(_xlfn.XLOOKUP($F6,'Acerto virtual'!$E:$E,'Acerto virtual'!K:K),"")} | Z6: {=IFERROR(_xlfn.XLOOKUP($F6,'Acerto virtual'!$E:$E,'Acerto virtual'!L:L),"")} | AA6: {=IFERROR(_xlfn.XLOOKUP($F6,'Acerto virtual'!$E:$E,'Acerto virtual'!M:M),"")} | AB6: {=IFERROR(_xlfn.XLOOKUP($F6,'Acerto virtual'!$E:$E,'Acerto virtual'!N:N),"")} | AC6: {=IFERROR(_xlfn.XLOOKUP($F6,'Acerto virtual'!$E:$E,'Acerto virtual'!O:O),"")} | AD6: {=IFERROR(_xlfn.XLOOKUP($F6,'Acerto virtual'!$E:$E,'Acerto virtual'!P:P),"")} | AE6: {=IFERROR(_xlfn.XLOOKUP($F6,'Acerto virtual'!$E:$E,'Acerto virtual'!Q:Q),"")} | AF6: {=IFERROR(_xlfn.XLOOKUP($F6,'Acerto virtual'!$E:$E,'Acerto virtual'!R:R),"")} | AG6: {=IFERROR(_xlfn.XLOOKUP($F6,'Acerto virtual'!$E:$E,'Acerto virtual'!S:S),"")} | AH6: {=IFERROR(_xlfn.XLOOKUP($F6,'Acerto virtual'!$E:$E,'Acerto virtual'!T:T),"")} | AI6: {=IFERROR(_xlfn.XLOOKUP($F6,'Acerto virtual'!$E:$E,'Acerto virtual'!U:U),"")}
A7: 3 | B7: 3040250249 | C7: {=IFERROR(_xlfn.XLOOKUP($B7,'Histórico'!$B:$B,'Histórico'!$I:$I),"")} -> 452-0133 | D7: {=IFERROR(_xlfn.XLOOKUP($B7,'Histórico'!$B:$B,'Histórico'!$J:$J),"")} -> 78286 | E7: {=IFERROR(_xlfn.XLOOKUP($B7,'Histórico'!$B:$B,'Histórico'!$K:$K),"")} -> BATTERY,NONRECHARGEABLE | F7: {=IFERROR(_xlfn.XLOOKUP($B7,'Histórico'!$B:$B,'Histórico'!$L:$L),"")} -> 382750-023 | G7: {=IFERROR(_xlfn.XLOOKUP($B7,'Histórico'!$B:$B,'Histórico'!$F:$F),"")} -> 26/02/2025 | H7: {=IFERROR(_xlfn.XLOOKUP($B7,'Histórico'!$B:$B,'Histórico'!$AA:$AA),"")} -> BAMN | I7: {=IFERROR(_xlfn.XLOOKUP($B7,Atual!$B:$B,Atual!$E:$E),"OS concluída")} -> REC | J7: =IF(G7="","",IF(I7="OS concluída","",$D$1-G7)) -> 596 | L7: =IF(N7="","",IFERROR(N7-G7,"NÃO APLICÁVEL")) -> NÃO APLICÁVEL | N7: {=IFERROR(_xlfn.XLOOKUP($B7,EMPRESA_1!A:A,EMPRESA_1!J:J),"")} -> CONDENADO | O7: {=IFERROR(_xlfn.XLOOKUP(B7,EMPRESA_1!A:A,EMPRESA_1!K:K),"")} -> VEE ONE | P7: {=IFERROR(_xlfn.XLOOKUP(B7,EMPRESA_1!A:A,EMPRESA_1!L:L),"")} | Q7: {=IFERROR(_xlfn.XLOOKUP(B7,EMPRESA_1!A:A,EMPRESA_1!J:J),"")} -> CONDENADO | R7: {=IFERROR(_xlfn.XLOOKUP(B7,EMPRESA_1!A:A,EMPRESA_1!M:M),"")} | T7: {=IFERROR(_xlfn.XLOOKUP($F7,'Acerto virtual'!$E:$E,'Acerto virtual'!F:F),"")} | U7: {=IFERROR(_xlfn.XLOOKUP($F7,'Acerto virtual'!$E:$E,'Acerto virtual'!G:G),"")} | V7: {=IFERROR(_xlfn.XLOOKUP($F7,'Acerto virtual'!$E:$E,'Acerto virtual'!H:H),"")} | W7: {=IFERROR(_xlfn.XLOOKUP($F7,'Acerto virtual'!$E:$E,'Acerto virtual'!I:I),"")} | X7: {=IFERROR(_xlfn.XLOOKUP($F7,'Acerto virtual'!$E:$E,'Acerto virtual'!J:J),"")} | Y7: {=IFERROR(_xlfn.XLOOKUP($F7,'Acerto virtual'!$E:$E,'Acerto virtual'!K:K),"")} | Z7: {=IFERROR(_xlfn.XLOOKUP($F7,'Acerto virtual'!$E:$E,'Acerto virtual'!L:L),"")} | AA7: {=IFERROR(_xlfn.XLOOKUP($F7,'Acerto virtual'!$E:$E,'Acerto virtual'!M:M),"")} | AB7: {=IFERROR(_xlfn.XLOOKUP($F7,'Acerto virtual'!$E:$E,'Acerto virtual'!N:N),"")} | AC7: {=IFERROR(_xlfn.XLOOKUP($F7,'Acerto virtual'!$E:$E,'Acerto virtual'!O:O),"")} | AD7: {=IFERROR(_xlfn.XLOOKUP($F7,'Acerto virtual'!$E:$E,'Acerto virtual'!P:P),"")} | AE7: {=IFERROR(_xlfn.XLOOKUP($F7,'Acerto virtual'!$E:$E,'Acerto virtual'!Q:Q),"")} | AF7: {=IFERROR(_xlfn.XLOOKUP($F7,'Acerto virtual'!$E:$E,'Acerto virtual'!R:R),"")} | AG7: {=IFERROR(_xlfn.XLOOKUP($F7,'Acerto virtual'!$E:$E,'Acerto virtual'!S:S),"")} | AH7: {=IFERROR(_xlfn.XLOOKUP($F7,'Acerto virtual'!$E:$E,'Acerto virtual'!T:T),"")} | AI7: {=IFERROR(_xlfn.XLOOKUP($F7,'Acerto virtual'!$E:$E,'Acerto virtual'!U:U),"")}
A8: 4 | B8: 3040250234 | C8: {=IFERROR(_xlfn.XLOOKUP($B8,'Histórico'!$B:$B,'Histórico'!$I:$I),"")} -> 3034792 | D8: {=IFERROR(_xlfn.XLOOKUP($B8,'Histórico'!$B:$B,'Histórico'!$J:$J),"")} -> 00198 | E8: {=IFERROR(_xlfn.XLOOKUP($B8,'Histórico'!$B:$B,'Histórico'!$K:$K),"")} -> BOMBA DE COMBUSTÍVEL | F8: {=IFERROR(_xlfn.XLOOKUP($B8,'Histórico'!$B:$B,'Histórico'!$L:$L),"")} -> 003342 | G8: {=IFERROR(_xlfn.XLOOKUP($B8,'Histórico'!$B:$B,'Histórico'!$F:$F),"")} -> 26/02/2025 | H8: {=IFERROR(_xlfn.XLOOKUP($B8,'Histórico'!$B:$B,'Histórico'!$AA:$AA),"")} -> PAMALS | I8: {=IFERROR(_xlfn.XLOOKUP($B8,Atual!$B:$B,Atual!$E:$E),"OS concluída")} -> REC | J8: =IF(G8="","",IF(I8="OS concluída","",$D$1-G8)) -> 596 | L8: =IF(N8="","",IFERROR(N8-G8,"NÃO APLICÁVEL")) -> 279 | N8: {=IFERROR(_xlfn.XLOOKUP($B8,EMPRESA_1!A:A,EMPRESA_1!J:J),"")} -> 45993 | O8: {=IFERROR(_xlfn.XLOOKUP(B8,EMPRESA_1!A:A,EMPRESA_1!K:K),"")} -> BANT | P8: {=IFERROR(_xlfn.XLOOKUP(B8,EMPRESA_1!A:A,EMPRESA_1!L:L),"")} -> 282/FAB/25 | Q8: {=IFERROR(_xlfn.XLOOKUP(B8,EMPRESA_1!A:A,EMPRESA_1!J:J),"")} -> 45993 | R8: {=IFERROR(_xlfn.XLOOKUP(B8,EMPRESA_1!A:A,EMPRESA_1!M:M),"")} | T8: {=IFERROR(_xlfn.XLOOKUP($F8,'Acerto virtual'!$E:$E,'Acerto virtual'!F:F),"")} | U8: {=IFERROR(_xlfn.XLOOKUP($F8,'Acerto virtual'!$E:$E,'Acerto virtual'!G:G),"")} | V8: {=IFERROR(_xlfn.XLOOKUP($F8,'Acerto virtual'!$E:$E,'Acerto virtual'!H:H),"")} | W8: {=IFERROR(_xlfn.XLOOKUP($F8,'Acerto virtual'!$E:$E,'Acerto virtual'!I:I),"")} | X8: {=IFERROR(_xlfn.XLOOKUP($F8,'Acerto virtual'!$E:$E,'Acerto virtual'!J:J),"")} | Y8: {=IFERROR(_xlfn.XLOOKUP($F8,'Acerto virtual'!$E:$E,'Acerto virtual'!K:K),"")} | Z8: {=IFERROR(_xlfn.XLOOKUP($F8,'Acerto virtual'!$E:$E,'Acerto virtual'!L:L),"")} | AA8: {=IFERROR(_xlfn.XLOOKUP($F8,'Acerto virtual'!$E:$E,'Acerto virtual'!M:M),"")} | AB8: {=IFERROR(_xlfn.XLOOKUP($F8,'Acerto virtual'!$E:$E,'Acerto virtual'!N:N),"")} | AC8: {=IFERROR(_xlfn.XLOOKUP($F8,'Acerto virtual'!$E:$E,'Acerto virtual'!O:O),"")} | AD8: {=IFERROR(_xlfn.XLOOKUP($F8,'Acerto virtual'!$E:$E,'Acerto virtual'!P:P),"")} | AE8: {=IFERROR(_xlfn.XLOOKUP($F8,'Acerto virtual'!$E:$E,'Acerto virtual'!Q:Q),"")} | AF8: {=IFERROR(_xlfn.XLOOKUP($F8,'Acerto virtual'!$E:$E,'Acerto virtual'!R:R),"")} | AG8: {=IFERROR(_xlfn.XLOOKUP($F8,'Acerto virtual'!$E:$E,'Acerto virtual'!S:S),"")} | AH8: {=IFERROR(_xlfn.XLOOKUP($F8,'Acerto virtual'!$E:$E,'Acerto virtual'!T:T),"")} | AI8: {=IFERROR(_xlfn.XLOOKUP($F8,'Acerto virtual'!$E:$E,'Acerto virtual'!U:U),"")}
A9: 5 | B9: 3040250816 | C9: {=IFERROR(_xlfn.XLOOKUP($B9,'Histórico'!$B:$B,'Histórico'!$I:$I),"")} -> 453-5060 | D9: {=IFERROR(_xlfn.XLOOKUP($B9,'Histórico'!$B:$B,'Histórico'!$J:$J),"")} -> 60253 | E9: {=IFERROR(_xlfn.XLOOKUP($B9,'Histórico'!$B:$B,'Histórico'!$K:$K),"")} -> BEACON,DISTRESS | F9: {=IFERROR(_xlfn.XLOOKUP($B9,'Histórico'!$B:$B,'Histórico'!$L:$L),"")} -> 09450 | G9: {=IFERROR(_xlfn.XLOOKUP($B9,'Histórico'!$B:$B,'Histórico'!$F:$F),"")} -> 20/03/2025 | H9: {=IFERROR(_xlfn.XLOOKUP($B9,'Histórico'!$B:$B,'Histórico'!$AA:$AA),"")} -> BAMN | I9: {=IFERROR(_xlfn.XLOOKUP($B9,Atual!$B:$B,Atual!$E:$E),"OS concluída")} -> REC | J9: =IF(G9="","",IF(I9="OS concluída","",$D$1-G9)) -> 574 | L9: =IF(N9="","",IFERROR(N9-G9,"NÃO APLICÁVEL")) -> 153 | N9: {=IFERROR(_xlfn.XLOOKUP($B9,EMPRESA_1!A:A,EMPRESA_1!J:J),"")} -> 45889 | O9: {=IFERROR(_xlfn.XLOOKUP(B9,EMPRESA_1!A:A,EMPRESA_1!K:K),"")} -> PAMA-LS | P9: {=IFERROR(_xlfn.XLOOKUP(B9,EMPRESA_1!A:A,EMPRESA_1!L:L),"")} -> 159/C98/2025 | Q9: {=IFERROR(_xlfn.XLOOKUP(B9,EMPRESA_1!A:A,EMPRESA_1!J:J),"")} -> 45889 | R9: {=IFERROR(_xlfn.XLOOKUP(B9,EMPRESA_1!A:A,EMPRESA_1!M:M),"")} | T9: {=IFERROR(_xlfn.XLOOKUP($F9,'Acerto virtual'!$E:$E,'Acerto virtual'!F:F),"")} | U9: {=IFERROR(_xlfn.XLOOKUP($F9,'Acerto virtual'!$E:$E,'Acerto virtual'!G:G),"")} | V9: {=IFERROR(_xlfn.XLOOKUP($F9,'Acerto virtual'!$E:$E,'Acerto virtual'!H:H),"")} | W9: {=IFERROR(_xlfn.XLOOKUP($F9,'Acerto virtual'!$E:$E,'Acerto virtual'!I:I),"")} | X9: {=IFERROR(_xlfn.XLOOKUP($F9,'Acerto virtual'!$E:$E,'Acerto virtual'!J:J),"")} | Y9: {=IFERROR(_xlfn.XLOOKUP($F9,'Acerto virtual'!$E:$E,'Acerto virtual'!K:K),"")} | Z9: {=IFERROR(_xlfn.XLOOKUP($F9,'Acerto virtual'!$E:$E,'Acerto virtual'!L:L),"")} | AA9: {=IFERROR(_xlfn.XLOOKUP($F9,'Acerto virtual'!$E:$E,'Acerto virtual'!M:M),"")} | AB9: {=IFERROR(_xlfn.XLOOKUP($F9,'Acerto virtual'!$E:$E,'Acerto virtual'!N:N),"")} | AC9: {=IFERROR(_xlfn.XLOOKUP($F9,'Acerto virtual'!$E:$E,'Acerto virtual'!O:O),"")} | AD9: {=IFERROR(_xlfn.XLOOKUP($F9,'Acerto virtual'!$E:$E,'Acerto virtual'!P:P),"")} | AE9: {=IFERROR(_xlfn.XLOOKUP($F9,'Acerto virtual'!$E:$E,'Acerto virtual'!Q:Q),"")} | AF9: {=IFERROR(_xlfn.XLOOKUP($F9,'Acerto virtual'!$E:$E,'Acerto virtual'!R:R),"")} | AG9: {=IFERROR(_xlfn.XLOOKUP($F9,'Acerto virtual'!$E:$E,'Acerto virtual'!S:S),"")} | AH9: {=IFERROR(_xlfn.XLOOKUP($F9,'Acerto virtual'!$E:$E,'Acerto virtual'!T:T),"")} | AI9: {=IFERROR(_xlfn.XLOOKUP($F9,'Acerto virtual'!$E:$E,'Acerto virtual'!U:U),"")}
A10: 6 | B10: 3040250830 | C10: {=IFERROR(_xlfn.XLOOKUP($B10,'Histórico'!$B:$B,'Histórico'!$I:$I),"")} -> 799-1 | D10: {=IFERROR(_xlfn.XLOOKUP($B10,'Histórico'!$B:$B,'Histórico'!$J:$J),"")} -> 83326 | E10: {=IFERROR(_xlfn.XLOOKUP($B10,'Histórico'!$B:$B,'Histórico'!$K:$K),"")} -> TRANSDUCER | F10: {=IFERROR(_xlfn.XLOOKUP($B10,'Histórico'!$B:$B,'Histórico'!$L:$L),"")} -> 1920 | G10: {=IFERROR(_xlfn.XLOOKUP($B10,'Histórico'!$B:$B,'Histórico'!$F:$F),"")} -> 20/03/2025 | H10: {=IFERROR(_xlfn.XLOOKUP($B10,'Histórico'!$B:$B,'Histórico'!$AA:$AA),"")} -> BACO | I10: {=IFERROR(_xlfn.XLOOKUP($B10,Atual!$B:$B,Atual!$E:$E),"OS concluída")} -> REC | J10: =IF(G10="","",IF(I10="OS concluída","",$D$1-G10)) -> 574 | L10: =IF(N10="","",IFERROR(N10-G10,"NÃO APLICÁVEL")) -> 112 | N10: {=IFERROR(_xlfn.XLOOKUP($B10,EMPRESA_1!A:A,EMPRESA_1!J:J),"")} -> 45848 | O10: {=IFERROR(_xlfn.XLOOKUP(B10,EMPRESA_1!A:A,EMPRESA_1!K:K),"")} -> BANT | P10: {=IFERROR(_xlfn.XLOOKUP(B10,EMPRESA_1!A:A,EMPRESA_1!L:L),"")} -> 103/C98/2025 | Q10: {=IFERROR(_xlfn.XLOOKUP(B10,EMPRESA_1!A:A,EMPRESA_1!J:J),"")} -> 45848 | R10: {=IFERROR(_xlfn.XLOOKUP(B10,EMPRESA_1!A:A,EMPRESA_1!M:M),"")} -> 148515‐04 | T10: {=IFERROR(_xlfn.XLOOKUP($F10,'Acerto virtual'!$E:$E,'Acerto virtual'!F:F),"")} | U10: {=IFERROR(_xlfn.XLOOKUP($F10,'Acerto virtual'!$E:$E,'Acerto virtual'!G:G),"")} | V10: {=IFERROR(_xlfn.XLOOKUP($F10,'Acerto virtual'!$E:$E,'Acerto virtual'!H:H),"")} | W10: {=IFERROR(_xlfn.XLOOKUP($F10,'Acerto virtual'!$E:$E,'Acerto virtual'!I:I),"")} | X10: {=IFERROR(_xlfn.XLOOKUP($F10,'Acerto virtual'!$E:$E,'Acerto virtual'!J:J),"")} | Y10: {=IFERROR(_xlfn.XLOOKUP($F10,'Acerto virtual'!$E:$E,'Acerto virtual'!K:K),"")} | Z10: {=IFERROR(_xlfn.XLOOKUP($F10,'Acerto virtual'!$E:$E,'Acerto virtual'!L:L),"")} | AA10: {=IFERROR(_xlfn.XLOOKUP($F10,'Acerto virtual'!$E:$E,'Acerto virtual'!M:M),"")} | AB10: {=IFERROR(_xlfn.XLOOKUP($F10,'Acerto virtual'!$E:$E,'Acerto virtual'!N:N),"")} | AC10: {=IFERROR(_xlfn.XLOOKUP($F10,'Acerto virtual'!$E:$E,'Acerto virtual'!O:O),"")} | AD10: {=IFERROR(_xlfn.XLOOKUP($F10,'Acerto virtual'!$E:$E,'Acerto virtual'!P:P),"")} | AE10: {=IFERROR(_xlfn.XLOOKUP($F10,'Acerto virtual'!$E:$E,'Acerto virtual'!Q:Q),"")} | AF10: {=IFERROR(_xlfn.XLOOKUP($F10,'Acerto virtual'!$E:$E,'Acerto virtual'!R:R),"")} | AG10: {=IFERROR(_xlfn.XLOOKUP($F10,'Acerto virtual'!$E:$E,'Acerto virtual'!S:S),"")} | AH10: {=IFERROR(_xlfn.XLOOKUP($F10,'Acerto virtual'!$E:$E,'Acerto virtual'!T:T),"")} | AI10: {=IFERROR(_xlfn.XLOOKUP($F10,'Acerto virtual'!$E:$E,'Acerto virtual'!U:U),"")}
A11: 7 | B11: 3040250829 | C11: {=IFERROR(_xlfn.XLOOKUP($B11,'Histórico'!$B:$B,'Histórico'!$I:$I),"")} -> 51539-012N | D11: {=IFERROR(_xlfn.XLOOKUP($B11,'Histórico'!$B:$B,'Histórico'!$J:$J),"")} -> 71379 | E11: {=IFERROR(_xlfn.XLOOKUP($B11,'Histórico'!$B:$B,'Histórico'!$K:$K),"")} -> CONTROL UNIT ASSY-GENERATOR | F11: {=IFERROR(_xlfn.XLOOKUP($B11,'Histórico'!$B:$B,'Histórico'!$L:$L),"")} -> 96967 | G11: {=IFERROR(_xlfn.XLOOKUP($B11,'Histórico'!$B:$B,'Histórico'!$F:$F),"")} -> 20/03/2025 | H11: {=IFERROR(_xlfn.XLOOKUP($B11,'Histórico'!$B:$B,'Histórico'!$AA:$AA),"")} -> BAMN | I11: {=IFERROR(_xlfn.XLOOKUP($B11,Atual!$B:$B,Atual!$E:$E),"OS concluída")} -> OS concluída | J11: =IF(G11="","",IF(I11="OS concluída","",$D$1-G11)) | L11: =IF(N11="","",IFERROR(N11-G11,"NÃO APLICÁVEL")) | N11: {=IFERROR(_xlfn.XLOOKUP($B11,Empresa!G:G,Empresa!K:K),"")} | P11: {=IFERROR(_xlfn.XLOOKUP($F11,'Vee one'!F:F,'Vee one'!O:O),"")} | Q11: {=IFERROR(_xlfn.XLOOKUP($F11,'Vee one'!F:F,'Vee one'!K:K),"")}
A12: 8 | B12: 3040250828 | C12: {=IFERROR(_xlfn.XLOOKUP($B12,'Histórico'!$B:$B,'Histórico'!$I:$I),"")} -> 51539-012N | D12: {=IFERROR(_xlfn.XLOOKUP($B12,'Histórico'!$B:$B,'Histórico'!$J:$J),"")} -> 71379 | E12: {=IFERROR(_xlfn.XLOOKUP($B12,'Histórico'!$B:$B,'Histórico'!$K:$K),"")} -> CONTROL UNIT ASSY-GENERATOR | F12: {=IFERROR(_xlfn.XLOOKUP($B12,'Histórico'!$B:$B,'Histórico'!$L:$L),"")} -> 2410 | G12: {=IFERROR(_xlfn.XLOOKUP($B12,'Histórico'!$B:$B,'Histórico'!$F:$F),"")} -> 20/03/2025 | H12: {=IFERROR(_xlfn.XLOOKUP($B12,'Histórico'!$B:$B,'Histórico'!$AA:$AA),"")} -> BACG | I12: {=IFERROR(_xlfn.XLOOKUP($B12,Atual!$B:$B,Atual!$E:$E),"OS concluída")} -> REC | J12: =IF(G12="","",IF(I12="OS concluída","",$D$1-G12)) -> 574 | L12: =IF(N12="","",IFERROR(N12-G12,"NÃO APLICÁVEL")) -> 362 | N12: {=IFERROR(_xlfn.XLOOKUP($B12,EMPRESA_1!A:A,EMPRESA_1!J:J),"")} -> 46098 | O12: {=IFERROR(_xlfn.XLOOKUP(B12,EMPRESA_1!A:A,EMPRESA_1!K:K),"")} -> BABR | P12: {=IFERROR(_xlfn.XLOOKUP(B12,EMPRESA_1!A:A,EMPRESA_1!L:L),"")} -> 208/FAB/26 | Q12: {=IFERROR(_xlfn.XLOOKUP(B12,EMPRESA_1!A:A,EMPRESA_1!J:J),"")} -> 46098 | R12: {=IFERROR(_xlfn.XLOOKUP(B12,EMPRESA_1!A:A,EMPRESA_1!M:M),"")} -> 99511 | T12: {=IFERROR(_xlfn.XLOOKUP($F12,'Acerto virtual'!$E:$E,'Acerto virtual'!F:F),"")} | U12: {=IFERROR(_xlfn.XLOOKUP($F12,'Acerto virtual'!$E:$E,'Acerto virtual'!G:G),"")} | V12: {=IFERROR(_xlfn.XLOOKUP($F12,'Acerto virtual'!$E:$E,'Acerto virtual'!H:H),"")} | W12: {=IFERROR(_xlfn.XLOOKUP($F12,'Acerto virtual'!$E:$E,'Acerto virtual'!I:I),"")} | X12: {=IFERROR(_xlfn.XLOOKUP($F12,'Acerto virtual'!$E:$E,'Acerto virtual'!J:J),"")} | Y12: {=IFERROR(_xlfn.XLOOKUP($F12,'Acerto virtual'!$E:$E,'Acerto virtual'!K:K),"")} | Z12: {=IFERROR(_xlfn.XLOOKUP($F12,'Acerto virtual'!$E:$E,'Acerto virtual'!L:L),"")} | AA12: {=IFERROR(_xlfn.XLOOKUP($F12,'Acerto virtual'!$E:$E,'Acerto virtual'!M:M),"")} | AB12: {=IFERROR(_xlfn.XLOOKUP($F12,'Acerto virtual'!$E:$E,'Acerto virtual'!N:N),"")} | AC12: {=IFERROR(_xlfn.XLOOKUP($F12,'Acerto virtual'!$E:$E,'Acerto virtual'!O:O),"")} | AD12: {=IFERROR(_xlfn.XLOOKUP($F12,'Acerto virtual'!$E:$E,'Acerto virtual'!P:P),"")} | AE12: {=IFERROR(_xlfn.XLOOKUP($F12,'Acerto virtual'!$E:$E,'Acerto virtual'!Q:Q),"")} | AF12: {=IFERROR(_xlfn.XLOOKUP($F12,'Acerto virtual'!$E:$E,'Acerto virtual'!R:R),"")} | AG12: {=IFERROR(_xlfn.XLOOKUP($F12,'Acerto virtual'!$E:$E,'Acerto virtual'!S:S),"")} | AH12: {=IFERROR(_xlfn.XLOOKUP($F12,'Acerto virtual'!$E:$E,'Acerto virtual'!T:T),"")} | AI12: {=IFERROR(_xlfn.XLOOKUP($F12,'Acerto virtual'!$E:$E,'Acerto virtual'!U:U),"")}
A13: 9 | B13: 3040250827 | C13: {=IFERROR(_xlfn.XLOOKUP($B13,'Histórico'!$B:$B,'Histórico'!$I:$I),"")} -> 51539-012N | D13: {=IFERROR(_xlfn.XLOOKUP($B13,'Histórico'!$B:$B,'Histórico'!$J:$J),"")} -> 71379 | E13: {=IFERROR(_xlfn.XLOOKUP($B13,'Histórico'!$B:$B,'Histórico'!$K:$K),"")} -> CONTROL UNIT ASSY-GENERATOR | F13: {=IFERROR(_xlfn.XLOOKUP($B13,'Histórico'!$B:$B,'Histórico'!$L:$L),"")} -> P1916 | G13: {=IFERROR(_xlfn.XLOOKUP($B13,'Histórico'!$B:$B,'Histórico'!$F:$F),"")} -> 20/03/2025 | H13: {=IFERROR(_xlfn.XLOOKUP($B13,'Histórico'!$B:$B,'Histórico'!$AA:$AA),"")} -> BANT | I13: {=IFERROR(_xlfn.XLOOKUP($B13,Atual!$B:$B,Atual!$E:$E),"OS concluída")} -> REC | J13: =IF(G13="","",IF(I13="OS concluída","",$D$1-G13)) -> 574 | L13: =IF(N13="","",IFERROR(N13-G13,"NÃO APLICÁVEL")) -> 378 | N13: {=IFERROR(_xlfn.XLOOKUP($B13,EMPRESA_1!A:A,EMPRESA_1!J:J),"")} -> 46114 | O13: {=IFERROR(_xlfn.XLOOKUP(B13,EMPRESA_1!A:A,EMPRESA_1!K:K),"")} -> BABR | P13: {=IFERROR(_xlfn.XLOOKUP(B13,EMPRESA_1!A:A,EMPRESA_1!L:L),"")} -> 271/FAB/26 | Q13: {=IFERROR(_xlfn.XLOOKUP(B13,EMPRESA_1!A:A,EMPRESA_1!J:J),"")} -> 46114 | R13: {=IFERROR(_xlfn.XLOOKUP(B13,EMPRESA_1!A:A,EMPRESA_1!M:M),"")} -> P2033 | T13: {=IFERROR(_xlfn.XLOOKUP($F13,'Acerto virtual'!$E:$E,'Acerto virtual'!F:F),"")} | U13: {=IFERROR(_xlfn.XLOOKUP($F13,'Acerto virtual'!$E:$E,'Acerto virtual'!G:G),"")} | V13: {=IFERROR(_xlfn.XLOOKUP($F13,'Acerto virtual'!$E:$E,'Acerto virtual'!H:H),"")} | W13: {=IFERROR(_xlfn.XLOOKUP($F13,'Acerto virtual'!$E:$E,'Acerto virtual'!I:I),"")} | X13: {=IFERROR(_xlfn.XLOOKUP($F13,'Acerto virtual'!$E:$E,'Acerto virtual'!J:J),"")} | Y13: {=IFERROR(_xlfn.XLOOKUP($F13,'Acerto virtual'!$E:$E,'Acerto virtual'!K:K),"")} | Z13: {=IFERROR(_xlfn.XLOOKUP($F13,'Acerto virtual'!$E:$E,'Acerto virtual'!L:L),"")} | AA13: {=IFERROR(_xlfn.XLOOKUP($F13,'Acerto virtual'!$E:$E,'Acerto virtual'!M:M),"")} | AB13: {=IFERROR(_xlfn.XLOOKUP($F13,'Acerto virtual'!$E:$E,'Acerto virtual'!N:N),"")} | AC13: {=IFERROR(_xlfn.XLOOKUP($F13,'Acerto virtual'!$E:$E,'Acerto virtual'!O:O),"")} | AD13: {=IFERROR(_xlfn.XLOOKUP($F13,'Acerto virtual'!$E:$E,'Acerto virtual'!P:P),"")} | AE13: {=IFERROR(_xlfn.XLOOKUP($F13,'Acerto virtual'!$E:$E,'Acerto virtual'!Q:Q),"")} | AF13: {=IFERROR(_xlfn.XLOOKUP($F13,'Acerto virtual'!$E:$E,'Acerto virtual'!R:R),"")} | AG13: {=IFERROR(_xlfn.XLOOKUP($F13,'Acerto virtual'!$E:$E,'Acerto virtual'!S:S),"")} | AH13: {=IFERROR(_xlfn.XLOOKUP($F13,'Acerto virtual'!$E:$E,'Acerto virtual'!T:T),"")} | AI13: {=IFERROR(_xlfn.XLOOKUP($F13,'Acerto virtual'!$E:$E,'Acerto virtual'!U:U),"")}
A14: 10 | B14: 3040250831 | C14: {=IFERROR(_xlfn.XLOOKUP($B14,'Histórico'!$B:$B,'Histórico'!$I:$I),"")} -> 799-1 | D14: {=IFERROR(_xlfn.XLOOKUP($B14,'Histórico'!$B:$B,'Histórico'!$J:$J),"")} -> 83326 | E14: {=IFERROR(_xlfn.XLOOKUP($B14,'Histórico'!$B:$B,'Histórico'!$K:$K),"")} -> TRANSDUCER | F14: {=IFERROR(_xlfn.XLOOKUP($B14,'Histórico'!$B:$B,'Histórico'!$L:$L),"")} -> 2697 | G14: {=IFERROR(_xlfn.XLOOKUP($B14,'Histórico'!$B:$B,'Histórico'!$F:$F),"")} -> 20/03/2025 | H14: {=IFERROR(_xlfn.XLOOKUP($B14,'Histórico'!$B:$B,'Histórico'!$AA:$AA),"")} -> BANT | I14: {=IFERROR(_xlfn.XLOOKUP($B14,Atual!$B:$B,Atual!$E:$E),"OS concluída")} -> REC | J14: =IF(G14="","",IF(I14="OS concluída","",$D$1-G14)) -> 574 | L14: =IF(N14="","",IFERROR(N14-G14,"NÃO APLICÁVEL")) -> 112 | N14: {=IFERROR(_xlfn.XLOOKUP($B14,EMPRESA_1!A:A,EMPRESA_1!J:J),"")} -> 45848 | O14: {=IFERROR(_xlfn.XLOOKUP(B14,EMPRESA_1!A:A,EMPRESA_1!K:K),"")} -> BANT | P14: {=IFERROR(_xlfn.XLOOKUP(B14,EMPRESA_1!A:A,EMPRESA_1!L:L),"")} -> 103/C98/2025 | Q14: {=IFERROR(_xlfn.XLOOKUP(B14,EMPRESA_1!A:A,EMPRESA_1!J:J),"")} -> 45848 | R14: {=IFERROR(_xlfn.XLOOKUP(B14,EMPRESA_1!A:A,EMPRESA_1!M:M),"")} -> 168393-11 | T14: {=IFERROR(_xlfn.XLOOKUP($F14,'Acerto virtual'!$E:$E,'Acerto virtual'!F:F),"")} | U14: {=IFERROR(_xlfn.XLOOKUP($F14,'Acerto virtual'!$E:$E,'Acerto virtual'!G:G),"")} | V14: {=IFERROR(_xlfn.XLOOKUP($F14,'Acerto virtual'!$E:$E,'Acerto virtual'!H:H),"")} | W14: {=IFERROR(_xlfn.XLOOKUP($F14,'Acerto virtual'!$E:$E,'Acerto virtual'!I:I),"")} | X14: {=IFERROR(_xlfn.XLOOKUP($F14,'Acerto virtual'!$E:$E,'Acerto virtual'!J:J),"")} | Y14: {=IFERROR(_xlfn.XLOOKUP($F14,'Acerto virtual'!$E:$E,'Acerto virtual'!K:K),"")} | Z14: {=IFERROR(_xlfn.XLOOKUP($F14,'Acerto virtual'!$E:$E,'Acerto virtual'!L:L),"")} | AA14: {=IFERROR(_xlfn.XLOOKUP($F14,'Acerto virtual'!$E:$E,'Acerto virtual'!M:M),"")} | AB14: {=IFERROR(_xlfn.XLOOKUP($F14,'Acerto virtual'!$E:$E,'Acerto virtual'!N:N),"")} | AC14: {=IFERROR(_xlfn.XLOOKUP($F14,'Acerto virtual'!$E:$E,'Acerto virtual'!O:O),"")} | AD14: {=IFERROR(_xlfn.XLOOKUP($F14,'Acerto virtual'!$E:$E,'Acerto virtual'!P:P),"")} | AE14: {=IFERROR(_xlfn.XLOOKUP($F14,'Acerto virtual'!$E:$E,'Acerto virtual'!Q:Q),"")} | AF14: {=IFERROR(_xlfn.XLOOKUP($F14,'Acerto virtual'!$E:$E,'Acerto virtual'!R:R),"")} | AG14: {=IFERROR(_xlfn.XLOOKUP($F14,'Acerto virtual'!$E:$E,'Acerto virtual'!S:S),"")} | AH14: {=IFERROR(_xlfn.XLOOKUP($F14,'Acerto virtual'!$E:$E,'Acerto virtual'!T:T),"")} | AI14: {=IFERROR(_xlfn.XLOOKUP($F14,'Acerto virtual'!$E:$E,'Acerto virtual'!U:U),"")}
A15: 11 | B15: 3040250833 | C15: {=IFERROR(_xlfn.XLOOKUP($B15,'Histórico'!$B:$B,'Histórico'!$I:$I),"")} -> 9910586-4 | D15: {=IFERROR(_xlfn.XLOOKUP($B15,'Histórico'!$B:$B,'Histórico'!$J:$J),"")} -> 7EK50 | E15: {=IFERROR(_xlfn.XLOOKUP($B15,'Histórico'!$B:$B,'Histórico'!$K:$K),"")} -> FLAP ACTUATOR AND MOTOR ASSEMBLY | F15: {=IFERROR(_xlfn.XLOOKUP($B15,'Histórico'!$B:$B,'Histórico'!$L:$L),"")} -> 1569 | G15: {=IFERROR(_xlfn.XLOOKUP($B15,'Histórico'!$B:$B,'Histórico'!$F:$F),"")} -> 20/03/2025 | H15: {=IFERROR(_xlfn.XLOOKUP($B15,'Histórico'!$B:$B,'Histórico'!$AA:$AA),"")} -> ALA 3 | I15: {=IFERROR(_xlfn.XLOOKUP($B15,Atual!$B:$B,Atual!$E:$E),"OS concluída")} -> REC | J15: =IF(G15="","",IF(I15="OS concluída","",$D$1-G15)) -> 574 | L15: =IF(N15="","",IFERROR(N15-G15,"NÃO APLICÁVEL")) -> 124 | N15: {=IFERROR(_xlfn.XLOOKUP($B15,EMPRESA_1!A:A,EMPRESA_1!J:J),"")} -> 45860 | O15: {=IFERROR(_xlfn.XLOOKUP(B15,EMPRESA_1!A:A,EMPRESA_1!K:K),"")} -> BAMN | P15: {=IFERROR(_xlfn.XLOOKUP(B15,EMPRESA_1!A:A,EMPRESA_1!L:L),"")} -> 122/C98/2025 | Q15: {=IFERROR(_xlfn.XLOOKUP(B15,EMPRESA_1!A:A,EMPRESA_1!J:J),"")} -> 45860 | R15: {=IFERROR(_xlfn.XLOOKUP(B15,EMPRESA_1!A:A,EMPRESA_1!M:M),"")} | T15: {=IFERROR(_xlfn.XLOOKUP($F15,'Acerto virtual'!$E:$E,'Acerto virtual'!F:F),"")} | U15: {=IFERROR(_xlfn.XLOOKUP($F15,'Acerto virtual'!$E:$E,'Acerto virtual'!G:G),"")} | V15: {=IFERROR(_xlfn.XLOOKUP($F15,'Acerto virtual'!$E:$E,'Acerto virtual'!H:H),"")} | W15: {=IFERROR(_xlfn.XLOOKUP($F15,'Acerto virtual'!$E:$E,'Acerto virtual'!I:I),"")} | X15: {=IFERROR(_xlfn.XLOOKUP($F15,'Acerto virtual'!$E:$E,'Acerto virtual'!J:J),"")} | Y15: {=IFERROR(_xlfn.XLOOKUP($F15,'Acerto virtual'!$E:$E,'Acerto virtual'!K:K),"")} | Z15: {=IFERROR(_xlfn.XLOOKUP($F15,'Acerto virtual'!$E:$E,'Acerto virtual'!L:L),"")} | AA15: {=IFERROR(_xlfn.XLOOKUP($F15,'Acerto virtual'!$E:$E,'Acerto virtual'!M:M),"")} | AB15: {=IFERROR(_xlfn.XLOOKUP($F15,'Acerto virtual'!$E:$E,'Acerto virtual'!N:N),"")} | AC15: {=IFERROR(_xlfn.XLOOKUP($F15,'Acerto virtual'!$E:$E,'Acerto virtual'!O:O),"")} | AD15: {=IFERROR(_xlfn.XLOOKUP($F15,'Acerto virtual'!$E:$E,'Acerto virtual'!P:P),"")} | AE15: {=IFERROR(_xlfn.XLOOKUP($F15,'Acerto virtual'!$E:$E,'Acerto virtual'!Q:Q),"")} | AF15: {=IFERROR(_xlfn.XLOOKUP($F15,'Acerto virtual'!$E:$E,'Acerto virtual'!R:R),"")} | AG15: {=IFERROR(_xlfn.XLOOKUP($F15,'Acerto virtual'!$E:$E,'Acerto virtual'!S:S),"")} | AH15: {=IFERROR(_xlfn.XLOOKUP($F15,'Acerto virtual'!$E:$E,'Acerto virtual'!T:T),"")} | AI15: {=IFERROR(_xlfn.XLOOKUP($F15,'Acerto virtual'!$E:$E,'Acerto virtual'!U:U),"")}
A16: 12 | B16: 3040250834 | C16: {=IFERROR(_xlfn.XLOOKUP($B16,'Histórico'!$B:$B,'Histórico'!$I:$I),"")} -> 9910586-4 | D16: {=IFERROR(_xlfn.XLOOKUP($B16,'Histórico'!$B:$B,'Histórico'!$J:$J),"")} -> 7EK50 | E16: {=IFERROR(_xlfn.XLOOKUP($B16,'Histórico'!$B:$B,'Histórico'!$K:$K),"")} -> FLAP ACTUATOR AND MOTOR ASSEMBLY | F16: {=IFERROR(_xlfn.XLOOKUP($B16,'Histórico'!$B:$B,'Histórico'!$L:$L),"")} -> 2706 | G16: {=IFERROR(_xlfn.XLOOKUP($B16,'Histórico'!$B:$B,'Histórico'!$F:$F),"")} -> 20/03/2025 | H16: {=IFERROR(_xlfn.XLOOKUP($B16,'Histórico'!$B:$B,'Histórico'!$AA:$AA),"")} -> ALA 3 | I16: {=IFERROR(_xlfn.XLOOKUP($B16,Atual!$B:$B,Atual!$E:$E),"OS concluída")} -> OS concluída | J16: =IF(G16="","",IF(I16="OS concluída","",$D$1-G16)) | L16: =IF(N16="","",IFERROR(N16-G16,"NÃO APLICÁVEL")) | N16: {=IFERROR(_xlfn.XLOOKUP($B16,Empresa!G:G,Empresa!K:K),"")} | P16: {=IFERROR(_xlfn.XLOOKUP($F16,'Vee one'!F:F,'Vee one'!O:O),"")} | Q16: {=IFERROR(_xlfn.XLOOKUP($F16,'Vee one'!F:F,'Vee one'!K:K),"")}
A17: 13 | B17: 3040250832 | C17: {=IFERROR(_xlfn.XLOOKUP($B17,'Histórico'!$B:$B,'Histórico'!$I:$I),"")} -> 9910338-4 | D17: {=IFERROR(_xlfn.XLOOKUP($B17,'Histórico'!$B:$B,'Histórico'!$J:$J),"")} -> 13068 | E17: {=IFERROR(_xlfn.XLOOKUP($B17,'Histórico'!$B:$B,'Histórico'!$K:$K),"")} -> FUEL TOTALIZER INDICATOR | F17: {=IFERROR(_xlfn.XLOOKUP($B17,'Histórico'!$B:$B,'Histórico'!$L:$L),"")} -> 0215-217 | G17: {=IFERROR(_xlfn.XLOOKUP($B17,'Histórico'!$B:$B,'Histórico'!$F:$F),"")} -> 20/03/2025 | H17: {=IFERROR(_xlfn.XLOOKUP($B17,'Histórico'!$B:$B,'Histórico'!$AA:$AA),"")} -> EEAR | I17: {=IFERROR(_xlfn.XLOOKUP($B17,Atual!$B:$B,Atual!$E:$E),"OS concluída")} -> REC | J17: =IF(G17="","",IF(I17="OS concluída","",$D$1-G17)) -> 574 | L17: =IF(N17="","",IFERROR(N17-G17,"NÃO APLICÁVEL")) -> 64 | N17: {=IFERROR(_xlfn.XLOOKUP($B17,EMPRESA_1!A:A,EMPRESA_1!J:J),"")} -> 45800 | O17: {=IFERROR(_xlfn.XLOOKUP(B17,EMPRESA_1!A:A,EMPRESA_1!K:K),"")} -> PAMA-LS | P17: {=IFERROR(_xlfn.XLOOKUP(B17,EMPRESA_1!A:A,EMPRESA_1!L:L),"")} -> 045/C98/2025 | Q17: {=IFERROR(_xlfn.XLOOKUP(B17,EMPRESA_1!A:A,EMPRESA_1!J:J),"")} -> 45800 | R17: {=IFERROR(_xlfn.XLOOKUP(B17,EMPRESA_1!A:A,EMPRESA_1!M:M),"")} | T17: {=IFERROR(_xlfn.XLOOKUP($F17,'Acerto virtual'!$E:$E,'Acerto virtual'!F:F),"")} | U17: {=IFERROR(_xlfn.XLOOKUP($F17,'Acerto virtual'!$E:$E,'Acerto virtual'!G:G),"")} | V17: {=IFERROR(_xlfn.XLOOKUP($F17,'Acerto virtual'!$E:$E,'Acerto virtual'!H:H),"")} | W17: {=IFERROR(_xlfn.XLOOKUP($F17,'Acerto virtual'!$E:$E,'Acerto virtual'!I:I),"")} | X17: {=IFERROR(_xlfn.XLOOKUP($F17,'Acerto virtual'!$E:$E,'Acerto virtual'!J:J),"")} | Y17: {=IFERROR(_xlfn.XLOOKUP($F17,'Acerto virtual'!$E:$E,'Acerto virtual'!K:K),"")} | Z17: {=IFERROR(_xlfn.XLOOKUP($F17,'Acerto virtual'!$E:$E,'Acerto virtual'!L:L),"")} | AA17: {=IFERROR(_xlfn.XLOOKUP($F17,'Acerto virtual'!$E:$E,'Acerto virtual'!M:M),"")} | AB17: {=IFERROR(_xlfn.XLOOKUP($F17,'Acerto virtual'!$E:$E,'Acerto virtual'!N:N),"")} | AC17: {=IFERROR(_xlfn.XLOOKUP($F17,'Acerto virtual'!$E:$E,'Acerto virtual'!O:O),"")} | AD17: {=IFERROR(_xlfn.XLOOKUP($F17,'Acerto virtual'!$E:$E,'Acerto virtual'!P:P),"")} | AE17: {=IFERROR(_xlfn.XLOOKUP($F17,'Acerto virtual'!$E:$E,'Acerto virtual'!Q:Q),"")} | AF17: {=IFERROR(_xlfn.XLOOKUP($F17,'Acerto virtual'!$E:$E,'Acerto virtual'!R:R),"")} | AG17: {=IFERROR(_xlfn.XLOOKUP($F17,'Acerto virtual'!$E:$E,'Acerto virtual'!S:S),"")} | AH17: {=IFERROR(_xlfn.XLOOKUP($F17,'Acerto virtual'!$E:$E,'Acerto virtual'!T:T),"")} | AI17: {=IFERROR(_xlfn.XLOOKUP($F17,'Acerto virtual'!$E:$E,'Acerto virtual'!U:U),"")}
A18: 14 | B18: 3040250835 | C18: {=IFERROR(_xlfn.XLOOKUP($B18,'Histórico'!$B:$B,'Histórico'!$I:$I),"")} -> ASG12000-2 | D18: {=IFERROR(_xlfn.XLOOKUP($B18,'Histórico'!$B:$B,'Histórico'!$J:$J),"")} -> 71653 | E18: {=IFERROR(_xlfn.XLOOKUP($B18,'Histórico'!$B:$B,'Histórico'!$K:$K),"")} -> ALTERNATOR | F18: {=IFERROR(_xlfn.XLOOKUP($B18,'Histórico'!$B:$B,'Histórico'!$L:$L),"")} -> K010158 | G18: {=IFERROR(_xlfn.XLOOKUP($B18,'Histórico'!$B:$B,'Histórico'!$F:$F),"")} -> 20/03/2025 | H18: {=IFERROR(_xlfn.XLOOKUP($B18,'Histórico'!$B:$B,'Histórico'!$AA:$AA),"")} -> ALA 5 | I18: {=IFERROR(_xlfn.XLOOKUP($B18,Atual!$B:$B,Atual!$E:$E),"OS concluída")} -> OS concluída | J18: =IF(G18="","",IF(I18="OS concluída","",$D$1-G18)) | L18: =IF(N18="","",IFERROR(N18-G18,"NÃO APLICÁVEL")) -> NÃO APLICÁVEL | N18: {=IFERROR(_xlfn.XLOOKUP($B18,EMPRESA_1!A:A,EMPRESA_1!J:J),"")} -> REPARADO | O18: {=IFERROR(_xlfn.XLOOKUP(B18,EMPRESA_1!A:A,EMPRESA_1!K:K),"")} -> V1 PAMA-LS | P18: {=IFERROR(_xlfn.XLOOKUP(B18,EMPRESA_1!A:A,EMPRESA_1!L:L),"")} | Q18: {=IFERROR(_xlfn.XLOOKUP(B18,EMPRESA_1!A:A,EMPRESA_1!J:J),"")} -> REPARADO | R18: {=IFERROR(_xlfn.XLOOKUP(B18,EMPRESA_1!A:A,EMPRESA_1!M:M),"")} | T18: {=IFERROR(_xlfn.XLOOKUP($F18,'Acerto virtual'!$E:$E,'Acerto virtual'!F:F),"")} | U18: {=IFERROR(_xlfn.XLOOKUP($F18,'Acerto virtual'!$E:$E,'Acerto virtual'!G:G),"")} | V18: {=IFERROR(_xlfn.XLOOKUP($F18,'Acerto virtual'!$E:$E,'Acerto virtual'!H:H),"")} | W18: {=IFERROR(_xlfn.XLOOKUP($F18,'Acerto virtual'!$E:$E,'Acerto virtual'!I:I),"")} | X18: {=IFERROR(_xlfn.XLOOKUP($F18,'Acerto virtual'!$E:$E,'Acerto virtual'!J:J),"")} | Y18: {=IFERROR(_xlfn.XLOOKUP($F18,'Acerto virtual'!$E:$E,'Acerto virtual'!K:K),"")} | Z18: {=IFERROR(_xlfn.XLOOKUP($F18,'Acerto virtual'!$E:$E,'Acerto virtual'!L:L),"")} | AA18: {=IFERROR(_xlfn.XLOOKUP($F18,'Acerto virtual'!$E:$E,'Acerto virtual'!M:M),"")} | AB18: {=IFERROR(_xlfn.XLOOKUP($F18,'Acerto virtual'!$E:$E,'Acerto virtual'!N:N),"")} | AC18: {=IFERROR(_xlfn.XLOOKUP($F18,'Acerto virtual'!$E:$E,'Acerto virtual'!O:O),"")} | AD18: {=IFERROR(_xlfn.XLOOKUP($F18,'Acerto virtual'!$E:$E,'Acerto virtual'!P:P),"")} | AE18: {=IFERROR(_xlfn.XLOOKUP($F18,'Acerto virtual'!$E:$E,'Acerto virtual'!Q:Q),"")} | AF18: {=IFERROR(_xlfn.XLOOKUP($F18,'Acerto virtual'!$E:$E,'Acerto virtual'!R:R),"")} | AG18: {=IFERROR(_xlfn.XLOOKUP($F18,'Acerto virtual'!$E:$E,'Acerto virtual'!S:S),"")} | AH18: {=IFERROR(_xlfn.XLOOKUP($F18,'Acerto virtual'!$E:$E,'Acerto virtual'!T:T),"")} | AI18: {=IFERROR(_xlfn.XLOOKUP($F18,'Acerto virtual'!$E:$E,'Acerto virtual'!U:U),"")}
A19: 15 | B19: 3040250841 | C19: {=IFERROR(_xlfn.XLOOKUP($B19,'Histórico'!$B:$B,'Histórico'!$I:$I),"")} -> C661030-0301 | D19: {=IFERROR(_xlfn.XLOOKUP($B19,'Histórico'!$B:$B,'Histórico'!$J:$J),"")} -> 7EK50 | E19: {=IFERROR(_xlfn.XLOOKUP($B19,'Histórico'!$B:$B,'Histórico'!$K:$K),"")} -> TURN BANK | F19: {=IFERROR(_xlfn.XLOOKUP($B19,'Histórico'!$B:$B,'Histórico'!$L:$L),"")} -> 9911-257 | G19: {=IFERROR(_xlfn.XLOOKUP($B19,'Histórico'!$B:$B,'Histórico'!$F:$F),"")} -> 20/03/2025 | H19: {=IFERROR(_xlfn.XLOOKUP($B19,'Histórico'!$B:$B,'Histórico'!$AA:$AA),"")} -> PAMALS | I19: {=IFERROR(_xlfn.XLOOKUP($B19,Atual!$B:$B,Atual!$E:$E),"OS concluída")} -> REC | J19: =IF(G19="","",IF(I19="OS concluída","",$D$1-G19)) -> 574 | L19: =IF(N19="","",IFERROR(N19-G19,"NÃO APLICÁVEL")) -> NÃO APLICÁVEL | N19: {=IFERROR(_xlfn.XLOOKUP($B19,EMPRESA_1!A:A,EMPRESA_1!J:J),"")} -> EM REPARO | O19: {=IFERROR(_xlfn.XLOOKUP(B19,EMPRESA_1!A:A,EMPRESA_1!K:K),"")} -> LEAP | P19: {=IFERROR(_xlfn.XLOOKUP(B19,EMPRESA_1!A:A,EMPRESA_1!L:L),"")} | Q19: {=IFERROR(_xlfn.XLOOKUP(B19,EMPRESA_1!A:A,EMPRESA_1!J:J),"")} -> EM REPARO | R19: {=IFERROR(_xlfn.XLOOKUP(B19,EMPRESA_1!A:A,EMPRESA_1!M:M),"")} | T19: {=IFERROR(_xlfn.XLOOKUP($F19,'Acerto virtual'!$E:$E,'Acerto virtual'!F:F),"")} | U19: {=IFERROR(_xlfn.XLOOKUP($F19,'Acerto virtual'!$E:$E,'Acerto virtual'!G:G),"")} | V19: {=IFERROR(_xlfn.XLOOKUP($F19,'Acerto virtual'!$E:$E,'Acerto virtual'!H:H),"")} | W19: {=IFERROR(_xlfn.XLOOKUP($F19,'Acerto virtual'!$E:$E,'Acerto virtual'!I:I),"")} | X19: {=IFERROR(_xlfn.XLOOKUP($F19,'Acerto virtual'!$E:$E,'Acerto virtual'!J:J),"")} | Y19: {=IFERROR(_xlfn.XLOOKUP($F19,'Acerto virtual'!$E:$E,'Acerto virtual'!K:K),"")} | Z19: {=IFERROR(_xlfn.XLOOKUP($F19,'Acerto virtual'!$E:$E,'Acerto virtual'!L:L),"")} | AA19: {=IFERROR(_xlfn.XLOOKUP($F19,'Acerto virtual'!$E:$E,'Acerto virtual'!M:M),"")} | AB19: {=IFERROR(_xlfn.XLOOKUP($F19,'Acerto virtual'!$E:$E,'Acerto virtual'!N:N),"")} | AC19: {=IFERROR(_xlfn.XLOOKUP($F19,'Acerto virtual'!$E:$E,'Acerto virtual'!O:O),"")} | AD19: {=IFERROR(_xlfn.XLOOKUP($F19,'Acerto virtual'!$E:$E,'Acerto virtual'!P:P),"")} | AE19: {=IFERROR(_xlfn.XLOOKUP($F19,'Acerto virtual'!$E:$E,'Acerto virtual'!Q:Q),"")} | AF19: {=IFERROR(_xlfn.XLOOKUP($F19,'Acerto virtual'!$E:$E,'Acerto virtual'!R:R),"")} | AG19: {=IFERROR(_xlfn.XLOOKUP($F19,'Acerto virtual'!$E:$E,'Acerto virtual'!S:S),"")} | AH19: {=IFERROR(_xlfn.XLOOKUP($F19,'Acerto virtual'!$E:$E,'Acerto virtual'!T:T),"")} | AI19: {=IFERROR(_xlfn.XLOOKUP($F19,'Acerto virtual'!$E:$E,'Acerto virtual'!U:U),"")}
A20: 16 | B20: 3040250842 | C20: {=IFERROR(_xlfn.XLOOKUP($B20,'Histórico'!$B:$B,'Histórico'!$I:$I),"")} -> C662041-0102 | D20: {=IFERROR(_xlfn.XLOOKUP($B20,'Histórico'!$B:$B,'Histórico'!$J:$J),"")} -> 7EK50 | E20: {=IFERROR(_xlfn.XLOOKUP($B20,'Histórico'!$B:$B,'Histórico'!$K:$K),"")} -> INDICATOR FUEL | F20: {=IFERROR(_xlfn.XLOOKUP($B20,'Histórico'!$B:$B,'Histórico'!$L:$L),"")} -> 791 | G20: {=IFERROR(_xlfn.XLOOKUP($B20,'Histórico'!$B:$B,'Histórico'!$F:$F),"")} -> 20/03/2025 | H20: {=IFERROR(_xlfn.XLOOKUP($B20,'Histórico'!$B:$B,'Histórico'!$AA:$AA),"")} -> ALA 5 | I20: {=IFERROR(_xlfn.XLOOKUP($B20,Atual!$B:$B,Atual!$E:$E),"OS concluída")} -> REC | J20: =IF(G20="","",IF(I20="OS concluída","",$D$1-G20)) -> 574 | L20: =IF(N20="","",IFERROR(N20-G20,"NÃO APLICÁVEL")) -> 161 | N20: {=IFERROR(_xlfn.XLOOKUP($B20,EMPRESA_1!A:A,EMPRESA_1!J:J),"")} -> 45897 | O20: {=IFERROR(_xlfn.XLOOKUP(B20,EMPRESA_1!A:A,EMPRESA_1!K:K),"")} -> PAMA-LS | P20: {=IFERROR(_xlfn.XLOOKUP(B20,EMPRESA_1!A:A,EMPRESA_1!L:L),"")} -> 159/C98/2025 | Q20: {=IFERROR(_xlfn.XLOOKUP(B20,EMPRESA_1!A:A,EMPRESA_1!J:J),"")} -> 45897 | R20: {=IFERROR(_xlfn.XLOOKUP(B20,EMPRESA_1!A:A,EMPRESA_1!M:M),"")} | T20: {=IFERROR(_xlfn.XLOOKUP($F20,'Acerto virtual'!$E:$E,'Acerto virtual'!F:F),"")} | U20: {=IFERROR(_xlfn.XLOOKUP($F20,'Acerto virtual'!$E:$E,'Acerto virtual'!G:G),"")} | V20: {=IFERROR(_xlfn.XLOOKUP($F20,'Acerto virtual'!$E:$E,'Acerto virtual'!H:H),"")} | W20: {=IFERROR(_xlfn.XLOOKUP($F20,'Acerto virtual'!$E:$E,'Acerto virtual'!I:I),"")} | X20: {=IFERROR(_xlfn.XLOOKUP($F20,'Acerto virtual'!$E:$E,'Acerto virtual'!J:J),"")} | Y20: {=IFERROR(_xlfn.XLOOKUP($F20,'Acerto virtual'!$E:$E,'Acerto virtual'!K:K),"")} | Z20: {=IFERROR(_xlfn.XLOOKUP($F20,'Acerto virtual'!$E:$E,'Acerto virtual'!L:L),"")} | AA20: {=IFERROR(_xlfn.XLOOKUP($F20,'Acerto virtual'!$E:$E,'Acerto virtual'!M:M),"")} | AB20: {=IFERROR(_xlfn.XLOOKUP($F20,'Acerto virtual'!$E:$E,'Acerto virtual'!N:N),"")} | AC20: {=IFERROR(_xlfn.XLOOKUP($F20,'Acerto virtual'!$E:$E,'Acerto virtual'!O:O),"")} | AD20: {=IFERROR(_xlfn.XLOOKUP($F20,'Acerto virtual'!$E:$E,'Acerto virtual'!P:P),"")} | AE20: {=IFERROR(_xlfn.XLOOKUP($F20,'Acerto virtual'!$E:$E,'Acerto virtual'!Q:Q),"")} | AF20: {=IFERROR(_xlfn.XLOOKUP($F20,'Acerto virtual'!$E:$E,'Acerto virtual'!R:R),"")} | AG20: {=IFERROR(_xlfn.XLOOKUP($F20,'Acerto virtual'!$E:$E,'Acerto virtual'!S:S),"")} | AH20: {=IFERROR(_xlfn.XLOOKUP($F20,'Acerto virtual'!$E:$E,'Acerto virtual'!T:T),"")} | AI20: {=IFERROR(_xlfn.XLOOKUP($F20,'Acerto virtual'!$E:$E,'Acerto virtual'!U:U),"")}
